Workbook
Name AGT_GM_Target_Ent: Inputs!$D$40
Name AGT_Markup_Ent: Inputs!$D$41
Name AGT_TasksPM_Ent: Inputs!$D$7
Name AGT_Tenants_Ent: Inputs!$D$6
Name Branch_Avg: Inputs!$C$11
Name FX_KES_A: Inputs!$B$44
Name FX_NGN_A: Inputs!$B$45
Name FX_UGX_A: Inputs!$B$43
Name Retry_Avg: Inputs!$C$12

Sheet README
A1: SaaS Agent Cost-Per-Task Calculator
A3: Purpose | B3: Per-tier agent cost engine for AI-agent SaaS products. Builds the agent COGS waterfall from inputs: (planner steps + worker steps x parallel branches) x (1 + retries) x LLM tokens + tool invocations + HITL escalations + vector + observability + eval overhead + retraining amortisation + safety floor + supervision overhead. Produces cost-per-attempted-task AND cost-per-resolved-task (the true unit, since failed / abandoned tasks still consume cost and must amortise across resolved outcomes). Includes margin analysis vs per-resolution pricing, 2-D sensitivity, eight pre-coded stress scenarios, dashboard with traffic lights, and Africa-specific adjustments.
A5: Sheets in this workbook
A6: Inputs | B6: Yellow cells. Tier mix, per-task agent dimensions, LLM rates, tools, HITL, eval, reserves, FX.
A7: Cost-Per-Task | B7: Per-tier waterfall: step inflation, LLM, tool, HITL, vector, observability, eval, retraining, safety floor, supervision. Cost per attempted vs resolved task. Sensitivity columns.
A8: Margin-Analysis | B8: Agent price per resolved task × resolution rate vs cost-per-resolved-task → agent gross margin per tier; contribution margin including S&M attribution.
A9: Sensitivity | B9: Four 2-D tables: tokens/step × $/1k; intervention-rate × HITL $/min; tools/task × external-%; parallel branches × retries factor (step inflation).
A10: Stress-Test | B10: Six pre-coded scenarios: Provider 5x; Intervention 2x; Model deprecation 2x; Tool-vendor outage 3x; Abandonment 50→25% (positive); Combined shock.
A11: Dashboard | B11: Cost-per-resolved by tier with traffic lights (>70% GM green / 50-70 amber / <50 red); stress waterfall chart; reference to AI-cost-of-tenant baseline.
A12: Africa-Notes | B12: Agent-specific FX clauses, mobile-money in tool costs, longer collection cycles for SLA-tied per-resolution pricing, USD pricing for Enterprise, sovereign-AI premium.
A14: Owner | B14: CFO + Head of Agent (joint ownership); Eval Engineer for intervention rate; Tool Engineer for tool cost share
A15: Update cadence | B15: Weekly: cost-per-resolved-task, cost-per-task weighted, intervention rate, tool reliability. Monthly: agent gross margin, HITL share, tool-cost share, retry overhead share, provider pricing watch. Quarterly: model-migration reserve, irreversibility reserve. Variance >+15% WoW on cost-per-resolved triggers a re-plan loop per meta-living-plan-governance.
A16: Living-plan discipline | B16: All yellow cells are user-editable inputs. White cells are formulas — do not overwrite. Refresh inputs on the cadence above. Any variance >10% versus plan triggers a re-plan loop per skills/meta-living-plan-governance.
A17: Sources / methodology | B17: saas-agent-cost-per-task-calculator-spec.md, saas-agent-unit-economics-template.md (this engine); book-extractions/agent-products-business-plan-audit-2026.md COGS waterfall; saas-ai-cost-of-tenant-calculator.xlsx (single-shot baseline this workbook extends to multi-step).
A19: Currency convention | B19: All inputs in USD. Use FX cell on Inputs sheet to display local-currency equivalents (UGX, KES, NGN, ZAR, EGP). Mobile-money (M-Pesa / MoMo) and card-rail fees enter as % of revenue.

Sheet Inputs
A1: Inputs — Agent Cost-Per-Task Calculator
A2: Yellow = input. White = formula. Three tiers: Free, Pro, Enterprise.
A4: 1. Tenant Mix & Volume
B5: Free | C5: Pro | D5: Enterprise | F5: Notes
A6: Tenants (count) | B6: 400 | C6: 150 | D6: 30 | F6: Active customer count by tier.
A7: Active tasks per tenant per month | B7: 50 | C7: 400 | D7: 3000 | F7: Tasks attempted per tenant per month.
A8: 2. Per-Task Agent Architecture
A9: Avg planner steps per task | B9: 1 | C9: 1 | D9: 2 | F9: Plan / decompose step(s) before workers.
A10: Avg worker steps per task | B10: 2 | C10: 4 | D10: 8 | F10: Worker LLM calls per task (single branch).
A11: Parallel branches per task | B11: 1 | C11: 1 | D11: 2 | F11: Fan-out factor for multi-agent designs. 1 = single agent.
A12: Retries factor (% of steps retried) | B12: 0.1 | C12: 0.15 | D12: 0.2 | F12: Retry-overhead multiplier on step count.
A13: Abandonment rate | B13: 0.1 | C13: 0.12 | D13: 0.15 | F13: % of attempted tasks the user abandons. Divides into cost-per-resolved.
A14: Intervention (HITL escalation) rate | B14: 0.05 | C14: 0.1 | D14: 0.15 | F14: % of tasks needing human help.
A15: HITL minutes per intervention | B15: 3 | C15: 5 | D15: 8 | F15: Avg minutes a human spends per escalated task.
A16: HITL fully-loaded $/min | B16: 0.1 | C16: 0.15 | D16: 0.5 | F16: Loaded HITL hourly rate / 60. Africa-low end Free; US-comparable Ent.
A17: 3. LLM Token Dimensions (per step, three model classes)
A18: Input tokens per step (avg) | B18: 400 | C18: 800 | D18: 1500 | F18: Prompt + RAG context + chat history per step.
A19: Output tokens per step (avg) | B19: 150 | C19: 400 | D19: 1000 | F19: Generation tokens per step.
A20: Cheap-router model $/1k input | B20: 0.0001 | C20: 0.00015 | D20: 0.0002 | F20: Routing / cheap step price. Llama / Haiku class.
A21: Cheap-router model $/1k output | B21: 0.0002 | C21: 0.0006 | D21: 0.0008
A22: Planner model $/1k input | B22: 0.0005 | C22: 0.0015 | D22: 0.0025 | F22: Planner LLM. GPT-4o-mini → GPT-4o / Sonnet.
A23: Planner model $/1k output | B23: 0.0015 | C23: 0.005 | D23: 0.01
A24: Worker model $/1k input | B24: 0.00015 | C24: 0.0005 | D24: 0.0015 | F24: Worker LLM (typically mid-tier).
A25: Worker model $/1k output | B25: 0.0006 | C25: 0.0015 | D25: 0.005
A26: 4. Tools, Vector, Observability
A27: Tool calls per task | B27: 2 | C27: 5 | D27: 10 | F27: Avg invocations to external tools per task.
A28: % of tool calls external (paid) | B28: 0.4 | C28: 0.6 | D28: 0.8 | F28: Fraction that incurs vendor cost (rest internal/free).
A29: Avg external tool call $ | B29: 0.005 | C29: 0.01 | D29: 0.02 | F29: Avg per-invocation tariff (CRM/ERP/payment/KYC/etc).
A30: Vector store $/task | B30: 0.0005 | C30: 0.001 | D30: 0.0025 | F30: Pinecone / Qdrant / pgvector per-query allocation.
A31: Observability $/task | B31: 0.0002 | C31: 0.0005 | D31: 0.0015 | F31: Langfuse / LangSmith / Helicone per-trace allocation.
A32: 5. Overheads, Retraining & Safety
A33: Eval overhead (% of LLM+tool cost) | B33: 0.08 | C33: 0.1 | D33: 0.15 | F33: Online + offline eval re-runs as a % of direct AI+tool.
A34: Retraining amortisation $/task | B34: 0 | C34: 0.0005 | D34: 0.002 | F34: Monthly retrain cost / monthly task volume.
A35: Supervision overhead (% of LLM) | B35: 0.05 | C35: 0.08 | D35: 0.12 | F35: Critic / supervisor LLM calls overhead.
A36: Safety floor — red-team $/task | B36: 0.0001 | C36: 0.0005 | D36: 0.002 | F36: Red-team monitoring, jailbreak detection.
A37: 6. Pricing & Margin Targets
A38: Per-resolved-task price ($) | B38: 0 | C38: 0.5 | D38: 2 | F38: Headline price per resolved (Free tier may be $0 / tier-bundled).
A39: S&M attribution % of revenue | B39: 0 | C39: 0.25 | D39: 0.15 | F39: Per-resolution revenue absorbed by S&M.
A40: Target agent gross margin | B40: 0.5 | C40: 0.65 | D40: 0.75 | F40: Pricing-floor target; <50 red / 50-70 amber / >70 green on Dashboard.
A41: Internal markup (cost ceiling × price) | B41: 1.3 | C41: 1.5 | D41: 1.5 | F41: If cost-per-resolved > markup × price, flag tenant as above ceiling.
...

Sheet Cost-Per-Task
A1: Cost-Per-Task — Agent COGS Waterfall (USD / task)
A2: Step inflation × LLM (planner + worker + supervision) + tools + HITL + vector + obs + eval + retraining + safety.
A3: Component | B3: Free | C3: Pro | D3: Enterprise | E3: Free ×2 steps | F3: Pro ×2 tools | G3: Ent ×2 interv. | H3: Ent ×2 abandon | I3: Formula
A4: Step inflation (steps per attempted task) | B4: =(Inputs!B9+Inputs!B10*Inputs!B11)*(1+Inputs!B12) -> 0 | C4: =(Inputs!C9+Inputs!C10*Inputs!C11)*(1+Inputs!C12) -> 0 | D4: =(Inputs!D9+Inputs!D10*Inputs!D11)*(1+Inputs!D12) -> 0
A5: LLM cost (planner + worker × branches × retries) | B5: =(Inputs!B9*(1+Inputs!B12)*(Inputs!B18*Inputs!B22+Inputs!B19*Inputs!B23)/1000+Inputs!B10*Inputs!B11*(1+Inputs!B12)*(Inputs!B18*Inputs!B24+Inputs!B19*Inputs!B25)/1000) -> 0 | C5: =(Inputs!C9*(1+Inputs!C12)*(Inputs!C18*Inputs!C22+Inputs!C19*Inputs!C23)/1000+Inputs!C10*Inputs!C11*(1+Inputs!C12)*(Inputs!C18*Inputs!C24+Inputs!C19*Inputs!C25)/1000) -> 0 | D5: =(Inputs!D9*(1+Inputs!D12)*(Inputs!D18*Inputs!D22+Inputs!D19*Inputs!D23)/1000+Inputs!D10*Inputs!D11*(1+Inputs!D12)*(Inputs!D18*Inputs!D24+Inputs!D19*Inputs!D25)/1000) -> 0
A6: Tool cost (calls × external-% × $/call) | B6: =Inputs!B27*Inputs!B28*Inputs!B29 -> 0 | C6: =Inputs!C27*Inputs!C28*Inputs!C29 -> 0 | D6: =Inputs!D27*Inputs!D28*Inputs!D29 -> 0
A7: HITL escalation cost (interv. rate × min × $/min) | B7: =Inputs!B14*Inputs!B15*Inputs!B16 -> 0 | C7: =Inputs!C14*Inputs!C15*Inputs!C16 -> 0 | D7: =Inputs!D14*Inputs!D15*Inputs!D16 -> 0
A8: Vector store / RAG per task | B8: =Inputs!B30 -> 0 | C8: =Inputs!C30 -> 0 | D8: =Inputs!D30 -> 0
A9: Observability / tracing per task | B9: =Inputs!B31 -> 0 | C9: =Inputs!C31 -> 0 | D9: =Inputs!D31 -> 0
A10: Supervision (% of LLM) | B10: =B5*Inputs!B35 -> 0 | C10: =C5*Inputs!C35 -> 0 | D10: =D5*Inputs!D35 -> 0
A11: Eval overhead (% of LLM + tool) | B11: =(B5+B6)*Inputs!B33 -> 0 | C11: =(C5+C6)*Inputs!C33 -> 0 | D11: =(D5+D6)*Inputs!D33 -> 0
A12: Retraining amortisation per task | B12: =Inputs!B34 -> 0 | C12: =Inputs!C34 -> 0 | D12: =Inputs!D34 -> 0
A13: Safety floor (red-team monitoring) | B13: =Inputs!B36 -> 0 | C13: =Inputs!C36 -> 0 | D13: =Inputs!D36 -> 0
A14: TOTAL cost per ATTEMPTED task | B14: =SUM(B5:B13) -> 0 | C14: =SUM(C5:C13) -> 0 | D14: =SUM(D5:D13) -> 0
A15: COST per RESOLVED task (÷ (1−abandonment)) | B15: =B14/(1-Inputs!B13) -> 0 | C15: =C14/(1-Inputs!C13) -> 0 | D15: =D14/(1-Inputs!D13) -> 0 | I15: The TRUE unit. Failed/abandoned tasks still consume cost; resolved outcomes carry that drag.
A16: × Tasks/month × Tenants → tier monthly cost | B16: =B14*Inputs!B7*Inputs!B6 -> 0 | C16: =C14*Inputs!C7*Inputs!C6 -> 0 | D16: =D14*Inputs!D7*Inputs!D6 -> 0
A17: Annual tier agent COGS (USD) | B17: =B16*12 -> 0 | C17: =C16*12 -> 0 | D17: =D16*12 -> 0
A18: GRAND total annual agent COGS (USD, all tiers) | B18: =SUM(B17:D17) -> 0
A21: Sensitivity columns (×2 stress vs baseline, per tier highlighted)
A22: Free — cost/resolved @ ×2 steps | B22: =( Inputs!B9*2*(1+Inputs!B12)*(Inputs!B18*Inputs!B22+Inputs!B19*Inputs!B23)/1000+ Inputs!B10*2*Inputs!B11*(1+Inputs!B12)*(Inputs!B18*Inputs!B24+Inputs!B19*Inputs!B25)/1000+ Inputs!B27*Inputs!B28*Inputs!B29+ Inputs!B14*Inputs!B15*Inputs!B16+ Inputs!B30 + Inputs!B31 + Inputs!B34 + Inputs!B36 )*(1+Inputs!B35+Inputs!B33)/(1-Inputs!B13) -> 0
A23: Pro — cost/resolved @ ×2 tool calls | B23: =( Inputs!C9*(1+Inputs!C12)*(Inputs!C18*Inputs!C22+Inputs!C19*Inputs!C23)/1000+ Inputs!C10*Inputs!C11*(1+Inputs!C12)*(Inputs!C18*Inputs!C24+Inputs!C19*Inputs!C25)/1000+ Inputs!C27*2*Inputs!C28*Inputs!C29+ Inputs!C14*Inputs!C15*Inputs!C16+ Inputs!C30 + Inputs!C31 + Inputs!C34 + Inputs!C36 )*(1+Inputs!C35+Inputs!C33)/(1-Inputs!C13) -> 0
A24: Ent — cost/resolved @ ×2 intervention rate | B24: =( Inputs!D9*(1+Inputs!D12)*(Inputs!D18*Inputs!D22+Inputs!D19*Inputs!D23)/1000+ Inputs!D10*Inputs!D11*(1+Inputs!D12)*(Inputs!D18*Inputs!D24+Inputs!D19*Inputs!D25)/1000+ Inputs!D27*Inputs!D28*Inputs!D29+ Inputs!D14*2*Inputs!D15*Inputs!D16+ Inputs!D30 + Inputs!D31 + Inputs!D34 + Inputs!D36 )*(1+Inputs!D35+Inputs!D33)/(1-Inputs!D13) -> 0
A25: Ent — cost/resolved @ ×2 abandonment rate | B25: =D14/(1-Inputs!D13*2) -> 0

Sheet Margin-Analysis
A1: Agent Margin Analysis — by Tier
A3: Line | B3: Free | C3: Pro | D3: Enterprise
A4: Per-resolved-task price ($) | B4: =Inputs!B38 -> 0 | C4: =Inputs!C38 -> 0 | D4: =Inputs!D38 -> 0
A5: Resolution rate (1 − abandonment) | B5: =1-Inputs!B13 -> 0 | C5: =1-Inputs!C13 -> 0 | D5: =1-Inputs!D13 -> 0
A6: Agent revenue per attempted task ($) | B6: =Inputs!B38*(1-Inputs!B13) -> 0 | C6: =Inputs!C38*(1-Inputs!C13) -> 0 | D6: =Inputs!D38*(1-Inputs!D13) -> 0
A7: Cost per attempted task ($) | B7: ='Cost-Per-Task'!B14 -> 0 | C7: ='Cost-Per-Task'!C14 -> 0 | D7: ='Cost-Per-Task'!D14 -> 0
A8: Cost per resolved task ($) | B8: ='Cost-Per-Task'!B15 -> 0 | C8: ='Cost-Per-Task'!C15 -> 0 | D8: ='Cost-Per-Task'!D15 -> 0
A9: Agent gross profit per resolved ($) | B9: =Inputs!B38-'Cost-Per-Task'!B15 -> 0 | C9: =Inputs!C38-'Cost-Per-Task'!C15 -> 0 | D9: =Inputs!D38-'Cost-Per-Task'!D15 -> 0
A10: Agent gross margin % | B10: =IF(Inputs!B38>0,(Inputs!B38-'Cost-Per-Task'!B15)/Inputs!B38,-1) -> 0 | C10: =IF(Inputs!C38>0,(Inputs!C38-'Cost-Per-Task'!C15)/Inputs!C38,-1) -> 0 | D10: =IF(Inputs!D38>0,(Inputs!D38-'Cost-Per-Task'!D15)/Inputs!D38,-1) -> 0
A11: S&M attribution per resolved ($) | B11: =Inputs!B38*Inputs!B39 -> 0 | C11: =Inputs!C38*Inputs!C39 -> 0 | D11: =Inputs!D38*Inputs!D39 -> 0
A12: Contribution margin per resolved ($) | B12: =Inputs!B38-'Cost-Per-Task'!B15-Inputs!B38*Inputs!B39 -> 0 | C12: =Inputs!C38-'Cost-Per-Task'!C15-Inputs!C38*Inputs!C39 -> 0 | D12: =Inputs!D38-'Cost-Per-Task'!D15-Inputs!D38*Inputs!D39 -> 0
A13: Contribution margin % | B13: =IF(Inputs!B38>0,(Inputs!B38-'Cost-Per-Task'!B15-Inputs!B38*Inputs!B39)/Inputs!B38,-1) -> 0 | C13: =IF(Inputs!C38>0,(Inputs!C38-'Cost-Per-Task'!C15-Inputs!C38*Inputs!C39)/Inputs!C38,-1) -> 0 | D13: =IF(Inputs!D38>0,(Inputs!D38-'Cost-Per-Task'!D15-Inputs!D38*Inputs!D39)/Inputs!D38,-1) -> 0
A14: Cost ceiling ($ = markup × price) | B14: =Inputs!B38*Inputs!B41 -> 0 | C14: =Inputs!C38*Inputs!C41 -> 0 | D14: =Inputs!D38*Inputs!D41 -> 0
A15: Above ceiling? (cost-per-resolved > ceiling) | B15: =IF('Cost-Per-Task'!B15>Inputs!B38*Inputs!B41,"YES","no") -> 0 | C15: =IF('Cost-Per-Task'!C15>Inputs!C38*Inputs!C41,"YES","no") -> 0 | D15: =IF('Cost-Per-Task'!D15>Inputs!D38*Inputs!D41,"YES","no") -> 0

Sheet Sensitivity
A1: Sensitivity — 2-D tables (Enterprise tier focus)
A3: 1. Tokens/step (combined in+out) × Blended $/1k → LLM cost / step
A5: Tokens ↓ $/1k → | B5: 0.0005 | C5: 0.001 | D5: 0.0025 | E5: 0.005 | F5: 0.01 | G5: 0.02 | H5: 0.05
A6: 200 | B6: =(200*0.0005)/1000 -> 0 | C6: =(200*0.001)/1000 -> 0 | D6: =(200*0.0025)/1000 -> 0 | E6: =(200*0.005)/1000 -> 0 | F6: =(200*0.01)/1000 -> 0 | G6: =(200*0.02)/1000 -> 0 | H6: =(200*0.05)/1000 -> 0
A7: 500 | B7: =(500*0.0005)/1000 -> 0 | C7: =(500*0.001)/1000 -> 0 | D7: =(500*0.0025)/1000 -> 0 | E7: =(500*0.005)/1000 -> 0 | F7: =(500*0.01)/1000 -> 0 | G7: =(500*0.02)/1000 -> 0 | H7: =(500*0.05)/1000 -> 0
A8: 1000 | B8: =(1000*0.0005)/1000 -> 0 | C8: =(1000*0.001)/1000 -> 0 | D8: =(1000*0.0025)/1000 -> 0 | E8: =(1000*0.005)/1000 -> 0 | F8: =(1000*0.01)/1000 -> 0 | G8: =(1000*0.02)/1000 -> 0 | H8: =(1000*0.05)/1000 -> 0
A9: 2000 | B9: =(2000*0.0005)/1000 -> 0 | C9: =(2000*0.001)/1000 -> 0 | D9: =(2000*0.0025)/1000 -> 0 | E9: =(2000*0.005)/1000 -> 0 | F9: =(2000*0.01)/1000 -> 0 | G9: =(2000*0.02)/1000 -> 0 | H9: =(2000*0.05)/1000 -> 0
A10: 3000 | B10: =(3000*0.0005)/1000 -> 0 | C10: =(3000*0.001)/1000 -> 0 | D10: =(3000*0.0025)/1000 -> 0 | E10: =(3000*0.005)/1000 -> 0 | F10: =(3000*0.01)/1000 -> 0 | G10: =(3000*0.02)/1000 -> 0 | H10: =(3000*0.05)/1000 -> 0
A11: 5000 | B11: =(5000*0.0005)/1000 -> 0 | C11: =(5000*0.001)/1000 -> 0 | D11: =(5000*0.0025)/1000 -> 0 | E11: =(5000*0.005)/1000 -> 0 | F11: =(5000*0.01)/1000 -> 0 | G11: =(5000*0.02)/1000 -> 0 | H11: =(5000*0.05)/1000 -> 0
A12: 8000 | B12: =(8000*0.0005)/1000 -> 0 | C12: =(8000*0.001)/1000 -> 0 | D12: =(8000*0.0025)/1000 -> 0 | E12: =(8000*0.005)/1000 -> 0 | F12: =(8000*0.01)/1000 -> 0 | G12: =(8000*0.02)/1000 -> 0 | H12: =(8000*0.05)/1000 -> 0
A15: 2. Intervention rate × HITL $/min → HITL cost / task (Ent HITL min)
A17: Interv. ↓ $/min → | B17: 0.05 | C17: 0.1 | D17: 0.2 | E17: 0.5 | F17: 1 | G17: 1.5 | H17: 2
A18: 0.02 | B18: =0.02*Inputs!D15*0.05 -> 0 | C18: =0.02*Inputs!D15*0.1 -> 0 | D18: =0.02*Inputs!D15*0.2 -> 0 | E18: =0.02*Inputs!D15*0.5 -> 0 | F18: =0.02*Inputs!D15*1.0 -> 0 | G18: =0.02*Inputs!D15*1.5 -> 0 | H18: =0.02*Inputs!D15*2.0 -> 0
A19: 0.05 | B19: =0.05*Inputs!D15*0.05 -> 0 | C19: =0.05*Inputs!D15*0.1 -> 0 | D19: =0.05*Inputs!D15*0.2 -> 0 | E19: =0.05*Inputs!D15*0.5 -> 0 | F19: =0.05*Inputs!D15*1.0 -> 0 | G19: =0.05*Inputs!D15*1.5 -> 0 | H19: =0.05*Inputs!D15*2.0 -> 0
A20: 0.1 | B20: =0.1*Inputs!D15*0.05 -> 0 | C20: =0.1*Inputs!D15*0.1 -> 0 | D20: =0.1*Inputs!D15*0.2 -> 0 | E20: =0.1*Inputs!D15*0.5 -> 0 | F20: =0.1*Inputs!D15*1.0 -> 0 | G20: =0.1*Inputs!D15*1.5 -> 0 | H20: =0.1*Inputs!D15*2.0 -> 0
A21: 0.15 | B21: =0.15*Inputs!D15*0.05 -> 0 | C21: =0.15*Inputs!D15*0.1 -> 0 | D21: =0.15*Inputs!D15*0.2 -> 0 | E21: =0.15*Inputs!D15*0.5 -> 0 | F21: =0.15*Inputs!D15*1.0 -> 0 | G21: =0.15*Inputs!D15*1.5 -> 0 | H21: =0.15*Inputs!D15*2.0 -> 0
A22: 0.2 | B22: =0.2*Inputs!D15*0.05 -> 0 | C22: =0.2*Inputs!D15*0.1 -> 0 | D22: =0.2*Inputs!D15*0.2 -> 0 | E22: =0.2*Inputs!D15*0.5 -> 0 | F22: =0.2*Inputs!D15*1.0 -> 0 | G22: =0.2*Inputs!D15*1.5 -> 0 | H22: =0.2*Inputs!D15*2.0 -> 0
A23: 0.3 | B23: =0.3*Inputs!D15*0.05 -> 0 | C23: =0.3*Inputs!D15*0.1 -> 0 | D23: =0.3*Inputs!D15*0.2 -> 0 | E23: =0.3*Inputs!D15*0.5 -> 0 | F23: =0.3*Inputs!D15*1.0 -> 0 | G23: =0.3*Inputs!D15*1.5 -> 0 | H23: =0.3*Inputs!D15*2.0 -> 0
A24: 0.5 | B24: =0.5*Inputs!D15*0.05 -> 0 | C24: =0.5*Inputs!D15*0.1 -> 0 | D24: =0.5*Inputs!D15*0.2 -> 0 | E24: =0.5*Inputs!D15*0.5 -> 0 | F24: =0.5*Inputs!D15*1.0 -> 0 | G24: =0.5*Inputs!D15*1.5 -> 0 | H24: =0.5*Inputs!D15*2.0 -> 0
A27: 3. Tools/task × External-% → tool cost / task (Ent $/call)
A29: Tools ↓ Ext% → | B29: 0.1 | C29: 0.25 | D29: 0.4 | E29: 0.6 | F29: 0.75 | G29: 0.9 | H29: 1
A30: 1 | B30: =1*0.1*Inputs!D29 -> 0 | C30: =1*0.25*Inputs!D29 -> 0 | D30: =1*0.4*Inputs!D29 -> 0 | E30: =1*0.6*Inputs!D29 -> 0 | F30: =1*0.75*Inputs!D29 -> 0 | G30: =1*0.9*Inputs!D29 -> 0 | H30: =1*1.0*Inputs!D29 -> 0
A31: 3 | B31: =3*0.1*Inputs!D29 -> 0 | C31: =3*0.25*Inputs!D29 -> 0 | D31: =3*0.4*Inputs!D29 -> 0 | E31: =3*0.6*Inputs!D29 -> 0 | F31: =3*0.75*Inputs!D29 -> 0 | G31: =3*0.9*Inputs!D29 -> 0 | H31: =3*1.0*Inputs!D29 -> 0
A32: 5 | B32: =5*0.1*Inputs!D29 -> 0 | C32: =5*0.25*Inputs!D29 -> 0 | D32: =5*0.4*Inputs!D29 -> 0 | E32: =5*0.6*Inputs!D29 -> 0 | F32: =5*0.75*Inputs!D29 -> 0 | G32: =5*0.9*Inputs!D29 -> 0 | H32: =5*1.0*Inputs!D29 -> 0
A33: 10 | B33: =10*0.1*Inputs!D29 -> 0 | C33: =10*0.25*Inputs!D29 -> 0 | D33: =10*0.4*Inputs!D29 -> 0 | E33: =10*0.6*Inputs!D29 -> 0 | F33: =10*0.75*Inputs!D29 -> 0 | G33: =10*0.9*Inputs!D29 -> 0 | H33: =10*1.0*Inputs!D29 -> 0
A34: 15 | B34: =15*0.1*Inputs!D29 -> 0 | C34: =15*0.25*Inputs!D29 -> 0 | D34: =15*0.4*Inputs!D29 -> 0 | E34: =15*0.6*Inputs!D29 -> 0 | F34: =15*0.75*Inputs!D29 -> 0 | G34: =15*0.9*Inputs!D29 -> 0 | H34: =15*1.0*Inputs!D29 -> 0
A35: 25 | B35: =25*0.1*Inputs!D29 -> 0 | C35: =25*0.25*Inputs!D29 -> 0 | D35: =25*0.4*Inputs!D29 -> 0 | E35: =25*0.6*Inputs!D29 -> 0 | F35: =25*0.75*Inputs!D29 -> 0 | G35: =25*0.9*Inputs!D29 -> 0 | H35: =25*1.0*Inputs!D29 -> 0
A36: 40 | B36: =40*0.1*Inputs!D29 -> 0 | C36: =40*0.25*Inputs!D29 -> 0 | D36: =40*0.4*Inputs!D29 -> 0 | E36: =40*0.6*Inputs!D29 -> 0 | F36: =40*0.75*Inputs!D29 -> 0 | G36: =40*0.9*Inputs!D29 -> 0 | H36: =40*1.0*Inputs!D29 -> 0
A39: 4. Parallel branches × Retries factor → step inflation multiplier (planner=1, worker=4 ref)
A41: Branches ↓ Retries → | B41: 0 | C41: 0.05 | D41: 0.1 | E41: 0.2 | F41: 0.3 | G41: 0.5 | H41: 1
A42: 1 | B42: =(1+4*1)*(1+0.0) -> 0 | C42: =(1+4*1)*(1+0.05) -> 0 | D42: =(1+4*1)*(1+0.1) -> 0 | E42: =(1+4*1)*(1+0.2) -> 0 | F42: =(1+4*1)*(1+0.3) -> 0 | G42: =(1+4*1)*(1+0.5) -> 0 | H42: =(1+4*1)*(1+1.0) -> 0
A43: 2 | B43: =(1+4*2)*(1+0.0) -> 0 | C43: =(1+4*2)*(1+0.05) -> 0 | D43: =(1+4*2)*(1+0.1) -> 0 | E43: =(1+4*2)*(1+0.2) -> 0 | F43: =(1+4*2)*(1+0.3) -> 0 | G43: =(1+4*2)*(1+0.5) -> 0 | H43: =(1+4*2)*(1+1.0) -> 0
A44: 3 | B44: =(1+4*3)*(1+0.0) -> 0 | C44: =(1+4*3)*(1+0.05) -> 0 | D44: =(1+4*3)*(1+0.1) -> 0 | E44: =(1+4*3)*(1+0.2) -> 0 | F44: =(1+4*3)*(1+0.3) -> 0 | G44: =(1+4*3)*(1+0.5) -> 0 | H44: =(1+4*3)*(1+1.0) -> 0
A45: 4 | B45: =(1+4*4)*(1+0.0) -> 0 | C45: =(1+4*4)*(1+0.05) -> 0 | D45: =(1+4*4)*(1+0.1) -> 0 | E45: =(1+4*4)*(1+0.2) -> 0 | F45: =(1+4*4)*(1+0.3) -> 0 | G45: =(1+4*4)*(1+0.5) -> 0 | H45: =(1+4*4)*(1+1.0) -> 0
A46: 5 | B46: =(1+4*5)*(1+0.0) -> 0 | C46: =(1+4*5)*(1+0.05) -> 0 | D46: =(1+4*5)*(1+0.1) -> 0 | E46: =(1+4*5)*(1+0.2) -> 0 | F46: =(1+4*5)*(1+0.3) -> 0 | G46: =(1+4*5)*(1+0.5) -> 0 | H46: =(1+4*5)*(1+1.0) -> 0
A47: 8 | B47: =(1+4*8)*(1+0.0) -> 0 | C47: =(1+4*8)*(1+0.05) -> 0 | D47: =(1+4*8)*(1+0.1) -> 0 | E47: =(1+4*8)*(1+0.2) -> 0 | F47: =(1+4*8)*(1+0.3) -> 0 | G47: =(1+4*8)*(1+0.5) -> 0 | H47: =(1+4*8)*(1+1.0) -> 0
A48: 12 | B48: =(1+4*12)*(1+0.0) -> 0 | C48: =(1+4*12)*(1+0.05) -> 0 | D48: =(1+4*12)*(1+0.1) -> 0 | E48: =(1+4*12)*(1+0.2) -> 0 | F48: =(1+4*12)*(1+0.3) -> 0 | G48: =(1+4*12)*(1+0.5) -> 0 | H48: =(1+4*12)*(1+1.0) -> 0

Sheet Stress-Test
A1: Stress-Test — Enterprise Tier Cost-Per-Resolved
A3: Scenario | B3: Cost/resolved $ | C3: Agent GM % | D3: Above ceiling? | E3: Δ vs base | F3: Mitigation
A4: Baseline | B4: =(Inputs!D9*(1+Inputs!D12+0.0)*(Inputs!D18*1.0*Inputs!D22*1.0+Inputs!D19*1.0*Inputs!D23*1.0)/1000+ Inputs!D10*Inputs!D11*(1+Inputs!D12+0.0)*(Inputs!D18*1.0*Inputs!D24*1.0+Inputs!D19*1.0*Inputs!D25*1.0)/1000+ Inputs!D27*1.0*Inputs!D28*Inputs!D29+ Inputs!D14*1.0*Inputs!D15*Inputs!D16+ Inputs!D30 + Inputs!D31 + Inputs!D34 + Inputs!D36) * (1+Inputs!D35+Inputs!D33) / (1-Inputs!D13*1.0) -> 0 | C4: =IF(Inputs!D38>0,(Inputs!D38-B4)/Inputs!D38,-1) -> 0 | D4: =IF(B4>Inputs!D38*Inputs!D41,"YES","no") -> 0 | E4: =B4-'Cost-Per-Task'!D15 -> 0 | F4: n/a — reference
A5: Provider 5× price hike | B5: =(Inputs!D9*(1+Inputs!D12+0.0)*(Inputs!D18*1.0*Inputs!D22*5.0+Inputs!D19*1.0*Inputs!D23*5.0)/1000+ Inputs!D10*Inputs!D11*(1+Inputs!D12+0.0)*(Inputs!D18*1.0*Inputs!D24*5.0+Inputs!D19*1.0*Inputs!D25*5.0)/1000+ Inputs!D27*1.0*Inputs!D28*Inputs!D29+ Inputs!D14*1.0*Inputs!D15*Inputs!D16+ Inputs!D30 + Inputs!D31 + Inputs!D34 + Inputs!D36) * (1+Inputs!D35+Inputs!D33) / (1-Inputs!D13*1.0) -> 0 | C5: =IF(Inputs!D38>0,(Inputs!D38-B5)/Inputs!D38,-1) -> 0 | D5: =IF(B5>Inputs!D38*Inputs!D41,"YES","no") -> 0 | E5: =B5-'Cost-Per-Task'!D15 -> 0 | F5: Emergency price-pass-through; switch provider; downshift router.
A6: Intervention rate doubles to ~30% | B6: =(Inputs!D9*(1+Inputs!D12+0.0)*(Inputs!D18*1.0*Inputs!D22*1.0+Inputs!D19*1.0*Inputs!D23*1.0)/1000+ Inputs!D10*Inputs!D11*(1+Inputs!D12+0.0)*(Inputs!D18*1.0*Inputs!D24*1.0+Inputs!D19*1.0*Inputs!D25*1.0)/1000+ Inputs!D27*1.0*Inputs!D28*Inputs!D29+ Inputs!D14*2.0*Inputs!D15*Inputs!D16+ Inputs!D30 + Inputs!D31 + Inputs!D34 + Inputs!D36) * (1+Inputs!D35+Inputs!D33) / (1-Inputs!D13*1.0) -> 0 | C6: =IF(Inputs!D38>0,(Inputs!D38-B6)/Inputs!D38,-1) -> 0 | D6: =IF(B6>Inputs!D38*Inputs!D41,"YES","no") -> 0 | E6: =B6-'Cost-Per-Task'!D15 -> 0 | F6: Re-train triage; tighten policy thresholds; eval round.
A7: Foundation-model deprecation (2× cost forced) | B7: =(Inputs!D9*(1+Inputs!D12+0.0)*(Inputs!D18*1.0*Inputs!D22*2.0+Inputs!D19*1.0*Inputs!D23*2.0)/1000+ Inputs!D10*Inputs!D11*(1+Inputs!D12+0.0)*(Inputs!D18*1.0*Inputs!D24*2.0+Inputs!D19*1.0*Inputs!D25*2.0)/1000+ Inputs!D27*1.0*Inputs!D28*Inputs!D29+ Inputs!D14*1.0*Inputs!D15*Inputs!D16+ Inputs!D30 + Inputs!D31 + Inputs!D34 + Inputs!D36) * (1+Inputs!D35+Inputs!D33) / (1-Inputs!D13*1.0) -> 0 | C7: =IF(Inputs!D38>0,(Inputs!D38-B7)/Inputs!D38,-1) -> 0 | D7: =IF(B7>Inputs!D38*Inputs!D41,"YES","no") -> 0 | E7: =B7-'Cost-Per-Task'!D15 -> 0 | F7: Reserve drawdown; planned migration; bench OSS fallback.
A8: Tool-vendor outage (3× calls via fallback chain) | B8: =(Inputs!D9*(1+Inputs!D12+0.1)*(Inputs!D18*1.0*Inputs!D22*1.0+Inputs!D19*1.0*Inputs!D23*1.0)/1000+ Inputs!D10*Inputs!D11*(1+Inputs!D12+0.1)*(Inputs!D18*1.0*Inputs!D24*1.0+Inputs!D19*1.0*Inputs!D25*1.0)/1000+ Inputs!D27*3.0*Inputs!D28*Inputs!D29+ Inputs!D14*1.0*Inputs!D15*Inputs!D16+ Inputs!D30 + Inputs!D31 + Inputs!D34 + Inputs!D36) * (1+Inputs!D35+Inputs!D33) / (1-Inputs!D13*1.0) -> 0 | C8: =IF(Inputs!D38>0,(Inputs!D38-B8)/Inputs!D38,-1) -> 0 | D8: =IF(B8>Inputs!D38*Inputs!D41,"YES","no") -> 0 | E8: =B8-'Cost-Per-Task'!D15 -> 0 | F8: Multi-vendor failover; degrade gracefully; SLA credit.
A9: Positive — abandonment 50%→25% (better triage) | B9: =(Inputs!D9*(1+Inputs!D12+0.0)*(Inputs!D18*1.0*Inputs!D22*1.0+Inputs!D19*1.0*Inputs!D23*1.0)/1000+ Inputs!D10*Inputs!D11*(1+Inputs!D12+0.0)*(Inputs!D18*1.0*Inputs!D24*1.0+Inputs!D19*1.0*Inputs!D25*1.0)/1000+ Inputs!D27*1.0*Inputs!D28*Inputs!D29+ Inputs!D14*1.0*Inputs!D15*Inputs!D16+ Inputs!D30 + Inputs!D31 + Inputs!D34 + Inputs!D36) * (1+Inputs!D35+Inputs!D33) / (1-Inputs!D13*0.5) -> 0 | C9: =IF(Inputs!D38>0,(Inputs!D38-B9)/Inputs!D38,-1) -> 0 | D9: =IF(B9>Inputs!D38*Inputs!D41,"YES","no") -> 0 | E9: =B9-'Cost-Per-Task'!D15 -> 0 | F9: Upside case if eval / triage improvements land.
A10: Combined shock: provider 2× + interv 2× + aband +10pp | B10: =(Inputs!D9*(1+Inputs!D12+0.0)*(Inputs!D18*1.0*Inputs!D22*2.0+Inputs!D19*1.0*Inputs!D23*2.0)/1000+ Inputs!D10*Inputs!D11*(1+Inputs!D12+0.0)*(Inputs!D18*1.0*Inputs!D24*2.0+Inputs!D19*1.0*Inputs!D25*2.0)/1000+ Inputs!D27*1.0*Inputs!D28*Inputs!D29+ Inputs!D14*2.0*Inputs!D15*Inputs!D16+ Inputs!D30 + Inputs!D31 + Inputs!D34 + Inputs!D36) * (1+Inputs!D35+Inputs!D33) / (1-(Inputs!D13+0.10)) -> 0 | C10: =IF(Inputs!D38>0,(Inputs!D38-B10)/Inputs!D38,-1) -> 0 | D10: =IF(B10>Inputs!D38*Inputs!D41,"YES","no") -> 0 | E10: =B10-'Cost-Per-Task'!D15 -> 0 | F10: Multi-front response: reprice + retrain + switch + reserve.

Sheet Dashboard
A1: Dashboard — Agent Cost-Per-Task
A4: Free — cost per attempted task ($) | B4: ='Cost-Per-Task'!B14 -> 0
A5: Pro — cost per attempted task ($) | B5: ='Cost-Per-Task'!C14 -> 0
A6: Enterprise — cost per attempted ($) | B6: ='Cost-Per-Task'!D14 -> 0
A7: Free — cost per RESOLVED task ($) | B7: ='Cost-Per-Task'!B15 -> 0
A8: Pro — cost per RESOLVED task ($) | B8: ='Cost-Per-Task'!C15 -> 0
A9: Enterprise — cost per RESOLVED ($) | B9: ='Cost-Per-Task'!D15 -> 0
A10: Free agent GM % | B10: ='Margin-Analysis'!B10 -> 0
A11: Pro agent GM % | B11: ='Margin-Analysis'!C10 -> 0
A12: Enterprise agent GM % | B12: ='Margin-Analysis'!D10 -> 0
A13: Pro contribution margin % | B13: ='Margin-Analysis'!C13 -> 0
A14: Enterprise contribution margin % | B14: ='Margin-Analysis'!D13 -> 0
A15: GRAND annual agent COGS (USD all tiers) | B15: ='Cost-Per-Task'!B18 -> 0
A16: GRAND annual COGS in UGX | B16: ='Cost-Per-Task'!B18*FX_UGX_A -> 0
A17: Baseline (AI-cost-of-tenant calc) cross-ref | B17: See skills/14-ai-integration/templates/saas-ai-cost-of-tenant-calculator.xlsx — agent COGS extends that single-shot model

Sheet Africa-Notes
A1: Africa-Specific Adjustments & Notes
A3: FX Pass-Through | B3: USD-denominated cloud (AWS/Azure/GCP), AI APIs, and SaaS tooling sit against UGX/KES/NGN/ZAR/EGP revenue. Adjust gross-margin benchmarks 5–10pp downward vs US comps. Hold an FX rate on Inputs and stress it ±15% in the sensitivity tab.
A4: M-Pesa Payment Rail (Kenya, Tanzania) | B4: Typical fee 1.0–1.5% per transaction. STK-Push timeout failures generate involuntary churn — model 3-retry dunning over 7 days; recovery typically 30–50%. Track separately from voluntary churn.
A5: MoMo (MTN / Airtel — Uganda, Ghana, Rwanda, Nigeria) | B5: Fee band 1.5–2.0% per transaction. PIN-failure and float-shortage produce 4–6% annual involuntary churn vs <1% US card rails. Best-practice: integrate two rails (MoMo + card) and route based on tier.
A6: Card Rails (Flutterwave / Paystack / Stripe) | B6: Card fees 2.9–3.8% + fixed. Card-decline rate 8–15% on first attempt for African issuing banks. Use Account-Updater services where available.
A7: USD-Enterprise Tier | B7: Charge Enterprise customers (>$1k MRR) in USD invoiced via local entity or offshore SPV to hedge FX. Carries through to the Multi-Step P&L as a separate revenue stream. Recommended for 30–60% of total ARR by Y3.
A8: Longer Collection Cycles | B8: Enterprise/public-sector DSO in Africa: 60–120 days (vs 30–45 US). Working-capital trough is deeper. Buffer trough at 9 months of opex vs the US 6-month standard.
A9: Annual Prepayment Uptake | B9: African SaaS: 20–40% of new contracts pay annually (vs 60–80% US enterprise). Discount typically 10–15%. Model deferred revenue accordingly — do not assume US prepayment economics.
A10: Sales-Cycle Length | B10: African mid-market sales cycle: 90–180 days. Enterprise: 6–18 months including procurement / public-sector RFP loops. CAC-payback benchmarks: relax US targets by 50–100%: <18 (SMB), <24 (Mid), <36 (Ent).
A11: AI Cost Hedging | B11: LLM APIs are USD-priced. Hedge via (a) USD-priced AI premium tier, (b) per-tenant usage caps, (c) open-source model fallback (Llama-class on Bedrock/Together). The AI-cost calculator workbook models all three.
A12: DFI / Local-Bank Reporting | B12: Banks (Stanbic, Equity, KCB, Centenary) and DFIs (FMO, Norfund, Proparco, IFC) require local-currency primary view + USD parallel view. Build the model in USD here; toggle the FX row on Inputs for local presentation.
A13: Rule-of-40 Calibration | B13: Adjust to target 30 for years 1–3 of African SaaS (vs US 40). Aim for 40 by Year 4 once vertical S&M is unlocked.
A14: Per-Resolution Pricing under FX | B14: Agent per-resolution prices charged in local currency face USD-denominated LLM and tool cost. Include an FX corridor in pricing (re-price quarterly if FX moves >5%); Enterprise SLAs in USD. The model must hold across +/-20% FX swing per saas-agent-pricing-strategy.
... A20: Channel Cost as Per-Task Line Item | B20: WhatsApp Business API, USSD aggregator fees, SMS, IVR — these are real per-task costs in African contexts. Roll them into the external-tool cost ($/call × calls/task) cell with documented breakdown.
