Workbook
Name ARPA_C: Inputs!$B$12
Name Bank_Invol: Inputs!$B$30
Name Bank_Mix: Inputs!$B$26
Name Base_Logo_Churn: Inputs!$B$17
Name Base_Rev_Churn: Inputs!$B$20
Name Card_Invol: Inputs!$B$29
Name Card_Mix: Inputs!$B$25
Name Churn_Floor: Inputs!$B$19
Name Contraction_C: Inputs!$B$14
Name Decay_Factor: Inputs!$B$18
Name Dunning_Recovery: Inputs!$B$31
Name Expansion_C: Inputs!$B$13
Name FX_C: Inputs!$B$35
Name MoMo_Invol: Inputs!$B$28
Name MoMo_Mix: Inputs!$B$24
Name MPesa_Invol: Inputs!$B$27
Name MPesa_Mix: Inputs!$B$23

Sheet README
A1: SaaS Cohort & Retention Model
A3: Purpose | B3: 36-month logo and revenue cohort retention matrix with optional tenure-decay (churn falls as cohorts mature), NRR / GRR trend, and separate involuntary-churn tracking by African payment rail (M-Pesa, MoMo, card). Surfaces the 'smile curve' test that distinguishes net-negative-churn SaaS from acquisition-treadmill SaaS.
A5: Sheets in this workbook
A6: Inputs | B6: New logos by channel (12 mo), ARPA, base churn, tenure decay factor, expansion, involuntary churn by rail.
A7: Logo-Cohort | B7: 36-month logo retention matrix, formula-driven, with cohort heatmap.
A8: Revenue-Cohort | B8: Revenue-weighted retention with expansion compounding; smile-curve test.
A9: NRR-GRR | B9: Aggregate NRR and GRR trended monthly; trigger thresholds.
A10: Involuntary-Churn | B10: Dunning-recoverable vs hard-lost across M-Pesa / MoMo / Card rails.
A11: Dashboard | B11: Cohort heatmap, NRR trend, churn curve, smile-curve test.
A12: Africa-Notes | B12: Payment-rail mechanics, public-sector cohort split, regional split discipline.
A14: Owner | B14: CFO / Head of Customer Success
A15: Update cadence | B15: Monthly cohort refresh from billing system. Quarterly QBR slide.
A16: Living-plan discipline | B16: All yellow cells are user-editable inputs. White cells are formulas — do not overwrite. Refresh inputs on the cadence above. Any variance >10% versus plan triggers a re-plan loop per skills/meta-living-plan-governance.
A17: Sources / methodology | B17: Mersch (Hacking SaaS) ch. 11; Skok forentrepreneurs.com; ChartMogul SaaS Benchmarks; Garbugli.
A19: Currency convention | B19: All inputs in USD. Use FX cell on Inputs sheet to display local-currency equivalents (UGX, KES, NGN, ZAR, EGP). Mobile-money (M-Pesa / MoMo) and card-rail fees enter as % of revenue.

Sheet Inputs
A1: Inputs — Cohort & Retention Model
A3: 1. New Logos Acquired per Month (12 cohorts)
A4: Month / Cohort | B4: M01 | C4: M02 | D4: M03 | E4: M04 | F4: M05 | G4: M06 | H4: M07 | I4: M08 | J4: M09 | K4: M10 | L4: M11 | M4: M12
A5: Paid channel | B5: 3 | C5: 4 | D5: 5 | E5: 6 | F5: 8 | G5: 10 | H5: 12 | I5: 12 | J5: 15 | K5: 15 | L5: 18 | M5: 20
A6: Inbound channel | B6: 5 | C6: 6 | D6: 7 | E6: 9 | F6: 12 | G6: 15 | H6: 18 | I6: 20 | J6: 22 | K6: 25 | L6: 28 | M6: 32
A7: Outbound channel | B7: 2 | C7: 2 | D7: 3 | E7: 4 | F7: 5 | G7: 6 | H7: 8 | I7: 10 | J7: 12 | K7: 12 | L7: 14 | M7: 16
A8: Partner channel | B8: 1 | C8: 1 | D8: 2 | E8: 2 | F8: 3 | G8: 4 | H8: 5 | I8: 5 | J8: 6 | K8: 7 | L8: 8 | M8: 10
A9: Total new logos (calc) | B9: =SUM(B5:B8) -> 0 | C9: =SUM(C5:C8) -> 0 | D9: =SUM(D5:D8) -> 0 | E9: =SUM(E5:E8) -> 0 | F9: =SUM(F5:F8) -> 0 | G9: =SUM(G5:G8) -> 0 | H9: =SUM(H5:H8) -> 0 | I9: =SUM(I5:I8) -> 0 | ... M9: =SUM(M5:M8) -> 0
A11: 2. Pricing & Expansion
A12: ARPA ($/month) | B12: 79
A13: Monthly expansion rate (existing customers) | B13: 0.012
A14: Monthly contraction rate | B14: 0.004
A16: 3. Churn — Base + Tenure Decay
A17: Base monthly logo churn (M1) | B17: 0.04 | D17: Rationale: cohorts mature → churn falls. 0.97 means each month's churn is 97% of the prior month's.
A18: Tenure decay factor (per month, applied multiplicatively) | B18: 0.97
A19: Floor monthly logo churn (long-run) | B19: 0.01
A20: Monthly revenue (gross) churn (base) | B20: 0.03
A22: 4. Involuntary Churn by Payment Rail
A23: % revenue collected via M-Pesa | B23: 0.35
A24: % revenue collected via MoMo (MTN/Airtel) | B24: 0.3
A25: % revenue collected via card / Stripe / Flutterwave | B25: 0.25
A26: % revenue collected via bank-transfer / invoice | B26: 0.1
A27: M-Pesa monthly involuntary churn | B27: 0.005
A28: MoMo monthly involuntary churn | B28: 0.008
A29: Card monthly involuntary churn | B29: 0.006
A30: Bank-transfer monthly involuntary churn | B30: 0.001
A31: Dunning recovery rate | B31: 0.4 | D31: % of failed payments recovered via 3-retry dunning over 7 days.
A33: 5. FX
A34: Reporting currency | B34: UGX
A35: FX (local per 1 USD) | B35: 3800

Sheet Logo-Cohort
A1: Logo Cohort Retention (% of original cohort still active)
A3: Retention(t) = retention(t-1) × (1 - churn_t), churn_t = MAX(floor, base × decay^t)
A5: Cohort | B5: M0 | C5: M1 | D5: M2 | E5: M3 | F5: M4 | G5: M5 | H5: M6 | I5: M7 | J5: M8 | K5: M9 | L5: M10 | M5: M11 | N5: M12 | O5: M13 | P5: M14 | Q5: M15 | R5: M16 | S5: M17 | T5: M18 | U5: M19 | V5: M20 | W5: M21 | X5: M22 | Y5: M23 | Z5: M24 | AA5: M25 | AB5: M26 | AC5: M27 | AD5: M28 | AE5: M29 | AF5: M30 | AG5: M31 | AH5: M32 | AI5: M33 | AJ5: M34 | AK5: M35 | AL5: M36
A6: Cohort 01 | B6: 1 | C6: =B6*(1-MAX(Churn_Floor, Base_Logo_Churn*Decay_Factor^0)) -> 0 | D6: =C6*(1-MAX(Churn_Floor, Base_Logo_Churn*Decay_Factor^1)) -> 0 | E6: =D6*(1-MAX(Churn_Floor, Base_Logo_Churn*Decay_Factor^2)) -> 0 | F6: =E6*(1-MAX(Churn_Floor, Base_Logo_Churn*Decay_Factor^3)) -> 0 | G6: =F6*(1-MAX(Churn_Floor, Base_Logo_Churn*Decay_Factor^4)) -> 0 | H6: =G6*(1-MAX(Churn_Floor, Base_Logo_Churn*Decay_Factor^5)) -> 0 | I6: =H6*(1-MAX(Churn_Floor, Base_Logo_Churn*Decay_Factor^6)) -> 0 | J6: =I6*(1-MAX(Churn_Floor, Base_Logo_Churn*Decay_Factor^7)) -> 0 | K6: =J6*(1-MAX(Churn_Floor, Base_Logo_Churn*Decay_Factor^8)) -> 0 | L6: =K6*(1-MAX(Churn_Floor, Base_Logo_Churn*Decay_Factor^9)) -> 0 | M6: =L6*(1-MAX(Churn_Floor, Base_Logo_Churn*Decay_Factor^10)) -> 0 | N6: =M6*(1-MAX(Churn_Floor, Base_Logo_Churn*Decay_Factor^11)) -> 0 | O6: =N6*(1-MAX(Churn_Floor, Base_Logo_Churn*Decay_Factor^12)) -> 0 | P6: =O6*(1-MAX(Churn_Floor, Base_Logo_Churn*Decay_Factor^13)) -> 0 | Q6: =P6*(1-MAX(Churn_Floor, Base_Logo_Churn*Decay_Factor^14)) -> 0 | R6: =Q6*(1-MAX(Churn_Floor, Base_Logo_Churn*Decay_Factor^15)) -> 0 | S6: =R6*(1-MAX(Churn_Floor, Base_Logo_Churn*Decay_Factor^16)) -> 0 | T6: =S6*(1-MAX(Churn_Floor, Base_Logo_Churn*Decay_Factor^17)) -> 0 | U6: =T6*(1-MAX(Churn_Floor, Base_Logo_Churn*Decay_Factor^18)) -> 0 | V6: =U6*(1-MAX(Churn_Floor, Base_Logo_Churn*Decay_Factor^19)) -> 0 | W6: =V6*(1-MAX(Churn_Floor, Base_Logo_Churn*Decay_Factor^20)) -> 0 | X6: =W6*(1-MAX(Churn_Floor, Base_Logo_Churn*Decay_Factor^21)) -> 0 | Y6: =X6*(1-MAX(Churn_Floor, Base_Logo_Churn*Decay_Factor^22)) -> 0 | Z6: =Y6*(1-MAX(Churn_Floor, Base_Logo_Churn*Decay_Factor^23)) -> 0 | AA6: =Z6*(1-MAX(Churn_Floor, Base_Logo_Churn*Decay_Factor^24)) -> 0 | AB6: =AA6*(1-MAX(Churn_Floor, Base_Logo_Churn*Decay_Factor^25)) -> 0 | AC6: =AB6*(1-MAX(Churn_Floor, Base_Logo_Churn*Decay_Factor^26)) -> 0 | AD6: =AC6*(1-MAX(Churn_Floor, Base_Logo_Churn*Decay_Factor^27)) -> 0 | AE6: =AD6*(1-MAX(Churn_Floor, Base_Logo_Churn*Decay_Factor^28)) -> 0 | AF6: =AE6*(1-MAX(Churn_Floor, Base_Logo_Churn*Decay_Factor^29)) -> 0 | AG6: =AF6*(1-MAX(Churn_Floor, Base_Logo_Churn*Decay_Factor^30)) -> 0 | AH6: =AG6*(1-MAX(Churn_Floor, Base_Logo_Churn*Decay_Factor^31)) -> 0 | AI6: =AH6*(1-MAX(Churn_Floor, Base_Logo_Churn*Decay_Factor^32)) -> 0 | AJ6: =AI6*(1-MAX(Churn_Floor, Base_Logo_Churn*Decay_Factor^33)) -> 0 | AK6: =AJ6*(1-MAX(Churn_Floor, Base_Logo_Churn*Decay_Factor^34)) -> 0 | AL6: =AK6*(1-MAX(Churn_Floor, Base_Logo_Churn*Decay_Factor^35)) -> 0
A7: Cohort 02 | B7: 1 | C7: =B7*(1-MAX(Churn_Floor, Base_Logo_Churn*Decay_Factor^0)) -> 0 | D7: =C7*(1-MAX(Churn_Floor, Base_Logo_Churn*Decay_Factor^1)) -> 0 | E7: =D7*(1-MAX(Churn_Floor, Base_Logo_Churn*Decay_Factor^2)) -> 0 | F7: =E7*(1-MAX(Churn_Floor, Base_Logo_Churn*Decay_Factor^3)) -> 0 | G7: =F7*(1-MAX(Churn_Floor, Base_Logo_Churn*Decay_Factor^4)) -> 0 | H7: =G7*(1-MAX(Churn_Floor, Base_Logo_Churn*Decay_Factor^5)) -> 0 | I7: =H7*(1-MAX(Churn_Floor, Base_Logo_Churn*Decay_Factor^6)) -> 0 | J7: =I7*(1-MAX(Churn_Floor, Base_Logo_Churn*Decay_Factor^7)) -> 0 | K7: =J7*(1-MAX(Churn_Floor, Base_Logo_Churn*Decay_Factor^8)) -> 0 | L7: =K7*(1-MAX(Churn_Floor, Base_Logo_Churn*Decay_Factor^9)) -> 0 | M7: =L7*(1-MAX(Churn_Floor, Base_Logo_Churn*Decay_Factor^10)) -> 0 | N7: =M7*(1-MAX(Churn_Floor, Base_Logo_Churn*Decay_Factor^11)) -> 0 | O7: =N7*(1-MAX(Churn_Floor, Base_Logo_Churn*Decay_Factor^12)) -> 0 | P7: =O7*(1-MAX(Churn_Floor, Base_Logo_Churn*Decay_Factor^13)) -> 0 | Q7: =P7*(1-MAX(Churn_Floor, Base_Logo_Churn*Decay_Factor^14)) -> 0 | R7: =Q7*(1-MAX(Churn_Floor, Base_Logo_Churn*Decay_Factor^15)) -> 0 | S7: =R7*(1-MAX(Churn_Floor, Base_Logo_Churn*Decay_Factor^16)) -> 0 | T7: =S7*(1-MAX(Churn_Floor, Base_Logo_Churn*Decay_Factor^17)) -> 0 | U7: =T7*(1-MAX(Churn_Floor, Base_Logo_Churn*Decay_Factor^18)) -> 0 | V7: =U7*(1-MAX(Churn_Floor, Base_Logo_Churn*Decay_Factor^19)) -> 0 | W7: =V7*(1-MAX(Churn_Floor, Base_Logo_Churn*Decay_Factor^20)) -> 0 | X7: =W7*(1-MAX(Churn_Floor, Base_Logo_Churn*Decay_Factor^21)) -> 0 | Y7: =X7*(1-MAX(Churn_Floor, Base_Logo_Churn*Decay_Factor^22)) -> 0 | Z7: =Y7*(1-MAX(Churn_Floor, Base_Logo_Churn*Decay_Factor^23)) -> 0 | AA7: =Z7*(1-MAX(Churn_Floor, Base_Logo_Churn*Decay_Factor^24)) -> 0 | AB7: =AA7*(1-MAX(Churn_Floor, Base_Logo_Churn*Decay_Factor^25)) -> 0 | AC7: =AB7*(1-MAX(Churn_Floor, Base_Logo_Churn*Decay_Factor^26)) -> 0 | AD7: =AC7*(1-MAX(Churn_Floor, Base_Logo_Churn*Decay_Factor^27)) -> 0 | AE7: =AD7*(1-MAX(Churn_Floor, Base_Logo_Churn*Decay_Factor^28)) -> 0 | AF7: =AE7*(1-MAX(Churn_Floor, Base_Logo_Churn*Decay_Factor^29)) -> 0 | AG7: =AF7*(1-MAX(Churn_Floor, Base_Logo_Churn*Decay_Factor^30)) -> 0 | AH7: =AG7*(1-MAX(Churn_Floor, Base_Logo_Churn*Decay_Factor^31)) -> 0 | AI7: =AH7*(1-MAX(Churn_Floor, Base_Logo_Churn*Decay_Factor^32)) -> 0 | AJ7: =AI7*(1-MAX(Churn_Floor, Base_Logo_Churn*Decay_Factor^33)) -> 0 | AK7: =AJ7*(1-MAX(Churn_Floor, Base_Logo_Churn*Decay_Factor^34)) -> 0 | AL7: =AK7*(1-MAX(Churn_Floor, Base_Logo_Churn*Decay_Factor^35)) -> 0
A8: Cohort 03 | B8: 1 | C8: =B8*(1-MAX(Churn_Floor, Base_Logo_Churn*Decay_Factor^0)) -> 0 | D8: =C8*(1-MAX(Churn_Floor, Base_Logo_Churn*Decay_Factor^1)) -> 0 | E8: =D8*(1-MAX(Churn_Floor, Base_Logo_Churn*Decay_Factor^2)) -> 0 | F8: =E8*(1-MAX(Churn_Floor, Base_Logo_Churn*Decay_Factor^3)) -> 0 | G8: =F8*(1-MAX(Churn_Floor, Base_Logo_Churn*Decay_Factor^4)) -> 0 | H8: =G8*(1-MAX(Churn_Floor, Base_Logo_Churn*Decay_Factor^5)) -> 0 | I8: =H8*(1-MAX(Churn_Floor, Base_Logo_Churn*Decay_Factor^6)) -> 0 | J8: =I8*(1-MAX(Churn_Floor, Base_Logo_Churn*Decay_Factor^7)) -> 0 | K8: =J8*(1-MAX(Churn_Floor, Base_Logo_Churn*Decay_Factor^8)) -> 0 | L8: =K8*(1-MAX(Churn_Floor, Base_Logo_Churn*Decay_Factor^9)) -> 0 | M8: =L8*(1-MAX(Churn_Floor, Base_Logo_Churn*Decay_Factor^10)) -> 0 | N8: =M8*(1-MAX(Churn_Floor, Base_Logo_Churn*Decay_Factor^11)) -> 0 | O8: =N8*(1-MAX(Churn_Floor, Base_Logo_Churn*Decay_Factor^12)) -> 0 | P8: =O8*(1-MAX(Churn_Floor, Base_Logo_Churn*Decay_Factor^13)) -> 0 | Q8: =P8*(1-MAX(Churn_Floor, Base_Logo_Churn*Decay_Factor^14)) -> 0 | R8: =Q8*(1-MAX(Churn_Floor, Base_Logo_Churn*Decay_Factor^15)) -> 0 | S8: =R8*(1-MAX(Churn_Floor, Base_Logo_Churn*Decay_Factor^16)) -> 0 | T8: =S8*(1-MAX(Churn_Floor, Base_Logo_Churn*Decay_Factor^17)) -> 0 | U8: =T8*(1-MAX(Churn_Floor, Base_Logo_Churn*Decay_Factor^18)) -> 0 | V8: =U8*(1-MAX(Churn_Floor, Base_Logo_Churn*Decay_Factor^19)) -> 0 | W8: =V8*(1-MAX(Churn_Floor, Base_Logo_Churn*Decay_Factor^20)) -> 0 | X8: =W8*(1-MAX(Churn_Floor, Base_Logo_Churn*Decay_Factor^21)) -> 0 | Y8: =X8*(1-MAX(Churn_Floor, Base_Logo_Churn*Decay_Factor^22)) -> 0 | Z8: =Y8*(1-MAX(Churn_Floor, Base_Logo_Churn*Decay_Factor^23)) -> 0 | AA8: =Z8*(1-MAX(Churn_Floor, Base_Logo_Churn*Decay_Factor^24)) -> 0 | AB8: =AA8*(1-MAX(Churn_Floor, Base_Logo_Churn*Decay_Factor^25)) -> 0 | AC8: =AB8*(1-MAX(Churn_Floor, Base_Logo_Churn*Decay_Factor^26)) -> 0 | AD8: =AC8*(1-MAX(Churn_Floor, Base_Logo_Churn*Decay_Factor^27)) -> 0 | AE8: =AD8*(1-MAX(Churn_Floor, Base_Logo_Churn*Decay_Factor^28)) -> 0 | AF8: =AE8*(1-MAX(Churn_Floor, Base_Logo_Churn*Decay_Factor^29)) -> 0 | AG8: =AF8*(1-MAX(Churn_Floor, Base_Logo_Churn*Decay_Factor^30)) -> 0 | AH8: =AG8*(1-MAX(Churn_Floor, Base_Logo_Churn*Decay_Factor^31)) -> 0 | AI8: =AH8*(1-MAX(Churn_Floor, Base_Logo_Churn*Decay_Factor^32)) -> 0 | AJ8: =AI8*(1-MAX(Churn_Floor, Base_Logo_Churn*Decay_Factor^33)) -> 0 | AK8: =AJ8*(1-MAX(Churn_Floor, Base_Logo_Churn*Decay_Factor^34)) -> 0 | AL8: =AK8*(1-MAX(Churn_Floor, Base_Logo_Churn*Decay_Factor^35)) -> 0
A9: Cohort 04 | B9: 1 | C9: =B9*(1-MAX(Churn_Floor, Base_Logo_Churn*Decay_Factor^0)) -> 0 | D9: =C9*(1-MAX(Churn_Floor, Base_Logo_Churn*Decay_Factor^1)) -> 0 | E9: =D9*(1-MAX(Churn_Floor, Base_Logo_Churn*Decay_Factor^2)) -> 0 | F9: =E9*(1-MAX(Churn_Floor, Base_Logo_Churn*Decay_Factor^3)) -> 0 | G9: =F9*(1-MAX(Churn_Floor, Base_Logo_Churn*Decay_Factor^4)) -> 0 | H9: =G9*(1-MAX(Churn_Floor, Base_Logo_Churn*Decay_Factor^5)) -> 0 | I9: =H9*(1-MAX(Churn_Floor, Base_Logo_Churn*Decay_Factor^6)) -> 0 | J9: =I9*(1-MAX(Churn_Floor, Base_Logo_Churn*Decay_Factor^7)) -> 0 | K9: =J9*(1-MAX(Churn_Floor, Base_Logo_Churn*Decay_Factor^8)) -> 0 | L9: =K9*(1-MAX(Churn_Floor, Base_Logo_Churn*Decay_Factor^9)) -> 0 | M9: =L9*(1-MAX(Churn_Floor, Base_Logo_Churn*Decay_Factor^10)) -> 0 | N9: =M9*(1-MAX(Churn_Floor, Base_Logo_Churn*Decay_Factor^11)) -> 0 | O9: =N9*(1-MAX(Churn_Floor, Base_Logo_Churn*Decay_Factor^12)) -> 0 | P9: =O9*(1-MAX(Churn_Floor, Base_Logo_Churn*Decay_Factor^13)) -> 0 | Q9: =P9*(1-MAX(Churn_Floor, Base_Logo_Churn*Decay_Factor^14)) -> 0 | R9: =Q9*(1-MAX(Churn_Floor, Base_Logo_Churn*Decay_Factor^15)) -> 0 | S9: =R9*(1-MAX(Churn_Floor, Base_Logo_Churn*Decay_Factor^16)) -> 0 | T9: =S9*(1-MAX(Churn_Floor, Base_Logo_Churn*Decay_Factor^17)) -> 0 | U9: =T9*(1-MAX(Churn_Floor, Base_Logo_Churn*Decay_Factor^18)) -> 0 | V9: =U9*(1-MAX(Churn_Floor, Base_Logo_Churn*Decay_Factor^19)) -> 0 | W9: =V9*(1-MAX(Churn_Floor, Base_Logo_Churn*Decay_Factor^20)) -> 0 | X9: =W9*(1-MAX(Churn_Floor, Base_Logo_Churn*Decay_Factor^21)) -> 0 | Y9: =X9*(1-MAX(Churn_Floor, Base_Logo_Churn*Decay_Factor^22)) -> 0 | Z9: =Y9*(1-MAX(Churn_Floor, Base_Logo_Churn*Decay_Factor^23)) -> 0 | AA9: =Z9*(1-MAX(Churn_Floor, Base_Logo_Churn*Decay_Factor^24)) -> 0 | AB9: =AA9*(1-MAX(Churn_Floor, Base_Logo_Churn*Decay_Factor^25)) -> 0 | AC9: =AB9*(1-MAX(Churn_Floor, Base_Logo_Churn*Decay_Factor^26)) -> 0 | AD9: =AC9*(1-MAX(Churn_Floor, Base_Logo_Churn*Decay_Factor^27)) -> 0 | AE9: =AD9*(1-MAX(Churn_Floor, Base_Logo_Churn*Decay_Factor^28)) -> 0 | AF9: =AE9*(1-MAX(Churn_Floor, Base_Logo_Churn*Decay_Factor^29)) -> 0 | AG9: =AF9*(1-MAX(Churn_Floor, Base_Logo_Churn*Decay_Factor^30)) -> 0 | AH9: =AG9*(1-MAX(Churn_Floor, Base_Logo_Churn*Decay_Factor^31)) -> 0 | AI9: =AH9*(1-MAX(Churn_Floor, Base_Logo_Churn*Decay_Factor^32)) -> 0 | AJ9: =AI9*(1-MAX(Churn_Floor, Base_Logo_Churn*Decay_Factor^33)) -> 0 | AK9: =AJ9*(1-MAX(Churn_Floor, Base_Logo_Churn*Decay_Factor^34)) -> 0 | AL9: =AK9*(1-MAX(Churn_Floor, Base_Logo_Churn*Decay_Factor^35)) -> 0
A10: Cohort 05 | B10: 1 | C10: =B10*(1-MAX(Churn_Floor, Base_Logo_Churn*Decay_Factor^0)) -> 0 | D10: =C10*(1-MAX(Churn_Floor, Base_Logo_Churn*Decay_Factor^1)) -> 0 | E10: =D10*(1-MAX(Churn_Floor, Base_Logo_Churn*Decay_Factor^2)) -> 0 | F10: =E10*(1-MAX(Churn_Floor, Base_Logo_Churn*Decay_Factor^3)) -> 0 | G10: =F10*(1-MAX(Churn_Floor, Base_Logo_Churn*Decay_Factor^4)) -> 0 | H10: =G10*(1-MAX(Churn_Floor, Base_Logo_Churn*Decay_Factor^5)) -> 0 | I10: =H10*(1-MAX(Churn_Floor, Base_Logo_Churn*Decay_Factor^6)) -> 0 | J10: =I10*(1-MAX(Churn_Floor, Base_Logo_Churn*Decay_Factor^7)) -> 0 | K10: =J10*(1-MAX(Churn_Floor, Base_Logo_Churn*Decay_Factor^8)) -> 0 | L10: =K10*(1-MAX(Churn_Floor, Base_Logo_Churn*Decay_Factor^9)) -> 0 | M10: =L10*(1-MAX(Churn_Floor, Base_Logo_Churn*Decay_Factor^10)) -> 0 | N10: =M10*(1-MAX(Churn_Floor, Base_Logo_Churn*Decay_Factor^11)) -> 0 | O10: =N10*(1-MAX(Churn_Floor, Base_Logo_Churn*Decay_Factor^12)) -> 0 | P10: =O10*(1-MAX(Churn_Floor, Base_Logo_Churn*Decay_Factor^13)) -> 0 | Q10: =P10*(1-MAX(Churn_Floor, Base_Logo_Churn*Decay_Factor^14)) -> 0 | R10: =Q10*(1-MAX(Churn_Floor, Base_Logo_Churn*Decay_Factor^15)) -> 0 | S10: =R10*(1-MAX(Churn_Floor, Base_Logo_Churn*Decay_Factor^16)) -> 0 | T10: =S10*(1-MAX(Churn_Floor, Base_Logo_Churn*Decay_Factor^17)) -> 0 | U10: =T10*(1-MAX(Churn_Floor, Base_Logo_Churn*Decay_Factor^18)) -> 0 | V10: =U10*(1-MAX(Churn_Floor, Base_Logo_Churn*Decay_Factor^19)) -> 0 | W10: =V10*(1-MAX(Churn_Floor, Base_Logo_Churn*Decay_Factor^20)) -> 0 | X10: =W10*(1-MAX(Churn_Floor, Base_Logo_Churn*Decay_Factor^21)) -> 0 | Y10: =X10*(1-MAX(Churn_Floor, Base_Logo_Churn*Decay_Factor^22)) -> 0 | Z10: =Y10*(1-MAX(Churn_Floor, Base_Logo_Churn*Decay_Factor^23)) -> 0 | AA10: =Z10*(1-MAX(Churn_Floor, Base_Logo_Churn*Decay_Factor^24)) -> 0 | AB10: =AA10*(1-MAX(Churn_Floor, Base_Logo_Churn*Decay_Factor^25)) -> 0 | AC10: =AB10*(1-MAX(Churn_Floor, Base_Logo_Churn*Decay_Factor^26)) -> 0 | AD10: =AC10*(1-MAX(Churn_Floor, Base_Logo_Churn*Decay_Factor^27)) -> 0 | AE10: =AD10*(1-MAX(Churn_Floor, Base_Logo_Churn*Decay_Factor^28)) -> 0 | AF10: =AE10*(1-MAX(Churn_Floor, Base_Logo_Churn*Decay_Factor^29)) -> 0 | AG10: =AF10*(1-MAX(Churn_Floor, Base_Logo_Churn*Decay_Factor^30)) -> 0 | AH10: =AG10*(1-MAX(Churn_Floor, Base_Logo_Churn*Decay_Factor^31)) -> 0 | AI10: =AH10*(1-MAX(Churn_Floor, Base_Logo_Churn*Decay_Factor^32)) -> 0 | AJ10: =AI10*(1-MAX(Churn_Floor, Base_Logo_Churn*Decay_Factor^33)) -> 0 | AK10: =AJ10*(1-MAX(Churn_Floor, Base_Logo_Churn*Decay_Factor^34)) -> 0 | AL10: =AK10*(1-MAX(Churn_Floor, Base_Logo_Churn*Decay_Factor^35)) -> 0
A11: Cohort 06 | B11: 1 | C11: =B11*(1-MAX(Churn_Floor, Base_Logo_Churn*Decay_Factor^0)) -> 0 | D11: =C11*(1-MAX(Churn_Floor, Base_Logo_Churn*Decay_Factor^1)) -> 0 | E11: =D11*(1-MAX(Churn_Floor, Base_Logo_Churn*Decay_Factor^2)) -> 0 | F11: =E11*(1-MAX(Churn_Floor, Base_Logo_Churn*Decay_Factor^3)) -> 0 | G11: =F11*(1-MAX(Churn_Floor, Base_Logo_Churn*Decay_Factor^4)) -> 0 | H11: =G11*(1-MAX(Churn_Floor, Base_Logo_Churn*Decay_Factor^5)) -> 0 | I11: =H11*(1-MAX(Churn_Floor, Base_Logo_Churn*Decay_Factor^6)) -> 0 | J11: =I11*(1-MAX(Churn_Floor, Base_Logo_Churn*Decay_Factor^7)) -> 0 | K11: =J11*(1-MAX(Churn_Floor, Base_Logo_Churn*Decay_Factor^8)) -> 0 | L11: =K11*(1-MAX(Churn_Floor, Base_Logo_Churn*Decay_Factor^9)) -> 0 | M11: =L11*(1-MAX(Churn_Floor, Base_Logo_Churn*Decay_Factor^10)) -> 0 | N11: =M11*(1-MAX(Churn_Floor, Base_Logo_Churn*Decay_Factor^11)) -> 0 | O11: =N11*(1-MAX(Churn_Floor, Base_Logo_Churn*Decay_Factor^12)) -> 0 | P11: =O11*(1-MAX(Churn_Floor, Base_Logo_Churn*Decay_Factor^13)) -> 0 | Q11: =P11*(1-MAX(Churn_Floor, Base_Logo_Churn*Decay_Factor^14)) -> 0 | R11: =Q11*(1-MAX(Churn_Floor, Base_Logo_Churn*Decay_Factor^15)) -> 0 | S11: =R11*(1-MAX(Churn_Floor, Base_Logo_Churn*Decay_Factor^16)) -> 0 | T11: =S11*(1-MAX(Churn_Floor, Base_Logo_Churn*Decay_Factor^17)) -> 0 | U11: =T11*(1-MAX(Churn_Floor, Base_Logo_Churn*Decay_Factor^18)) -> 0 | V11: =U11*(1-MAX(Churn_Floor, Base_Logo_Churn*Decay_Factor^19)) -> 0 | W11: =V11*(1-MAX(Churn_Floor, Base_Logo_Churn*Decay_Factor^20)) -> 0 | X11: =W11*(1-MAX(Churn_Floor, Base_Logo_Churn*Decay_Factor^21)) -> 0 | Y11: =X11*(1-MAX(Churn_Floor, Base_Logo_Churn*Decay_Factor^22)) -> 0 | Z11: =Y11*(1-MAX(Churn_Floor, Base_Logo_Churn*Decay_Factor^23)) -> 0 | AA11: =Z11*(1-MAX(Churn_Floor, Base_Logo_Churn*Decay_Factor^24)) -> 0 | AB11: =AA11*(1-MAX(Churn_Floor, Base_Logo_Churn*Decay_Factor^25)) -> 0 | AC11: =AB11*(1-MAX(Churn_Floor, Base_Logo_Churn*Decay_Factor^26)) -> 0 | AD11: =AC11*(1-MAX(Churn_Floor, Base_Logo_Churn*Decay_Factor^27)) -> 0 | AE11: =AD11*(1-MAX(Churn_Floor, Base_Logo_Churn*Decay_Factor^28)) -> 0 | AF11: =AE11*(1-MAX(Churn_Floor, Base_Logo_Churn*Decay_Factor^29)) -> 0 | AG11: =AF11*(1-MAX(Churn_Floor, Base_Logo_Churn*Decay_Factor^30)) -> 0 | AH11: =AG11*(1-MAX(Churn_Floor, Base_Logo_Churn*Decay_Factor^31)) -> 0 | AI11: =AH11*(1-MAX(Churn_Floor, Base_Logo_Churn*Decay_Factor^32)) -> 0 | AJ11: =AI11*(1-MAX(Churn_Floor, Base_Logo_Churn*Decay_Factor^33)) -> 0 | AK11: =AJ11*(1-MAX(Churn_Floor, Base_Logo_Churn*Decay_Factor^34)) -> 0 | AL11: =AK11*(1-MAX(Churn_Floor, Base_Logo_Churn*Decay_Factor^35)) -> 0
A12: Cohort 07 | B12: 1 | C12: =B12*(1-MAX(Churn_Floor, Base_Logo_Churn*Decay_Factor^0)) -> 0 | D12: =C12*(1-MAX(Churn_Floor, Base_Logo_Churn*Decay_Factor^1)) -> 0 | E12: =D12*(1-MAX(Churn_Floor, Base_Logo_Churn*Decay_Factor^2)) -> 0 | F12: =E12*(1-MAX(Churn_Floor, Base_Logo_Churn*Decay_Factor^3)) -> 0 | G12: =F12*(1-MAX(Churn_Floor, Base_Logo_Churn*Decay_Factor^4)) -> 0 | H12: =G12*(1-MAX(Churn_Floor, Base_Logo_Churn*Decay_Factor^5)) -> 0 | I12: =H12*(1-MAX(Churn_Floor, Base_Logo_Churn*Decay_Factor^6)) -> 0 | J12: =I12*(1-MAX(Churn_Floor, Base_Logo_Churn*Decay_Factor^7)) -> 0 | K12: =J12*(1-MAX(Churn_Floor, Base_Logo_Churn*Decay_Factor^8)) -> 0 | L12: =K12*(1-MAX(Churn_Floor, Base_Logo_Churn*Decay_Factor^9)) -> 0 | M12: =L12*(1-MAX(Churn_Floor, Base_Logo_Churn*Decay_Factor^10)) -> 0 | N12: =M12*(1-MAX(Churn_Floor, Base_Logo_Churn*Decay_Factor^11)) -> 0 | O12: =N12*(1-MAX(Churn_Floor, Base_Logo_Churn*Decay_Factor^12)) -> 0 | P12: =O12*(1-MAX(Churn_Floor, Base_Logo_Churn*Decay_Factor^13)) -> 0 | Q12: =P12*(1-MAX(Churn_Floor, Base_Logo_Churn*Decay_Factor^14)) -> 0 | R12: =Q12*(1-MAX(Churn_Floor, Base_Logo_Churn*Decay_Factor^15)) -> 0 | S12: =R12*(1-MAX(Churn_Floor, Base_Logo_Churn*Decay_Factor^16)) -> 0 | T12: =S12*(1-MAX(Churn_Floor, Base_Logo_Churn*Decay_Factor^17)) -> 0 | U12: =T12*(1-MAX(Churn_Floor, Base_Logo_Churn*Decay_Factor^18)) -> 0 | V12: =U12*(1-MAX(Churn_Floor, Base_Logo_Churn*Decay_Factor^19)) -> 0 | W12: =V12*(1-MAX(Churn_Floor, Base_Logo_Churn*Decay_Factor^20)) -> 0 | X12: =W12*(1-MAX(Churn_Floor, Base_Logo_Churn*Decay_Factor^21)) -> 0 | Y12: =X12*(1-MAX(Churn_Floor, Base_Logo_Churn*Decay_Factor^22)) -> 0 | Z12: =Y12*(1-MAX(Churn_Floor, Base_Logo_Churn*Decay_Factor^23)) -> 0 | AA12: =Z12*(1-MAX(Churn_Floor, Base_Logo_Churn*Decay_Factor^24)) -> 0 | AB12: =AA12*(1-MAX(Churn_Floor, Base_Logo_Churn*Decay_Factor^25)) -> 0 | AC12: =AB12*(1-MAX(Churn_Floor, Base_Logo_Churn*Decay_Factor^26)) -> 0 | AD12: =AC12*(1-MAX(Churn_Floor, Base_Logo_Churn*Decay_Factor^27)) -> 0 | AE12: =AD12*(1-MAX(Churn_Floor, Base_Logo_Churn*Decay_Factor^28)) -> 0 | AF12: =AE12*(1-MAX(Churn_Floor, Base_Logo_Churn*Decay_Factor^29)) -> 0 | AG12: =AF12*(1-MAX(Churn_Floor, Base_Logo_Churn*Decay_Factor^30)) -> 0 | AH12: =AG12*(1-MAX(Churn_Floor, Base_Logo_Churn*Decay_Factor^31)) -> 0 | AI12: =AH12*(1-MAX(Churn_Floor, Base_Logo_Churn*Decay_Factor^32)) -> 0 | AJ12: =AI12*(1-MAX(Churn_Floor, Base_Logo_Churn*Decay_Factor^33)) -> 0 | AK12: =AJ12*(1-MAX(Churn_Floor, Base_Logo_Churn*Decay_Factor^34)) -> 0 | AL12: =AK12*(1-MAX(Churn_Floor, Base_Logo_Churn*Decay_Factor^35)) -> 0
A13: Cohort 08 | B13: 1 | C13: =B13*(1-MAX(Churn_Floor, Base_Logo_Churn*Decay_Factor^0)) -> 0 | D13: =C13*(1-MAX(Churn_Floor, Base_Logo_Churn*Decay_Factor^1)) -> 0 | E13: =D13*(1-MAX(Churn_Floor, Base_Logo_Churn*Decay_Factor^2)) -> 0 | F13: =E13*(1-MAX(Churn_Floor, Base_Logo_Churn*Decay_Factor^3)) -> 0 | G13: =F13*(1-MAX(Churn_Floor, Base_Logo_Churn*Decay_Factor^4)) -> 0 | H13: =G13*(1-MAX(Churn_Floor, Base_Logo_Churn*Decay_Factor^5)) -> 0 | I13: =H13*(1-MAX(Churn_Floor, Base_Logo_Churn*Decay_Factor^6)) -> 0 | J13: =I13*(1-MAX(Churn_Floor, Base_Logo_Churn*Decay_Factor^7)) -> 0 | K13: =J13*(1-MAX(Churn_Floor, Base_Logo_Churn*Decay_Factor^8)) -> 0 | L13: =K13*(1-MAX(Churn_Floor, Base_Logo_Churn*Decay_Factor^9)) -> 0 | M13: =L13*(1-MAX(Churn_Floor, Base_Logo_Churn*Decay_Factor^10)) -> 0 | N13: =M13*(1-MAX(Churn_Floor, Base_Logo_Churn*Decay_Factor^11)) -> 0 | O13: =N13*(1-MAX(Churn_Floor, Base_Logo_Churn*Decay_Factor^12)) -> 0 | P13: =O13*(1-MAX(Churn_Floor, Base_Logo_Churn*Decay_Factor^13)) -> 0 | Q13: =P13*(1-MAX(Churn_Floor, Base_Logo_Churn*Decay_Factor^14)) -> 0 | R13: =Q13*(1-MAX(Churn_Floor, Base_Logo_Churn*Decay_Factor^15)) -> 0 | S13: =R13*(1-MAX(Churn_Floor, Base_Logo_Churn*Decay_Factor^16)) -> 0 | T13: =S13*(1-MAX(Churn_Floor, Base_Logo_Churn*Decay_Factor^17)) -> 0 | U13: =T13*(1-MAX(Churn_Floor, Base_Logo_Churn*Decay_Factor^18)) -> 0 | V13: =U13*(1-MAX(Churn_Floor, Base_Logo_Churn*Decay_Factor^19)) -> 0 | W13: =V13*(1-MAX(Churn_Floor, Base_Logo_Churn*Decay_Factor^20)) -> 0 | X13: =W13*(1-MAX(Churn_Floor, Base_Logo_Churn*Decay_Factor^21)) -> 0 | Y13: =X13*(1-MAX(Churn_Floor, Base_Logo_Churn*Decay_Factor^22)) -> 0 | Z13: =Y13*(1-MAX(Churn_Floor, Base_Logo_Churn*Decay_Factor^23)) -> 0 | AA13: =Z13*(1-MAX(Churn_Floor, Base_Logo_Churn*Decay_Factor^24)) -> 0 | AB13: =AA13*(1-MAX(Churn_Floor, Base_Logo_Churn*Decay_Factor^25)) -> 0 | AC13: =AB13*(1-MAX(Churn_Floor, Base_Logo_Churn*Decay_Factor^26)) -> 0 | AD13: =AC13*(1-MAX(Churn_Floor, Base_Logo_Churn*Decay_Factor^27)) -> 0 | AE13: =AD13*(1-MAX(Churn_Floor, Base_Logo_Churn*Decay_Factor^28)) -> 0 | AF13: =AE13*(1-MAX(Churn_Floor, Base_Logo_Churn*Decay_Factor^29)) -> 0 | AG13: =AF13*(1-MAX(Churn_Floor, Base_Logo_Churn*Decay_Factor^30)) -> 0 | AH13: =AG13*(1-MAX(Churn_Floor, Base_Logo_Churn*Decay_Factor^31)) -> 0 | AI13: =AH13*(1-MAX(Churn_Floor, Base_Logo_Churn*Decay_Factor^32)) -> 0 | AJ13: =AI13*(1-MAX(Churn_Floor, Base_Logo_Churn*Decay_Factor^33)) -> 0 | AK13: =AJ13*(1-MAX(Churn_Floor, Base_Logo_Churn*Decay_Factor^34)) -> 0 | AL13: =AK13*(1-MAX(Churn_Floor, Base_Logo_Churn*Decay_Factor^35)) -> 0
A14: Cohort 09 | B14: 1 | C14: =B14*(1-MAX(Churn_Floor, Base_Logo_Churn*Decay_Factor^0)) -> 0 | D14: =C14*(1-MAX(Churn_Floor, Base_Logo_Churn*Decay_Factor^1)) -> 0 | E14: =D14*(1-MAX(Churn_Floor, Base_Logo_Churn*Decay_Factor^2)) -> 0 | F14: =E14*(1-MAX(Churn_Floor, Base_Logo_Churn*Decay_Factor^3)) -> 0 | G14: =F14*(1-MAX(Churn_Floor, Base_Logo_Churn*Decay_Factor^4)) -> 0 | H14: =G14*(1-MAX(Churn_Floor, Base_Logo_Churn*Decay_Factor^5)) -> 0 | I14: =H14*(1-MAX(Churn_Floor, Base_Logo_Churn*Decay_Factor^6)) -> 0 | J14: =I14*(1-MAX(Churn_Floor, Base_Logo_Churn*Decay_Factor^7)) -> 0 | K14: =J14*(1-MAX(Churn_Floor, Base_Logo_Churn*Decay_Factor^8)) -> 0 | L14: =K14*(1-MAX(Churn_Floor, Base_Logo_Churn*Decay_Factor^9)) -> 0 | M14: =L14*(1-MAX(Churn_Floor, Base_Logo_Churn*Decay_Factor^10)) -> 0 | N14: =M14*(1-MAX(Churn_Floor, Base_Logo_Churn*Decay_Factor^11)) -> 0 | O14: =N14*(1-MAX(Churn_Floor, Base_Logo_Churn*Decay_Factor^12)) -> 0 | P14: =O14*(1-MAX(Churn_Floor, Base_Logo_Churn*Decay_Factor^13)) -> 0 | Q14: =P14*(1-MAX(Churn_Floor, Base_Logo_Churn*Decay_Factor^14)) -> 0 | R14: =Q14*(1-MAX(Churn_Floor, Base_Logo_Churn*Decay_Factor^15)) -> 0 | S14: =R14*(1-MAX(Churn_Floor, Base_Logo_Churn*Decay_Factor^16)) -> 0 | T14: =S14*(1-MAX(Churn_Floor, Base_Logo_Churn*Decay_Factor^17)) -> 0 | U14: =T14*(1-MAX(Churn_Floor, Base_Logo_Churn*Decay_Factor^18)) -> 0 | V14: =U14*(1-MAX(Churn_Floor, Base_Logo_Churn*Decay_Factor^19)) -> 0 | W14: =V14*(1-MAX(Churn_Floor, Base_Logo_Churn*Decay_Factor^20)) -> 0 | X14: =W14*(1-MAX(Churn_Floor, Base_Logo_Churn*Decay_Factor^21)) -> 0 | Y14: =X14*(1-MAX(Churn_Floor, Base_Logo_Churn*Decay_Factor^22)) -> 0 | Z14: =Y14*(1-MAX(Churn_Floor, Base_Logo_Churn*Decay_Factor^23)) -> 0 | AA14: =Z14*(1-MAX(Churn_Floor, Base_Logo_Churn*Decay_Factor^24)) -> 0 | AB14: =AA14*(1-MAX(Churn_Floor, Base_Logo_Churn*Decay_Factor^25)) -> 0 | AC14: =AB14*(1-MAX(Churn_Floor, Base_Logo_Churn*Decay_Factor^26)) -> 0 | AD14: =AC14*(1-MAX(Churn_Floor, Base_Logo_Churn*Decay_Factor^27)) -> 0 | AE14: =AD14*(1-MAX(Churn_Floor, Base_Logo_Churn*Decay_Factor^28)) -> 0 | AF14: =AE14*(1-MAX(Churn_Floor, Base_Logo_Churn*Decay_Factor^29)) -> 0 | AG14: =AF14*(1-MAX(Churn_Floor, Base_Logo_Churn*Decay_Factor^30)) -> 0 | AH14: =AG14*(1-MAX(Churn_Floor, Base_Logo_Churn*Decay_Factor^31)) -> 0 | AI14: =AH14*(1-MAX(Churn_Floor, Base_Logo_Churn*Decay_Factor^32)) -> 0 | AJ14: =AI14*(1-MAX(Churn_Floor, Base_Logo_Churn*Decay_Factor^33)) -> 0 | AK14: =AJ14*(1-MAX(Churn_Floor, Base_Logo_Churn*Decay_Factor^34)) -> 0 | AL14: =AK14*(1-MAX(Churn_Floor, Base_Logo_Churn*Decay_Factor^35)) -> 0
A15: Cohort 10 | B15: 1 | C15: =B15*(1-MAX(Churn_Floor, Base_Logo_Churn*Decay_Factor^0)) -> 0 | D15: =C15*(1-MAX(Churn_Floor, Base_Logo_Churn*Decay_Factor^1)) -> 0 | E15: =D15*(1-MAX(Churn_Floor, Base_Logo_Churn*Decay_Factor^2)) -> 0 | F15: =E15*(1-MAX(Churn_Floor, Base_Logo_Churn*Decay_Factor^3)) -> 0 | G15: =F15*(1-MAX(Churn_Floor, Base_Logo_Churn*Decay_Factor^4)) -> 0 | H15: =G15*(1-MAX(Churn_Floor, Base_Logo_Churn*Decay_Factor^5)) -> 0 | I15: =H15*(1-MAX(Churn_Floor, Base_Logo_Churn*Decay_Factor^6)) -> 0 | J15: =I15*(1-MAX(Churn_Floor, Base_Logo_Churn*Decay_Factor^7)) -> 0 | K15: =J15*(1-MAX(Churn_Floor, Base_Logo_Churn*Decay_Factor^8)) -> 0 | L15: =K15*(1-MAX(Churn_Floor, Base_Logo_Churn*Decay_Factor^9)) -> 0 | M15: =L15*(1-MAX(Churn_Floor, Base_Logo_Churn*Decay_Factor^10)) -> 0 | N15: =M15*(1-MAX(Churn_Floor, Base_Logo_Churn*Decay_Factor^11)) -> 0 | O15: =N15*(1-MAX(Churn_Floor, Base_Logo_Churn*Decay_Factor^12)) -> 0 | P15: =O15*(1-MAX(Churn_Floor, Base_Logo_Churn*Decay_Factor^13)) -> 0 | Q15: =P15*(1-MAX(Churn_Floor, Base_Logo_Churn*Decay_Factor^14)) -> 0 | R15: =Q15*(1-MAX(Churn_Floor, Base_Logo_Churn*Decay_Factor^15)) -> 0 | S15: =R15*(1-MAX(Churn_Floor, Base_Logo_Churn*Decay_Factor^16)) -> 0 | T15: =S15*(1-MAX(Churn_Floor, Base_Logo_Churn*Decay_Factor^17)) -> 0 | U15: =T15*(1-MAX(Churn_Floor, Base_Logo_Churn*Decay_Factor^18)) -> 0 | V15: =U15*(1-MAX(Churn_Floor, Base_Logo_Churn*Decay_Factor^19)) -> 0 | W15: =V15*(1-MAX(Churn_Floor, Base_Logo_Churn*Decay_Factor^20)) -> 0 | X15: =W15*(1-MAX(Churn_Floor, Base_Logo_Churn*Decay_Factor^21)) -> 0 | Y15: =X15*(1-MAX(Churn_Floor, Base_Logo_Churn*Decay_Factor^22)) -> 0 | Z15: =Y15*(1-MAX(Churn_Floor, Base_Logo_Churn*Decay_Factor^23)) -> 0 | AA15: =Z15*(1-MAX(Churn_Floor, Base_Logo_Churn*Decay_Factor^24)) -> 0 | AB15: =AA15*(1-MAX(Churn_Floor, Base_Logo_Churn*Decay_Factor^25)) -> 0 | AC15: =AB15*(1-MAX(Churn_Floor, Base_Logo_Churn*Decay_Factor^26)) -> 0 | AD15: =AC15*(1-MAX(Churn_Floor, Base_Logo_Churn*Decay_Factor^27)) -> 0 | AE15: =AD15*(1-MAX(Churn_Floor, Base_Logo_Churn*Decay_Factor^28)) -> 0 | AF15: =AE15*(1-MAX(Churn_Floor, Base_Logo_Churn*Decay_Factor^29)) -> 0 | AG15: =AF15*(1-MAX(Churn_Floor, Base_Logo_Churn*Decay_Factor^30)) -> 0 | AH15: =AG15*(1-MAX(Churn_Floor, Base_Logo_Churn*Decay_Factor^31)) -> 0 | AI15: =AH15*(1-MAX(Churn_Floor, Base_Logo_Churn*Decay_Factor^32)) -> 0 | AJ15: =AI15*(1-MAX(Churn_Floor, Base_Logo_Churn*Decay_Factor^33)) -> 0 | AK15: =AJ15*(1-MAX(Churn_Floor, Base_Logo_Churn*Decay_Factor^34)) -> 0 | AL15: =AK15*(1-MAX(Churn_Floor, Base_Logo_Churn*Decay_Factor^35)) -> 0
A16: Cohort 11 | B16: 1 | C16: =B16*(1-MAX(Churn_Floor, Base_Logo_Churn*Decay_Factor^0)) -> 0 | D16: =C16*(1-MAX(Churn_Floor, Base_Logo_Churn*Decay_Factor^1)) -> 0 | E16: =D16*(1-MAX(Churn_Floor, Base_Logo_Churn*Decay_Factor^2)) -> 0 | F16: =E16*(1-MAX(Churn_Floor, Base_Logo_Churn*Decay_Factor^3)) -> 0 | G16: =F16*(1-MAX(Churn_Floor, Base_Logo_Churn*Decay_Factor^4)) -> 0 | H16: =G16*(1-MAX(Churn_Floor, Base_Logo_Churn*Decay_Factor^5)) -> 0 | I16: =H16*(1-MAX(Churn_Floor, Base_Logo_Churn*Decay_Factor^6)) -> 0 | J16: =I16*(1-MAX(Churn_Floor, Base_Logo_Churn*Decay_Factor^7)) -> 0 | K16: =J16*(1-MAX(Churn_Floor, Base_Logo_Churn*Decay_Factor^8)) -> 0 | L16: =K16*(1-MAX(Churn_Floor, Base_Logo_Churn*Decay_Factor^9)) -> 0 | M16: =L16*(1-MAX(Churn_Floor, Base_Logo_Churn*Decay_Factor^10)) -> 0 | N16: =M16*(1-MAX(Churn_Floor, Base_Logo_Churn*Decay_Factor^11)) -> 0 | O16: =N16*(1-MAX(Churn_Floor, Base_Logo_Churn*Decay_Factor^12)) -> 0 | P16: =O16*(1-MAX(Churn_Floor, Base_Logo_Churn*Decay_Factor^13)) -> 0 | Q16: =P16*(1-MAX(Churn_Floor, Base_Logo_Churn*Decay_Factor^14)) -> 0 | R16: =Q16*(1-MAX(Churn_Floor, Base_Logo_Churn*Decay_Factor^15)) -> 0 | S16: =R16*(1-MAX(Churn_Floor, Base_Logo_Churn*Decay_Factor^16)) -> 0 | T16: =S16*(1-MAX(Churn_Floor, Base_Logo_Churn*Decay_Factor^17)) -> 0 | U16: =T16*(1-MAX(Churn_Floor, Base_Logo_Churn*Decay_Factor^18)) -> 0 | V16: =U16*(1-MAX(Churn_Floor, Base_Logo_Churn*Decay_Factor^19)) -> 0 | W16: =V16*(1-MAX(Churn_Floor, Base_Logo_Churn*Decay_Factor^20)) -> 0 | X16: =W16*(1-MAX(Churn_Floor, Base_Logo_Churn*Decay_Factor^21)) -> 0 | Y16: =X16*(1-MAX(Churn_Floor, Base_Logo_Churn*Decay_Factor^22)) -> 0 | Z16: =Y16*(1-MAX(Churn_Floor, Base_Logo_Churn*Decay_Factor^23)) -> 0 | AA16: =Z16*(1-MAX(Churn_Floor, Base_Logo_Churn*Decay_Factor^24)) -> 0 | AB16: =AA16*(1-MAX(Churn_Floor, Base_Logo_Churn*Decay_Factor^25)) -> 0 | AC16: =AB16*(1-MAX(Churn_Floor, Base_Logo_Churn*Decay_Factor^26)) -> 0 | AD16: =AC16*(1-MAX(Churn_Floor, Base_Logo_Churn*Decay_Factor^27)) -> 0 | AE16: =AD16*(1-MAX(Churn_Floor, Base_Logo_Churn*Decay_Factor^28)) -> 0 | AF16: =AE16*(1-MAX(Churn_Floor, Base_Logo_Churn*Decay_Factor^29)) -> 0 | AG16: =AF16*(1-MAX(Churn_Floor, Base_Logo_Churn*Decay_Factor^30)) -> 0 | AH16: =AG16*(1-MAX(Churn_Floor, Base_Logo_Churn*Decay_Factor^31)) -> 0 | AI16: =AH16*(1-MAX(Churn_Floor, Base_Logo_Churn*Decay_Factor^32)) -> 0 | AJ16: =AI16*(1-MAX(Churn_Floor, Base_Logo_Churn*Decay_Factor^33)) -> 0 | AK16: =AJ16*(1-MAX(Churn_Floor, Base_Logo_Churn*Decay_Factor^34)) -> 0 | AL16: =AK16*(1-MAX(Churn_Floor, Base_Logo_Churn*Decay_Factor^35)) -> 0
A17: Cohort 12 | B17: 1 | C17: =B17*(1-MAX(Churn_Floor, Base_Logo_Churn*Decay_Factor^0)) -> 0 | D17: =C17*(1-MAX(Churn_Floor, Base_Logo_Churn*Decay_Factor^1)) -> 0 | E17: =D17*(1-MAX(Churn_Floor, Base_Logo_Churn*Decay_Factor^2)) -> 0 | F17: =E17*(1-MAX(Churn_Floor, Base_Logo_Churn*Decay_Factor^3)) -> 0 | G17: =F17*(1-MAX(Churn_Floor, Base_Logo_Churn*Decay_Factor^4)) -> 0 | H17: =G17*(1-MAX(Churn_Floor, Base_Logo_Churn*Decay_Factor^5)) -> 0 | I17: =H17*(1-MAX(Churn_Floor, Base_Logo_Churn*Decay_Factor^6)) -> 0 | J17: =I17*(1-MAX(Churn_Floor, Base_Logo_Churn*Decay_Factor^7)) -> 0 | K17: =J17*(1-MAX(Churn_Floor, Base_Logo_Churn*Decay_Factor^8)) -> 0 | L17: =K17*(1-MAX(Churn_Floor, Base_Logo_Churn*Decay_Factor^9)) -> 0 | M17: =L17*(1-MAX(Churn_Floor, Base_Logo_Churn*Decay_Factor^10)) -> 0 | N17: =M17*(1-MAX(Churn_Floor, Base_Logo_Churn*Decay_Factor^11)) -> 0 | O17: =N17*(1-MAX(Churn_Floor, Base_Logo_Churn*Decay_Factor^12)) -> 0 | P17: =O17*(1-MAX(Churn_Floor, Base_Logo_Churn*Decay_Factor^13)) -> 0 | Q17: =P17*(1-MAX(Churn_Floor, Base_Logo_Churn*Decay_Factor^14)) -> 0 | R17: =Q17*(1-MAX(Churn_Floor, Base_Logo_Churn*Decay_Factor^15)) -> 0 | S17: =R17*(1-MAX(Churn_Floor, Base_Logo_Churn*Decay_Factor^16)) -> 0 | T17: =S17*(1-MAX(Churn_Floor, Base_Logo_Churn*Decay_Factor^17)) -> 0 | U17: =T17*(1-MAX(Churn_Floor, Base_Logo_Churn*Decay_Factor^18)) -> 0 | V17: =U17*(1-MAX(Churn_Floor, Base_Logo_Churn*Decay_Factor^19)) -> 0 | W17: =V17*(1-MAX(Churn_Floor, Base_Logo_Churn*Decay_Factor^20)) -> 0 | X17: =W17*(1-MAX(Churn_Floor, Base_Logo_Churn*Decay_Factor^21)) -> 0 | Y17: =X17*(1-MAX(Churn_Floor, Base_Logo_Churn*Decay_Factor^22)) -> 0 | Z17: =Y17*(1-MAX(Churn_Floor, Base_Logo_Churn*Decay_Factor^23)) -> 0 | AA17: =Z17*(1-MAX(Churn_Floor, Base_Logo_Churn*Decay_Factor^24)) -> 0 | AB17: =AA17*(1-MAX(Churn_Floor, Base_Logo_Churn*Decay_Factor^25)) -> 0 | AC17: =AB17*(1-MAX(Churn_Floor, Base_Logo_Churn*Decay_Factor^26)) -> 0 | AD17: =AC17*(1-MAX(Churn_Floor, Base_Logo_Churn*Decay_Factor^27)) -> 0 | AE17: =AD17*(1-MAX(Churn_Floor, Base_Logo_Churn*Decay_Factor^28)) -> 0 | AF17: =AE17*(1-MAX(Churn_Floor, Base_Logo_Churn*Decay_Factor^29)) -> 0 | AG17: =AF17*(1-MAX(Churn_Floor, Base_Logo_Churn*Decay_Factor^30)) -> 0 | AH17: =AG17*(1-MAX(Churn_Floor, Base_Logo_Churn*Decay_Factor^31)) -> 0 | AI17: =AH17*(1-MAX(Churn_Floor, Base_Logo_Churn*Decay_Factor^32)) -> 0 | AJ17: =AI17*(1-MAX(Churn_Floor, Base_Logo_Churn*Decay_Factor^33)) -> 0 | AK17: =AJ17*(1-MAX(Churn_Floor, Base_Logo_Churn*Decay_Factor^34)) -> 0 | AL17: =AK17*(1-MAX(Churn_Floor, Base_Logo_Churn*Decay_Factor^35)) -> 0

Sheet Revenue-Cohort
A1: Revenue Cohort Retention (NRR per cohort)
A3: Rev(t) = Rev(t-1) × Logo_Retention_growth × (1 + Expansion - Contraction). Includes expansion compounding.
A5: Cohort | B5: M0 | C5: M1 | D5: M2 | E5: M3 | F5: M4 | G5: M5 | H5: M6 | I5: M7 | J5: M8 | K5: M9 | L5: M10 | M5: M11 | N5: M12 | O5: M13 | P5: M14 | Q5: M15 | R5: M16 | S5: M17 | T5: M18 | U5: M19 | V5: M20 | W5: M21 | X5: M22 | Y5: M23 | Z5: M24 | AA5: M25 | AB5: M26 | AC5: M27 | AD5: M28 | AE5: M29 | AF5: M30 | AG5: M31 | AH5: M32 | AI5: M33 | AJ5: M34 | AK5: M35 | AL5: M36
A6: Cohort 01 | B6: 1 | C6: ='Logo-Cohort'!C6*(1+Expansion_C-Contraction_C)^1 -> 0 | D6: ='Logo-Cohort'!D6*(1+Expansion_C-Contraction_C)^2 -> 0 | E6: ='Logo-Cohort'!E6*(1+Expansion_C-Contraction_C)^3 -> 0 | F6: ='Logo-Cohort'!F6*(1+Expansion_C-Contraction_C)^4 -> 0 | G6: ='Logo-Cohort'!G6*(1+Expansion_C-Contraction_C)^5 -> 0 | H6: ='Logo-Cohort'!H6*(1+Expansion_C-Contraction_C)^6 -> 0 | I6: ='Logo-Cohort'!I6*(1+Expansion_C-Contraction_C)^7 -> 0 | J6: ='Logo-Cohort'!J6*(1+Expansion_C-Contraction_C)^8 -> 0 | K6: ='Logo-Cohort'!K6*(1+Expansion_C-Contraction_C)^9 -> 0 | L6: ='Logo-Cohort'!L6*(1+Expansion_C-Contraction_C)^10 -> 0 | M6: ='Logo-Cohort'!M6*(1+Expansion_C-Contraction_C)^11 -> 0 | N6: ='Logo-Cohort'!N6*(1+Expansion_C-Contraction_C)^12 -> 0 | O6: ='Logo-Cohort'!O6*(1+Expansion_C-Contraction_C)^13 -> 0 | P6: ='Logo-Cohort'!P6*(1+Expansion_C-Contraction_C)^14 -> 0 | Q6: ='Logo-Cohort'!Q6*(1+Expansion_C-Contraction_C)^15 -> 0 | R6: ='Logo-Cohort'!R6*(1+Expansion_C-Contraction_C)^16 -> 0 | S6: ='Logo-Cohort'!S6*(1+Expansion_C-Contraction_C)^17 -> 0 | T6: ='Logo-Cohort'!T6*(1+Expansion_C-Contraction_C)^18 -> 0 | U6: ='Logo-Cohort'!U6*(1+Expansion_C-Contraction_C)^19 -> 0 | V6: ='Logo-Cohort'!V6*(1+Expansion_C-Contraction_C)^20 -> 0 | W6: ='Logo-Cohort'!W6*(1+Expansion_C-Contraction_C)^21 -> 0 | X6: ='Logo-Cohort'!X6*(1+Expansion_C-Contraction_C)^22 -> 0 | Y6: ='Logo-Cohort'!Y6*(1+Expansion_C-Contraction_C)^23 -> 0 | Z6: ='Logo-Cohort'!Z6*(1+Expansion_C-Contraction_C)^24 -> 0 | AA6: ='Logo-Cohort'!AA6*(1+Expansion_C-Contraction_C)^25 -> 0 | AB6: ='Logo-Cohort'!AB6*(1+Expansion_C-Contraction_C)^26 -> 0 | AC6: ='Logo-Cohort'!AC6*(1+Expansion_C-Contraction_C)^27 -> 0 | AD6: ='Logo-Cohort'!AD6*(1+Expansion_C-Contraction_C)^28 -> 0 | AE6: ='Logo-Cohort'!AE6*(1+Expansion_C-Contraction_C)^29 -> 0 | AF6: ='Logo-Cohort'!AF6*(1+Expansion_C-Contraction_C)^30 -> 0 | AG6: ='Logo-Cohort'!AG6*(1+Expansion_C-Contraction_C)^31 -> 0 | AH6: ='Logo-Cohort'!AH6*(1+Expansion_C-Contraction_C)^32 -> 0 | AI6: ='Logo-Cohort'!AI6*(1+Expansion_C-Contraction_C)^33 -> 0 | AJ6: ='Logo-Cohort'!AJ6*(1+Expansion_C-Contraction_C)^34 -> 0 | AK6: ='Logo-Cohort'!AK6*(1+Expansion_C-Contraction_C)^35 -> 0 | AL6: ='Logo-Cohort'!AL6*(1+Expansion_C-Contraction_C)^36 -> 0
A7: Cohort 02 | B7: 1 | C7: ='Logo-Cohort'!C7*(1+Expansion_C-Contraction_C)^1 -> 0 | D7: ='Logo-Cohort'!D7*(1+Expansion_C-Contraction_C)^2 -> 0 | E7: ='Logo-Cohort'!E7*(1+Expansion_C-Contraction_C)^3 -> 0 | F7: ='Logo-Cohort'!F7*(1+Expansion_C-Contraction_C)^4 -> 0 | G7: ='Logo-Cohort'!G7*(1+Expansion_C-Contraction_C)^5 -> 0 | H7: ='Logo-Cohort'!H7*(1+Expansion_C-Contraction_C)^6 -> 0 | I7: ='Logo-Cohort'!I7*(1+Expansion_C-Contraction_C)^7 -> 0 | J7: ='Logo-Cohort'!J7*(1+Expansion_C-Contraction_C)^8 -> 0 | K7: ='Logo-Cohort'!K7*(1+Expansion_C-Contraction_C)^9 -> 0 | L7: ='Logo-Cohort'!L7*(1+Expansion_C-Contraction_C)^10 -> 0 | M7: ='Logo-Cohort'!M7*(1+Expansion_C-Contraction_C)^11 -> 0 | N7: ='Logo-Cohort'!N7*(1+Expansion_C-Contraction_C)^12 -> 0 | O7: ='Logo-Cohort'!O7*(1+Expansion_C-Contraction_C)^13 -> 0 | P7: ='Logo-Cohort'!P7*(1+Expansion_C-Contraction_C)^14 -> 0 | Q7: ='Logo-Cohort'!Q7*(1+Expansion_C-Contraction_C)^15 -> 0 | R7: ='Logo-Cohort'!R7*(1+Expansion_C-Contraction_C)^16 -> 0 | S7: ='Logo-Cohort'!S7*(1+Expansion_C-Contraction_C)^17 -> 0 | T7: ='Logo-Cohort'!T7*(1+Expansion_C-Contraction_C)^18 -> 0 | U7: ='Logo-Cohort'!U7*(1+Expansion_C-Contraction_C)^19 -> 0 | V7: ='Logo-Cohort'!V7*(1+Expansion_C-Contraction_C)^20 -> 0 | W7: ='Logo-Cohort'!W7*(1+Expansion_C-Contraction_C)^21 -> 0 | X7: ='Logo-Cohort'!X7*(1+Expansion_C-Contraction_C)^22 -> 0 | Y7: ='Logo-Cohort'!Y7*(1+Expansion_C-Contraction_C)^23 -> 0 | Z7: ='Logo-Cohort'!Z7*(1+Expansion_C-Contraction_C)^24 -> 0 | AA7: ='Logo-Cohort'!AA7*(1+Expansion_C-Contraction_C)^25 -> 0 | AB7: ='Logo-Cohort'!AB7*(1+Expansion_C-Contraction_C)^26 -> 0 | AC7: ='Logo-Cohort'!AC7*(1+Expansion_C-Contraction_C)^27 -> 0 | AD7: ='Logo-Cohort'!AD7*(1+Expansion_C-Contraction_C)^28 -> 0 | AE7: ='Logo-Cohort'!AE7*(1+Expansion_C-Contraction_C)^29 -> 0 | AF7: ='Logo-Cohort'!AF7*(1+Expansion_C-Contraction_C)^30 -> 0 | AG7: ='Logo-Cohort'!AG7*(1+Expansion_C-Contraction_C)^31 -> 0 | AH7: ='Logo-Cohort'!AH7*(1+Expansion_C-Contraction_C)^32 -> 0 | AI7: ='Logo-Cohort'!AI7*(1+Expansion_C-Contraction_C)^33 -> 0 | AJ7: ='Logo-Cohort'!AJ7*(1+Expansion_C-Contraction_C)^34 -> 0 | AK7: ='Logo-Cohort'!AK7*(1+Expansion_C-Contraction_C)^35 -> 0 | AL7: ='Logo-Cohort'!AL7*(1+Expansion_C-Contraction_C)^36 -> 0
A8: Cohort 03 | B8: 1 | C8: ='Logo-Cohort'!C8*(1+Expansion_C-Contraction_C)^1 -> 0 | D8: ='Logo-Cohort'!D8*(1+Expansion_C-Contraction_C)^2 -> 0 | E8: ='Logo-Cohort'!E8*(1+Expansion_C-Contraction_C)^3 -> 0 | F8: ='Logo-Cohort'!F8*(1+Expansion_C-Contraction_C)^4 -> 0 | G8: ='Logo-Cohort'!G8*(1+Expansion_C-Contraction_C)^5 -> 0 | H8: ='Logo-Cohort'!H8*(1+Expansion_C-Contraction_C)^6 -> 0 | I8: ='Logo-Cohort'!I8*(1+Expansion_C-Contraction_C)^7 -> 0 | J8: ='Logo-Cohort'!J8*(1+Expansion_C-Contraction_C)^8 -> 0 | K8: ='Logo-Cohort'!K8*(1+Expansion_C-Contraction_C)^9 -> 0 | L8: ='Logo-Cohort'!L8*(1+Expansion_C-Contraction_C)^10 -> 0 | M8: ='Logo-Cohort'!M8*(1+Expansion_C-Contraction_C)^11 -> 0 | N8: ='Logo-Cohort'!N8*(1+Expansion_C-Contraction_C)^12 -> 0 | O8: ='Logo-Cohort'!O8*(1+Expansion_C-Contraction_C)^13 -> 0 | P8: ='Logo-Cohort'!P8*(1+Expansion_C-Contraction_C)^14 -> 0 | Q8: ='Logo-Cohort'!Q8*(1+Expansion_C-Contraction_C)^15 -> 0 | R8: ='Logo-Cohort'!R8*(1+Expansion_C-Contraction_C)^16 -> 0 | S8: ='Logo-Cohort'!S8*(1+Expansion_C-Contraction_C)^17 -> 0 | T8: ='Logo-Cohort'!T8*(1+Expansion_C-Contraction_C)^18 -> 0 | U8: ='Logo-Cohort'!U8*(1+Expansion_C-Contraction_C)^19 -> 0 | V8: ='Logo-Cohort'!V8*(1+Expansion_C-Contraction_C)^20 -> 0 | W8: ='Logo-Cohort'!W8*(1+Expansion_C-Contraction_C)^21 -> 0 | X8: ='Logo-Cohort'!X8*(1+Expansion_C-Contraction_C)^22 -> 0 | Y8: ='Logo-Cohort'!Y8*(1+Expansion_C-Contraction_C)^23 -> 0 | Z8: ='Logo-Cohort'!Z8*(1+Expansion_C-Contraction_C)^24 -> 0 | AA8: ='Logo-Cohort'!AA8*(1+Expansion_C-Contraction_C)^25 -> 0 | AB8: ='Logo-Cohort'!AB8*(1+Expansion_C-Contraction_C)^26 -> 0 | AC8: ='Logo-Cohort'!AC8*(1+Expansion_C-Contraction_C)^27 -> 0 | AD8: ='Logo-Cohort'!AD8*(1+Expansion_C-Contraction_C)^28 -> 0 | AE8: ='Logo-Cohort'!AE8*(1+Expansion_C-Contraction_C)^29 -> 0 | AF8: ='Logo-Cohort'!AF8*(1+Expansion_C-Contraction_C)^30 -> 0 | AG8: ='Logo-Cohort'!AG8*(1+Expansion_C-Contraction_C)^31 -> 0 | AH8: ='Logo-Cohort'!AH8*(1+Expansion_C-Contraction_C)^32 -> 0 | AI8: ='Logo-Cohort'!AI8*(1+Expansion_C-Contraction_C)^33 -> 0 | AJ8: ='Logo-Cohort'!AJ8*(1+Expansion_C-Contraction_C)^34 -> 0 | AK8: ='Logo-Cohort'!AK8*(1+Expansion_C-Contraction_C)^35 -> 0 | AL8: ='Logo-Cohort'!AL8*(1+Expansion_C-Contraction_C)^36 -> 0
A9: Cohort 04 | B9: 1 | C9: ='Logo-Cohort'!C9*(1+Expansion_C-Contraction_C)^1 -> 0 | D9: ='Logo-Cohort'!D9*(1+Expansion_C-Contraction_C)^2 -> 0 | E9: ='Logo-Cohort'!E9*(1+Expansion_C-Contraction_C)^3 -> 0 | F9: ='Logo-Cohort'!F9*(1+Expansion_C-Contraction_C)^4 -> 0 | G9: ='Logo-Cohort'!G9*(1+Expansion_C-Contraction_C)^5 -> 0 | H9: ='Logo-Cohort'!H9*(1+Expansion_C-Contraction_C)^6 -> 0 | I9: ='Logo-Cohort'!I9*(1+Expansion_C-Contraction_C)^7 -> 0 | J9: ='Logo-Cohort'!J9*(1+Expansion_C-Contraction_C)^8 -> 0 | K9: ='Logo-Cohort'!K9*(1+Expansion_C-Contraction_C)^9 -> 0 | L9: ='Logo-Cohort'!L9*(1+Expansion_C-Contraction_C)^10 -> 0 | M9: ='Logo-Cohort'!M9*(1+Expansion_C-Contraction_C)^11 -> 0 | N9: ='Logo-Cohort'!N9*(1+Expansion_C-Contraction_C)^12 -> 0 | O9: ='Logo-Cohort'!O9*(1+Expansion_C-Contraction_C)^13 -> 0 | P9: ='Logo-Cohort'!P9*(1+Expansion_C-Contraction_C)^14 -> 0 | Q9: ='Logo-Cohort'!Q9*(1+Expansion_C-Contraction_C)^15 -> 0 | R9: ='Logo-Cohort'!R9*(1+Expansion_C-Contraction_C)^16 -> 0 | S9: ='Logo-Cohort'!S9*(1+Expansion_C-Contraction_C)^17 -> 0 | T9: ='Logo-Cohort'!T9*(1+Expansion_C-Contraction_C)^18 -> 0 | U9: ='Logo-Cohort'!U9*(1+Expansion_C-Contraction_C)^19 -> 0 | V9: ='Logo-Cohort'!V9*(1+Expansion_C-Contraction_C)^20 -> 0 | W9: ='Logo-Cohort'!W9*(1+Expansion_C-Contraction_C)^21 -> 0 | X9: ='Logo-Cohort'!X9*(1+Expansion_C-Contraction_C)^22 -> 0 | Y9: ='Logo-Cohort'!Y9*(1+Expansion_C-Contraction_C)^23 -> 0 | Z9: ='Logo-Cohort'!Z9*(1+Expansion_C-Contraction_C)^24 -> 0 | AA9: ='Logo-Cohort'!AA9*(1+Expansion_C-Contraction_C)^25 -> 0 | AB9: ='Logo-Cohort'!AB9*(1+Expansion_C-Contraction_C)^26 -> 0 | AC9: ='Logo-Cohort'!AC9*(1+Expansion_C-Contraction_C)^27 -> 0 | AD9: ='Logo-Cohort'!AD9*(1+Expansion_C-Contraction_C)^28 -> 0 | AE9: ='Logo-Cohort'!AE9*(1+Expansion_C-Contraction_C)^29 -> 0 | AF9: ='Logo-Cohort'!AF9*(1+Expansion_C-Contraction_C)^30 -> 0 | AG9: ='Logo-Cohort'!AG9*(1+Expansion_C-Contraction_C)^31 -> 0 | AH9: ='Logo-Cohort'!AH9*(1+Expansion_C-Contraction_C)^32 -> 0 | AI9: ='Logo-Cohort'!AI9*(1+Expansion_C-Contraction_C)^33 -> 0 | AJ9: ='Logo-Cohort'!AJ9*(1+Expansion_C-Contraction_C)^34 -> 0 | AK9: ='Logo-Cohort'!AK9*(1+Expansion_C-Contraction_C)^35 -> 0 | AL9: ='Logo-Cohort'!AL9*(1+Expansion_C-Contraction_C)^36 -> 0
A10: Cohort 05 | B10: 1 | C10: ='Logo-Cohort'!C10*(1+Expansion_C-Contraction_C)^1 -> 0 | D10: ='Logo-Cohort'!D10*(1+Expansion_C-Contraction_C)^2 -> 0 | E10: ='Logo-Cohort'!E10*(1+Expansion_C-Contraction_C)^3 -> 0 | F10: ='Logo-Cohort'!F10*(1+Expansion_C-Contraction_C)^4 -> 0 | G10: ='Logo-Cohort'!G10*(1+Expansion_C-Contraction_C)^5 -> 0 | H10: ='Logo-Cohort'!H10*(1+Expansion_C-Contraction_C)^6 -> 0 | I10: ='Logo-Cohort'!I10*(1+Expansion_C-Contraction_C)^7 -> 0 | J10: ='Logo-Cohort'!J10*(1+Expansion_C-Contraction_C)^8 -> 0 | K10: ='Logo-Cohort'!K10*(1+Expansion_C-Contraction_C)^9 -> 0 | L10: ='Logo-Cohort'!L10*(1+Expansion_C-Contraction_C)^10 -> 0 | M10: ='Logo-Cohort'!M10*(1+Expansion_C-Contraction_C)^11 -> 0 | N10: ='Logo-Cohort'!N10*(1+Expansion_C-Contraction_C)^12 -> 0 | O10: ='Logo-Cohort'!O10*(1+Expansion_C-Contraction_C)^13 -> 0 | P10: ='Logo-Cohort'!P10*(1+Expansion_C-Contraction_C)^14 -> 0 | Q10: ='Logo-Cohort'!Q10*(1+Expansion_C-Contraction_C)^15 -> 0 | R10: ='Logo-Cohort'!R10*(1+Expansion_C-Contraction_C)^16 -> 0 | S10: ='Logo-Cohort'!S10*(1+Expansion_C-Contraction_C)^17 -> 0 | T10: ='Logo-Cohort'!T10*(1+Expansion_C-Contraction_C)^18 -> 0 | U10: ='Logo-Cohort'!U10*(1+Expansion_C-Contraction_C)^19 -> 0 | V10: ='Logo-Cohort'!V10*(1+Expansion_C-Contraction_C)^20 -> 0 | W10: ='Logo-Cohort'!W10*(1+Expansion_C-Contraction_C)^21 -> 0 | X10: ='Logo-Cohort'!X10*(1+Expansion_C-Contraction_C)^22 -> 0 | Y10: ='Logo-Cohort'!Y10*(1+Expansion_C-Contraction_C)^23 -> 0 | Z10: ='Logo-Cohort'!Z10*(1+Expansion_C-Contraction_C)^24 -> 0 | AA10: ='Logo-Cohort'!AA10*(1+Expansion_C-Contraction_C)^25 -> 0 | AB10: ='Logo-Cohort'!AB10*(1+Expansion_C-Contraction_C)^26 -> 0 | AC10: ='Logo-Cohort'!AC10*(1+Expansion_C-Contraction_C)^27 -> 0 | AD10: ='Logo-Cohort'!AD10*(1+Expansion_C-Contraction_C)^28 -> 0 | AE10: ='Logo-Cohort'!AE10*(1+Expansion_C-Contraction_C)^29 -> 0 | AF10: ='Logo-Cohort'!AF10*(1+Expansion_C-Contraction_C)^30 -> 0 | AG10: ='Logo-Cohort'!AG10*(1+Expansion_C-Contraction_C)^31 -> 0 | AH10: ='Logo-Cohort'!AH10*(1+Expansion_C-Contraction_C)^32 -> 0 | AI10: ='Logo-Cohort'!AI10*(1+Expansion_C-Contraction_C)^33 -> 0 | AJ10: ='Logo-Cohort'!AJ10*(1+Expansion_C-Contraction_C)^34 -> 0 | AK10: ='Logo-Cohort'!AK10*(1+Expansion_C-Contraction_C)^35 -> 0 | AL10: ='Logo-Cohort'!AL10*(1+Expansion_C-Contraction_C)^36 -> 0
A11: Cohort 06 | B11: 1 | C11: ='Logo-Cohort'!C11*(1+Expansion_C-Contraction_C)^1 -> 0 | D11: ='Logo-Cohort'!D11*(1+Expansion_C-Contraction_C)^2 -> 0 | E11: ='Logo-Cohort'!E11*(1+Expansion_C-Contraction_C)^3 -> 0 | F11: ='Logo-Cohort'!F11*(1+Expansion_C-Contraction_C)^4 -> 0 | G11: ='Logo-Cohort'!G11*(1+Expansion_C-Contraction_C)^5 -> 0 | H11: ='Logo-Cohort'!H11*(1+Expansion_C-Contraction_C)^6 -> 0 | I11: ='Logo-Cohort'!I11*(1+Expansion_C-Contraction_C)^7 -> 0 | J11: ='Logo-Cohort'!J11*(1+Expansion_C-Contraction_C)^8 -> 0 | K11: ='Logo-Cohort'!K11*(1+Expansion_C-Contraction_C)^9 -> 0 | L11: ='Logo-Cohort'!L11*(1+Expansion_C-Contraction_C)^10 -> 0 | M11: ='Logo-Cohort'!M11*(1+Expansion_C-Contraction_C)^11 -> 0 | N11: ='Logo-Cohort'!N11*(1+Expansion_C-Contraction_C)^12 -> 0 | O11: ='Logo-Cohort'!O11*(1+Expansion_C-Contraction_C)^13 -> 0 | P11: ='Logo-Cohort'!P11*(1+Expansion_C-Contraction_C)^14 -> 0 | Q11: ='Logo-Cohort'!Q11*(1+Expansion_C-Contraction_C)^15 -> 0 | R11: ='Logo-Cohort'!R11*(1+Expansion_C-Contraction_C)^16 -> 0 | S11: ='Logo-Cohort'!S11*(1+Expansion_C-Contraction_C)^17 -> 0 | T11: ='Logo-Cohort'!T11*(1+Expansion_C-Contraction_C)^18 -> 0 | U11: ='Logo-Cohort'!U11*(1+Expansion_C-Contraction_C)^19 -> 0 | V11: ='Logo-Cohort'!V11*(1+Expansion_C-Contraction_C)^20 -> 0 | W11: ='Logo-Cohort'!W11*(1+Expansion_C-Contraction_C)^21 -> 0 | X11: ='Logo-Cohort'!X11*(1+Expansion_C-Contraction_C)^22 -> 0 | Y11: ='Logo-Cohort'!Y11*(1+Expansion_C-Contraction_C)^23 -> 0 | Z11: ='Logo-Cohort'!Z11*(1+Expansion_C-Contraction_C)^24 -> 0 | AA11: ='Logo-Cohort'!AA11*(1+Expansion_C-Contraction_C)^25 -> 0 | AB11: ='Logo-Cohort'!AB11*(1+Expansion_C-Contraction_C)^26 -> 0 | AC11: ='Logo-Cohort'!AC11*(1+Expansion_C-Contraction_C)^27 -> 0 | AD11: ='Logo-Cohort'!AD11*(1+Expansion_C-Contraction_C)^28 -> 0 | AE11: ='Logo-Cohort'!AE11*(1+Expansion_C-Contraction_C)^29 -> 0 | AF11: ='Logo-Cohort'!AF11*(1+Expansion_C-Contraction_C)^30 -> 0 | AG11: ='Logo-Cohort'!AG11*(1+Expansion_C-Contraction_C)^31 -> 0 | AH11: ='Logo-Cohort'!AH11*(1+Expansion_C-Contraction_C)^32 -> 0 | AI11: ='Logo-Cohort'!AI11*(1+Expansion_C-Contraction_C)^33 -> 0 | AJ11: ='Logo-Cohort'!AJ11*(1+Expansion_C-Contraction_C)^34 -> 0 | AK11: ='Logo-Cohort'!AK11*(1+Expansion_C-Contraction_C)^35 -> 0 | AL11: ='Logo-Cohort'!AL11*(1+Expansion_C-Contraction_C)^36 -> 0
A12: Cohort 07 | B12: 1 | C12: ='Logo-Cohort'!C12*(1+Expansion_C-Contraction_C)^1 -> 0 | D12: ='Logo-Cohort'!D12*(1+Expansion_C-Contraction_C)^2 -> 0 | E12: ='Logo-Cohort'!E12*(1+Expansion_C-Contraction_C)^3 -> 0 | F12: ='Logo-Cohort'!F12*(1+Expansion_C-Contraction_C)^4 -> 0 | G12: ='Logo-Cohort'!G12*(1+Expansion_C-Contraction_C)^5 -> 0 | H12: ='Logo-Cohort'!H12*(1+Expansion_C-Contraction_C)^6 -> 0 | I12: ='Logo-Cohort'!I12*(1+Expansion_C-Contraction_C)^7 -> 0 | J12: ='Logo-Cohort'!J12*(1+Expansion_C-Contraction_C)^8 -> 0 | K12: ='Logo-Cohort'!K12*(1+Expansion_C-Contraction_C)^9 -> 0 | L12: ='Logo-Cohort'!L12*(1+Expansion_C-Contraction_C)^10 -> 0 | M12: ='Logo-Cohort'!M12*(1+Expansion_C-Contraction_C)^11 -> 0 | N12: ='Logo-Cohort'!N12*(1+Expansion_C-Contraction_C)^12 -> 0 | O12: ='Logo-Cohort'!O12*(1+Expansion_C-Contraction_C)^13 -> 0 | P12: ='Logo-Cohort'!P12*(1+Expansion_C-Contraction_C)^14 -> 0 | Q12: ='Logo-Cohort'!Q12*(1+Expansion_C-Contraction_C)^15 -> 0 | R12: ='Logo-Cohort'!R12*(1+Expansion_C-Contraction_C)^16 -> 0 | S12: ='Logo-Cohort'!S12*(1+Expansion_C-Contraction_C)^17 -> 0 | T12: ='Logo-Cohort'!T12*(1+Expansion_C-Contraction_C)^18 -> 0 | U12: ='Logo-Cohort'!U12*(1+Expansion_C-Contraction_C)^19 -> 0 | V12: ='Logo-Cohort'!V12*(1+Expansion_C-Contraction_C)^20 -> 0 | W12: ='Logo-Cohort'!W12*(1+Expansion_C-Contraction_C)^21 -> 0 | X12: ='Logo-Cohort'!X12*(1+Expansion_C-Contraction_C)^22 -> 0 | Y12: ='Logo-Cohort'!Y12*(1+Expansion_C-Contraction_C)^23 -> 0 | Z12: ='Logo-Cohort'!Z12*(1+Expansion_C-Contraction_C)^24 -> 0 | AA12: ='Logo-Cohort'!AA12*(1+Expansion_C-Contraction_C)^25 -> 0 | AB12: ='Logo-Cohort'!AB12*(1+Expansion_C-Contraction_C)^26 -> 0 | AC12: ='Logo-Cohort'!AC12*(1+Expansion_C-Contraction_C)^27 -> 0 | AD12: ='Logo-Cohort'!AD12*(1+Expansion_C-Contraction_C)^28 -> 0 | AE12: ='Logo-Cohort'!AE12*(1+Expansion_C-Contraction_C)^29 -> 0 | AF12: ='Logo-Cohort'!AF12*(1+Expansion_C-Contraction_C)^30 -> 0 | AG12: ='Logo-Cohort'!AG12*(1+Expansion_C-Contraction_C)^31 -> 0 | AH12: ='Logo-Cohort'!AH12*(1+Expansion_C-Contraction_C)^32 -> 0 | AI12: ='Logo-Cohort'!AI12*(1+Expansion_C-Contraction_C)^33 -> 0 | AJ12: ='Logo-Cohort'!AJ12*(1+Expansion_C-Contraction_C)^34 -> 0 | AK12: ='Logo-Cohort'!AK12*(1+Expansion_C-Contraction_C)^35 -> 0 | AL12: ='Logo-Cohort'!AL12*(1+Expansion_C-Contraction_C)^36 -> 0
A13: Cohort 08 | B13: 1 | C13: ='Logo-Cohort'!C13*(1+Expansion_C-Contraction_C)^1 -> 0 | D13: ='Logo-Cohort'!D13*(1+Expansion_C-Contraction_C)^2 -> 0 | E13: ='Logo-Cohort'!E13*(1+Expansion_C-Contraction_C)^3 -> 0 | F13: ='Logo-Cohort'!F13*(1+Expansion_C-Contraction_C)^4 -> 0 | G13: ='Logo-Cohort'!G13*(1+Expansion_C-Contraction_C)^5 -> 0 | H13: ='Logo-Cohort'!H13*(1+Expansion_C-Contraction_C)^6 -> 0 | I13: ='Logo-Cohort'!I13*(1+Expansion_C-Contraction_C)^7 -> 0 | J13: ='Logo-Cohort'!J13*(1+Expansion_C-Contraction_C)^8 -> 0 | K13: ='Logo-Cohort'!K13*(1+Expansion_C-Contraction_C)^9 -> 0 | L13: ='Logo-Cohort'!L13*(1+Expansion_C-Contraction_C)^10 -> 0 | M13: ='Logo-Cohort'!M13*(1+Expansion_C-Contraction_C)^11 -> 0 | N13: ='Logo-Cohort'!N13*(1+Expansion_C-Contraction_C)^12 -> 0 | O13: ='Logo-Cohort'!O13*(1+Expansion_C-Contraction_C)^13 -> 0 | P13: ='Logo-Cohort'!P13*(1+Expansion_C-Contraction_C)^14 -> 0 | Q13: ='Logo-Cohort'!Q13*(1+Expansion_C-Contraction_C)^15 -> 0 | R13: ='Logo-Cohort'!R13*(1+Expansion_C-Contraction_C)^16 -> 0 | S13: ='Logo-Cohort'!S13*(1+Expansion_C-Contraction_C)^17 -> 0 | T13: ='Logo-Cohort'!T13*(1+Expansion_C-Contraction_C)^18 -> 0 | U13: ='Logo-Cohort'!U13*(1+Expansion_C-Contraction_C)^19 -> 0 | V13: ='Logo-Cohort'!V13*(1+Expansion_C-Contraction_C)^20 -> 0 | W13: ='Logo-Cohort'!W13*(1+Expansion_C-Contraction_C)^21 -> 0 | X13: ='Logo-Cohort'!X13*(1+Expansion_C-Contraction_C)^22 -> 0 | Y13: ='Logo-Cohort'!Y13*(1+Expansion_C-Contraction_C)^23 -> 0 | Z13: ='Logo-Cohort'!Z13*(1+Expansion_C-Contraction_C)^24 -> 0 | AA13: ='Logo-Cohort'!AA13*(1+Expansion_C-Contraction_C)^25 -> 0 | AB13: ='Logo-Cohort'!AB13*(1+Expansion_C-Contraction_C)^26 -> 0 | AC13: ='Logo-Cohort'!AC13*(1+Expansion_C-Contraction_C)^27 -> 0 | AD13: ='Logo-Cohort'!AD13*(1+Expansion_C-Contraction_C)^28 -> 0 | AE13: ='Logo-Cohort'!AE13*(1+Expansion_C-Contraction_C)^29 -> 0 | AF13: ='Logo-Cohort'!AF13*(1+Expansion_C-Contraction_C)^30 -> 0 | AG13: ='Logo-Cohort'!AG13*(1+Expansion_C-Contraction_C)^31 -> 0 | AH13: ='Logo-Cohort'!AH13*(1+Expansion_C-Contraction_C)^32 -> 0 | AI13: ='Logo-Cohort'!AI13*(1+Expansion_C-Contraction_C)^33 -> 0 | AJ13: ='Logo-Cohort'!AJ13*(1+Expansion_C-Contraction_C)^34 -> 0 | AK13: ='Logo-Cohort'!AK13*(1+Expansion_C-Contraction_C)^35 -> 0 | AL13: ='Logo-Cohort'!AL13*(1+Expansion_C-Contraction_C)^36 -> 0
A14: Cohort 09 | B14: 1 | C14: ='Logo-Cohort'!C14*(1+Expansion_C-Contraction_C)^1 -> 0 | D14: ='Logo-Cohort'!D14*(1+Expansion_C-Contraction_C)^2 -> 0 | E14: ='Logo-Cohort'!E14*(1+Expansion_C-Contraction_C)^3 -> 0 | F14: ='Logo-Cohort'!F14*(1+Expansion_C-Contraction_C)^4 -> 0 | G14: ='Logo-Cohort'!G14*(1+Expansion_C-Contraction_C)^5 -> 0 | H14: ='Logo-Cohort'!H14*(1+Expansion_C-Contraction_C)^6 -> 0 | I14: ='Logo-Cohort'!I14*(1+Expansion_C-Contraction_C)^7 -> 0 | J14: ='Logo-Cohort'!J14*(1+Expansion_C-Contraction_C)^8 -> 0 | K14: ='Logo-Cohort'!K14*(1+Expansion_C-Contraction_C)^9 -> 0 | L14: ='Logo-Cohort'!L14*(1+Expansion_C-Contraction_C)^10 -> 0 | M14: ='Logo-Cohort'!M14*(1+Expansion_C-Contraction_C)^11 -> 0 | N14: ='Logo-Cohort'!N14*(1+Expansion_C-Contraction_C)^12 -> 0 | O14: ='Logo-Cohort'!O14*(1+Expansion_C-Contraction_C)^13 -> 0 | P14: ='Logo-Cohort'!P14*(1+Expansion_C-Contraction_C)^14 -> 0 | Q14: ='Logo-Cohort'!Q14*(1+Expansion_C-Contraction_C)^15 -> 0 | R14: ='Logo-Cohort'!R14*(1+Expansion_C-Contraction_C)^16 -> 0 | S14: ='Logo-Cohort'!S14*(1+Expansion_C-Contraction_C)^17 -> 0 | T14: ='Logo-Cohort'!T14*(1+Expansion_C-Contraction_C)^18 -> 0 | U14: ='Logo-Cohort'!U14*(1+Expansion_C-Contraction_C)^19 -> 0 | V14: ='Logo-Cohort'!V14*(1+Expansion_C-Contraction_C)^20 -> 0 | W14: ='Logo-Cohort'!W14*(1+Expansion_C-Contraction_C)^21 -> 0 | X14: ='Logo-Cohort'!X14*(1+Expansion_C-Contraction_C)^22 -> 0 | Y14: ='Logo-Cohort'!Y14*(1+Expansion_C-Contraction_C)^23 -> 0 | Z14: ='Logo-Cohort'!Z14*(1+Expansion_C-Contraction_C)^24 -> 0 | AA14: ='Logo-Cohort'!AA14*(1+Expansion_C-Contraction_C)^25 -> 0 | AB14: ='Logo-Cohort'!AB14*(1+Expansion_C-Contraction_C)^26 -> 0 | AC14: ='Logo-Cohort'!AC14*(1+Expansion_C-Contraction_C)^27 -> 0 | AD14: ='Logo-Cohort'!AD14*(1+Expansion_C-Contraction_C)^28 -> 0 | AE14: ='Logo-Cohort'!AE14*(1+Expansion_C-Contraction_C)^29 -> 0 | AF14: ='Logo-Cohort'!AF14*(1+Expansion_C-Contraction_C)^30 -> 0 | AG14: ='Logo-Cohort'!AG14*(1+Expansion_C-Contraction_C)^31 -> 0 | AH14: ='Logo-Cohort'!AH14*(1+Expansion_C-Contraction_C)^32 -> 0 | AI14: ='Logo-Cohort'!AI14*(1+Expansion_C-Contraction_C)^33 -> 0 | AJ14: ='Logo-Cohort'!AJ14*(1+Expansion_C-Contraction_C)^34 -> 0 | AK14: ='Logo-Cohort'!AK14*(1+Expansion_C-Contraction_C)^35 -> 0 | AL14: ='Logo-Cohort'!AL14*(1+Expansion_C-Contraction_C)^36 -> 0
A15: Cohort 10 | B15: 1 | C15: ='Logo-Cohort'!C15*(1+Expansion_C-Contraction_C)^1 -> 0 | D15: ='Logo-Cohort'!D15*(1+Expansion_C-Contraction_C)^2 -> 0 | E15: ='Logo-Cohort'!E15*(1+Expansion_C-Contraction_C)^3 -> 0 | F15: ='Logo-Cohort'!F15*(1+Expansion_C-Contraction_C)^4 -> 0 | G15: ='Logo-Cohort'!G15*(1+Expansion_C-Contraction_C)^5 -> 0 | H15: ='Logo-Cohort'!H15*(1+Expansion_C-Contraction_C)^6 -> 0 | I15: ='Logo-Cohort'!I15*(1+Expansion_C-Contraction_C)^7 -> 0 | J15: ='Logo-Cohort'!J15*(1+Expansion_C-Contraction_C)^8 -> 0 | K15: ='Logo-Cohort'!K15*(1+Expansion_C-Contraction_C)^9 -> 0 | L15: ='Logo-Cohort'!L15*(1+Expansion_C-Contraction_C)^10 -> 0 | M15: ='Logo-Cohort'!M15*(1+Expansion_C-Contraction_C)^11 -> 0 | N15: ='Logo-Cohort'!N15*(1+Expansion_C-Contraction_C)^12 -> 0 | O15: ='Logo-Cohort'!O15*(1+Expansion_C-Contraction_C)^13 -> 0 | P15: ='Logo-Cohort'!P15*(1+Expansion_C-Contraction_C)^14 -> 0 | Q15: ='Logo-Cohort'!Q15*(1+Expansion_C-Contraction_C)^15 -> 0 | R15: ='Logo-Cohort'!R15*(1+Expansion_C-Contraction_C)^16 -> 0 | S15: ='Logo-Cohort'!S15*(1+Expansion_C-Contraction_C)^17 -> 0 | T15: ='Logo-Cohort'!T15*(1+Expansion_C-Contraction_C)^18 -> 0 | U15: ='Logo-Cohort'!U15*(1+Expansion_C-Contraction_C)^19 -> 0 | V15: ='Logo-Cohort'!V15*(1+Expansion_C-Contraction_C)^20 -> 0 | W15: ='Logo-Cohort'!W15*(1+Expansion_C-Contraction_C)^21 -> 0 | X15: ='Logo-Cohort'!X15*(1+Expansion_C-Contraction_C)^22 -> 0 | Y15: ='Logo-Cohort'!Y15*(1+Expansion_C-Contraction_C)^23 -> 0 | Z15: ='Logo-Cohort'!Z15*(1+Expansion_C-Contraction_C)^24 -> 0 | AA15: ='Logo-Cohort'!AA15*(1+Expansion_C-Contraction_C)^25 -> 0 | AB15: ='Logo-Cohort'!AB15*(1+Expansion_C-Contraction_C)^26 -> 0 | AC15: ='Logo-Cohort'!AC15*(1+Expansion_C-Contraction_C)^27 -> 0 | AD15: ='Logo-Cohort'!AD15*(1+Expansion_C-Contraction_C)^28 -> 0 | AE15: ='Logo-Cohort'!AE15*(1+Expansion_C-Contraction_C)^29 -> 0 | AF15: ='Logo-Cohort'!AF15*(1+Expansion_C-Contraction_C)^30 -> 0 | AG15: ='Logo-Cohort'!AG15*(1+Expansion_C-Contraction_C)^31 -> 0 | AH15: ='Logo-Cohort'!AH15*(1+Expansion_C-Contraction_C)^32 -> 0 | AI15: ='Logo-Cohort'!AI15*(1+Expansion_C-Contraction_C)^33 -> 0 | AJ15: ='Logo-Cohort'!AJ15*(1+Expansion_C-Contraction_C)^34 -> 0 | AK15: ='Logo-Cohort'!AK15*(1+Expansion_C-Contraction_C)^35 -> 0 | AL15: ='Logo-Cohort'!AL15*(1+Expansion_C-Contraction_C)^36 -> 0
