Workbook
Name ARPA_Mult: Inputs!$B$8
Name ARPA_P: Inputs!$B$18
Name CAC_P: Inputs!$B$96
Name Capex_Y1: Inputs!$B$82
Name Capex_Y2: Inputs!$B$83
Name Capex_Y3: Inputs!$B$84
Name Capex_Y4: Inputs!$B$85
Name Capex_Y5: Inputs!$B$86
Name Churn_Mult: Inputs!$B$7
Name COGS_PCT: Inputs!$B$46
Name Contraction_P: Inputs!$B$36
Name Eq_Y1: Inputs!$B$88
Name Eq_Y2: Inputs!$B$89
Name Eq_Y3: Inputs!$B$90
Name Expansion_P: Inputs!$B$35
Name FX_P: Inputs!$B$99
Name G_Y1: Inputs!$B$25
Name G_Y2: Inputs!$B$26
Name G_Y3: Inputs!$B$27
Name G_Y4: Inputs!$B$28
Name G_Y5: Inputs!$B$29
Name GA_Y1: Inputs!$B$56
Name GA_Y2: Inputs!$B$57
Name GA_Y3p: Inputs!$B$58
Name GM_P: Inputs!$B$47
Name HC_Cost_Y1: Inputs!$D$75
Name HC_Q_Cost_Row: Headcount!$A$15
Name HC_Total_Y1: Inputs!$D$74
Name Logo_Churn_P: Inputs!$B$37
Name Logo_Mult: Inputs!$B$6
Name M1_Logos: Inputs!$B$30
Name RD_Y1: Inputs!$B$53
Name RD_Y2: Inputs!$B$54
Name RD_Y3p: Inputs!$B$55
Name Rev_Churn_P: Inputs!$B$38
Name Scen_Active: Inputs!$B$5
Name SM_Y1: Inputs!$B$50
Name SM_Y2: Inputs!$B$51
Name SM_Y3p: Inputs!$B$52
Name Start_Cash: Inputs!$B$87
Name Tax_Rate: Inputs!$B$93

Sheet README
A1: SaaS Financial Projection — 3-Year / 5-Year (60 Months)
A3: Purpose | B3: Canonical SaaS 60-month financial model implementing Mersch's Multi-Step P&L, ARR Waterfall discipline, Cotton's headcount Rule of 3-and-10, and the Working-Capital Trough check. Single source of truth feeding the bankability dashboard, investor pitch, lender package, and quarterly board pack.
A5: Sheets in this workbook
A6: Inputs | B6: Pricing, ACV mix, new logos by channel, growth, GM, headcount-by-role, salaries, capex, working capital, FX.
A7: ARR-Waterfall | B7: 60-month opening + new + expansion − contraction − churned = closing ARR.
A8: MRR-Detail | B8: MRR build by tier & channel; reconciliation to ARR.
A9: Headcount | B9: Quarterly headcount by role with cost rollup.
A10: PnL | B10: Multi-Step P&L: Rev → COGS → GP → S&M → R&D → G&A → EBITDA → Adj → NI. Monthly + quarterly + annual.
A11: Cash | B11: CFO + capex + financing; running balance; trough month flagged; runway.
A12: Sensitivity | B12: 2-D table: new-logo growth × churn → ending ARR + runway.
A13: Scenarios | B13: Base / Bull / Bear active scenario toggle.
A14: Bankability-Dashboard | B14: Rule of 40, LTV:CAC, Payback, NRR, Burn Multiple, Magic Number, Quick Ratio + traffic lights.
A15: Africa-Notes | B15: FX, M-Pesa, MoMo, USD-Enterprise tier, DSO, prepayment uptake.
A17: Owner | B17: CFO (founder pre-CFO). Investor-facing: review with CEO monthly.
A18: Update cadence | B18: Monthly: refresh actuals against plan. Quarterly: re-forecast next 4 quarters. Annually: roll forward year-by-year.
... A22: Currency convention | B22: All inputs in USD. Use FX cell on Inputs sheet to display local-currency equivalents (UGX, KES, NGN, ZAR, EGP). Mobile-money (M-Pesa / MoMo) and card-rail fees enter as % of revenue.

Sheet Inputs
A1: Inputs — SaaS 60-Month Financial Projection
A2: Yellow = editable input. White = formula. Named ranges in use throughout.
A4: 0. Scenario Toggle
A5: Active scenario (Base / Bull / Bear) | B5: Base | G5: Drives Scenario_Active multipliers on logos, churn, ARPA, FX.
A6: Logo growth multiplier (active scenario) | B6: =IF(B5="Bull",1.25,IF(B5="Bear",0.75,1)) -> 0
A7: Churn multiplier (active scenario) | B7: =IF(B5="Bull",0.75,IF(B5="Bear",1.5,1)) -> 0
A8: ARPA multiplier (active scenario) | B8: =IF(B5="Bull",1.20,IF(B5="Bear",0.85,1)) -> 0
A10: 1. Pricing & Tier Mix
A11: Tier 1 (Free/Starter) MRR $ | B11: 0
A12: Tier 2 (Pro) MRR $ | B12: 79
A13: Tier 3 (Enterprise USD) MRR $ | B13: 499
A14: Mix % Tier 1 | B14: 0.2
A15: Mix % Tier 2 | B15: 0.6
A16: Mix % Tier 3 | B16: 0.2
A17: Annual price escalator | B17: 0.05
A18: Blended ARPA ($/mo) [calc, scenario-adj] | B18: =(B11*B14+B12*B15+B13*B16)*B8 -> 0
A20: 2. New Logos / Month (Year 1 baseline; Y2+ from growth rates)
A21: M1 new logos (paid) | B21: 3
A22: M1 new logos (inbound) | B22: 5
A23: M1 new logos (outbound) | B23: 2
A24: M1 new logos (partner) | B24: 1
A25: Monthly new-logo growth rate Year 1 | B25: 0.1
A26: Monthly new-logo growth rate Year 2 | B26: 0.07
A27: Monthly new-logo growth rate Year 3 | B27: 0.05
A28: Monthly new-logo growth rate Year 4 | B28: 0.04
A29: Monthly new-logo growth rate Year 5 | B29: 0.03
A30: M1 new logos total [calc] | B30: =B21+B22+B23+B24 -> 0
A32: 3. Churn & Expansion (monthly)
A33: Logo churn (gross) monthly | B33: 0.025
A34: Revenue churn (gross) monthly | B34: 0.02
A35: Expansion revenue monthly rate | B35: 0.012
A36: Contraction monthly rate | B36: 0.004
A37: Scenario-adjusted logo churn [calc] | B37: =B33*B7 -> 0
A38: Scenario-adjusted revenue churn [calc] | B38: =B34*B7 -> 0
A40: 4. Cost of Revenue % of revenue
A41: Hosting / infra % | B41: 0.08
A42: Customer support % | B42: 0.06
A43: Payment-rail fee % | B43: 0.025
A44: 3rd-party / API / data % | B44: 0.04
A45: Customer-success % | B45: 0.05
...

Sheet ARR-Waterfall
A1: ARR Waterfall — 60 Months
A3: Month | B3: M1 | C3: M2 | D3: M3 | E3: M4 | F3: M5 | G3: M6 | H3: M7 | I3: M8 | J3: M9 | K3: M10 | L3: M11 | M3: M12 | N3: M13 | O3: M14 | P3: M15 | Q3: M16 | R3: M17 | S3: M18 | T3: M19 | U3: M20 | V3: M21 | W3: M22 | X3: M23 | Y3: M24 | Z3: M25 | AA3: M26 | AB3: M27 | AC3: M28 | AD3: M29 | AE3: M30 | AF3: M31 | AG3: M32 | AH3: M33 | AI3: M34 | AJ3: M35 | AK3: M36 | AL3: M37 | AM3: M38 | AN3: M39 | AO3: M40 | AP3: M41 | AQ3: M42 | AR3: M43 | AS3: M44 | AT3: M45 | AU3: M46 | AV3: M47 | AW3: M48 | AX3: M49 | AY3: M50 | AZ3: M51 | BA3: M52 | BB3: M53 | BC3: M54 | BD3: M55 | BE3: M56 | BF3: M57 | BG3: M58 | BH3: M59 | BI3: M60
A4: Year | B4: 1 | C4: 1 | D4: 1 | E4: 1 | F4: 1 | G4: 1 | H4: 1 | I4: 1 | J4: 1 | K4: 1 | L4: 1 | M4: 1 | N4: 2 | O4: 2 | P4: 2 | Q4: 2 | R4: 2 | S4: 2 | T4: 2 | U4: 2 | V4: 2 | W4: 2 | X4: 2 | Y4: 2 | Z4: 3 | AA4: 3 | AB4: 3 | AC4: 3 | AD4: 3 | AE4: 3 | AF4: 3 | AG4: 3 | AH4: 3 | AI4: 3 | AJ4: 3 | AK4: 3 | AL4: 4 | AM4: 4 | AN4: 4 | AO4: 4 | AP4: 4 | AQ4: 4 | AR4: 4 | AS4: 4 | AT4: 4 | AU4: 4 | AV4: 4 | AW4: 4 | AX4: 5 | AY4: 5 | AZ4: 5 | BA4: 5 | BB4: 5 | BC4: 5 | BD4: 5 | BE4: 5 | BF4: 5 | BG4: 5 | BH4: 5 | BI4: 5
A5: New logos (count) | B5: =M1_Logos*Logo_Mult -> 0 | C5: =ROUND(B5*(1+IF(C4=1, G_Y1, IF(C4=2, G_Y2, IF(C4=3, G_Y3, IF(C4=4, G_Y4, G_Y5))))),0) -> 0 | D5: =ROUND(C5*(1+IF(D4=1, G_Y1, IF(D4=2, G_Y2, IF(D4=3, G_Y3, IF(D4=4, G_Y4, G_Y5))))),0) -> 0 | E5: =ROUND(D5*(1+IF(E4=1, G_Y1, IF(E4=2, G_Y2, IF(E4=3, G_Y3, IF(E4=4, G_Y4, G_Y5))))),0) -> 0 | F5: =ROUND(E5*(1+IF(F4=1, G_Y1, IF(F4=2, G_Y2, IF(F4=3, G_Y3, IF(F4=4, G_Y4, G_Y5))))),0) -> 0 | G5: =ROUND(F5*(1+IF(G4=1, G_Y1, IF(G4=2, G_Y2, IF(G4=3, G_Y3, IF(G4=4, G_Y4, G_Y5))))),0) -> 0 | H5: =ROUND(G5*(1+IF(H4=1, G_Y1, IF(H4=2, G_Y2, IF(H4=3, G_Y3, IF(H4=4, G_Y4, G_Y5))))),0) -> 0 | I5: =ROUND(H5*(1+IF(I4=1, G_Y1, IF(I4=2, G_Y2, IF(I4=3, G_Y3, IF(I4=4, G_Y4, G_Y5))))),0) -> 0 | J5: =ROUND(I5*(1+IF(J4=1, G_Y1, IF(J4=2, G_Y2, IF(J4=3, G_Y3, IF(J4=4, G_Y4, G_Y5))))),0) -> 0 | ... BI5: =ROUND(BH5*(1+IF(BI4=1, G_Y1, IF(BI4=2, G_Y2, IF(BI4=3, G_Y3, IF(BI4=4, G_Y4, G_Y5))))),0) -> 0
A6: Cum customers (end) | B6: =B5 -> 0 | C6: =B6*(1-Logo_Churn_P)+C5 -> 0 | D6: =C6*(1-Logo_Churn_P)+D5 -> 0 | E6: =D6*(1-Logo_Churn_P)+E5 -> 0 | F6: =E6*(1-Logo_Churn_P)+F5 -> 0 | G6: =F6*(1-Logo_Churn_P)+G5 -> 0 | H6: =G6*(1-Logo_Churn_P)+H5 -> 0 | I6: =H6*(1-Logo_Churn_P)+I5 -> 0 | J6: =I6*(1-Logo_Churn_P)+J5 -> 0 | ... BI6: =BH6*(1-Logo_Churn_P)+BI5 -> 0
A7: Opening ARR | B7: 0 | C7: =B12 -> 0 | D7: =C12 -> 0 | E7: =D12 -> 0 | F7: =E12 -> 0 | G7: =F12 -> 0 | H7: =G12 -> 0 | I7: =H12 -> 0 | J7: =I12 -> 0 | ... BI7: =BH12 -> 0
A8: New ARR | B8: =B5*ARPA_P*12 -> 0 | C8: =C5*ARPA_P*12 -> 0 | D8: =D5*ARPA_P*12 -> 0 | E8: =E5*ARPA_P*12 -> 0 | F8: =F5*ARPA_P*12 -> 0 | G8: =G5*ARPA_P*12 -> 0 | H8: =H5*ARPA_P*12 -> 0 | I8: =I5*ARPA_P*12 -> 0 | ... BI8: =BI5*ARPA_P*12 -> 0
A9: Expansion ARR | B9: =B7*Expansion_P -> 0 | C9: =C7*Expansion_P -> 0 | D9: =D7*Expansion_P -> 0 | E9: =E7*Expansion_P -> 0 | F9: =F7*Expansion_P -> 0 | G9: =G7*Expansion_P -> 0 | H9: =H7*Expansion_P -> 0 | I9: =I7*Expansion_P -> 0 | ... BI9: =BI7*Expansion_P -> 0
A10: Contraction ARR | B10: =-B7*Contraction_P -> 0 | C10: =-C7*Contraction_P -> 0 | D10: =-D7*Contraction_P -> 0 | E10: =-E7*Contraction_P -> 0 | F10: =-F7*Contraction_P -> 0 | G10: =-G7*Contraction_P -> 0 | H10: =-H7*Contraction_P -> 0 | I10: =-I7*Contraction_P -> 0 | ... BI10: =-BI7*Contraction_P -> 0
A11: Churn ARR | B11: =-B7*Rev_Churn_P -> 0 | C11: =-C7*Rev_Churn_P -> 0 | D11: =-D7*Rev_Churn_P -> 0 | E11: =-E7*Rev_Churn_P -> 0 | F11: =-F7*Rev_Churn_P -> 0 | G11: =-G7*Rev_Churn_P -> 0 | H11: =-H7*Rev_Churn_P -> 0 | I11: =-I7*Rev_Churn_P -> 0 | ... BI11: =-BI7*Rev_Churn_P -> 0
A12: Ending ARR | B12: =B7+B8+B9+B10+B11 -> 0 | C12: =C7+C8+C9+C10+C11 -> 0 | D12: =D7+D8+D9+D10+D11 -> 0 | E12: =E7+E8+E9+E10+E11 -> 0 | F12: =F7+F8+F9+F10+F11 -> 0 | G12: =G7+G8+G9+G10+G11 -> 0 | H12: =H7+H8+H9+H10+H11 -> 0 | I12: =I7+I8+I9+I10+I11 -> 0 | ... BI12: =BI7+BI8+BI9+BI10+BI11 -> 0
A13: Net New ARR | B13: =B8+B9+B10+B11 -> 0 | C13: =C8+C9+C10+C11 -> 0 | D13: =D8+D9+D10+D11 -> 0 | E13: =E8+E9+E10+E11 -> 0 | F13: =F8+F9+F10+F11 -> 0 | G13: =G8+G9+G10+G11 -> 0 | H13: =H8+H9+H10+H11 -> 0 | I13: =I8+I9+I10+I11 -> 0 | ... BI13: =BI8+BI9+BI10+BI11 -> 0
A14: MRR (end) | B14: =B12/12 -> 0 | C14: =C12/12 -> 0 | D14: =D12/12 -> 0 | E14: =E12/12 -> 0 | F14: =F12/12 -> 0 | G14: =G12/12 -> 0 | H14: =H12/12 -> 0 | I14: =I12/12 -> 0 | ... BI14: =BI12/12 -> 0
A16: Annual Snapshot — Ending ARR & YoY Growth
A17: End of Year | B17: Y1 | C17: Y2 | D17: Y3 | E17: Y4 | F17: Y5
A18: Ending ARR | B18: =M12 -> 0 | C18: =Y12 -> 0 | D18: =AK12 -> 0 | E18: =AW12 -> 0 | F18: =BI12 -> 0
A19: YoY Growth % | C19: =Y12/M12-1 -> 0 | D19: =AK12/Y12-1 -> 0 | E19: =AW12/AK12-1 -> 0 | F19: =BI12/AW12-1 -> 0

Sheet MRR-Detail
A1: MRR Detail — by Tier (reconciles to ARR Waterfall)
A3: Month | B3: M1 | C3: M2 | D3: M3 | E3: M4 | F3: M5 | G3: M6 | H3: M7 | I3: M8 | J3: M9 | K3: M10 | L3: M11 | M3: M12 | N3: M13 | O3: M14 | P3: M15 | Q3: M16 | R3: M17 | S3: M18 | T3: M19 | U3: M20 | V3: M21 | W3: M22 | X3: M23 | Y3: M24 | Z3: M25 | AA3: M26 | AB3: M27 | AC3: M28 | AD3: M29 | AE3: M30 | AF3: M31 | AG3: M32 | AH3: M33 | AI3: M34 | AJ3: M35 | AK3: M36 | AL3: M37 | AM3: M38 | AN3: M39 | AO3: M40 | AP3: M41 | AQ3: M42 | AR3: M43 | AS3: M44 | AT3: M45 | AU3: M46 | AV3: M47 | AW3: M48 | AX3: M49 | AY3: M50 | AZ3: M51 | BA3: M52 | BB3: M53 | BC3: M54 | BD3: M55 | BE3: M56 | BF3: M57 | BG3: M58 | BH3: M59 | BI3: M60
A4: Tier 1 (Starter) MRR | B4: ='ARR-Waterfall'!B6*Inputs!$B$14*Inputs!$B$11 -> 0 | C4: ='ARR-Waterfall'!C6*Inputs!$B$14*Inputs!$B$11 -> 0 | D4: ='ARR-Waterfall'!D6*Inputs!$B$14*Inputs!$B$11 -> 0 | E4: ='ARR-Waterfall'!E6*Inputs!$B$14*Inputs!$B$11 -> 0 | F4: ='ARR-Waterfall'!F6*Inputs!$B$14*Inputs!$B$11 -> 0 | G4: ='ARR-Waterfall'!G6*Inputs!$B$14*Inputs!$B$11 -> 0 | H4: ='ARR-Waterfall'!H6*Inputs!$B$14*Inputs!$B$11 -> 0 | I4: ='ARR-Waterfall'!I6*Inputs!$B$14*Inputs!$B$11 -> 0 | ... BI4: ='ARR-Waterfall'!BI6*Inputs!$B$14*Inputs!$B$11 -> 0
A5: Tier 2 (Pro) MRR | B5: ='ARR-Waterfall'!B6*Inputs!$B$15*Inputs!$B$12 -> 0 | C5: ='ARR-Waterfall'!C6*Inputs!$B$15*Inputs!$B$12 -> 0 | D5: ='ARR-Waterfall'!D6*Inputs!$B$15*Inputs!$B$12 -> 0 | E5: ='ARR-Waterfall'!E6*Inputs!$B$15*Inputs!$B$12 -> 0 | F5: ='ARR-Waterfall'!F6*Inputs!$B$15*Inputs!$B$12 -> 0 | G5: ='ARR-Waterfall'!G6*Inputs!$B$15*Inputs!$B$12 -> 0 | H5: ='ARR-Waterfall'!H6*Inputs!$B$15*Inputs!$B$12 -> 0 | I5: ='ARR-Waterfall'!I6*Inputs!$B$15*Inputs!$B$12 -> 0 | ... BI5: ='ARR-Waterfall'!BI6*Inputs!$B$15*Inputs!$B$12 -> 0
A6: Tier 3 (Enterprise) MRR | B6: ='ARR-Waterfall'!B6*Inputs!$B$16*Inputs!$B$13 -> 0 | C6: ='ARR-Waterfall'!C6*Inputs!$B$16*Inputs!$B$13 -> 0 | D6: ='ARR-Waterfall'!D6*Inputs!$B$16*Inputs!$B$13 -> 0 | E6: ='ARR-Waterfall'!E6*Inputs!$B$16*Inputs!$B$13 -> 0 | F6: ='ARR-Waterfall'!F6*Inputs!$B$16*Inputs!$B$13 -> 0 | G6: ='ARR-Waterfall'!G6*Inputs!$B$16*Inputs!$B$13 -> 0 | H6: ='ARR-Waterfall'!H6*Inputs!$B$16*Inputs!$B$13 -> 0 | I6: ='ARR-Waterfall'!I6*Inputs!$B$16*Inputs!$B$13 -> 0 | ... BI6: ='ARR-Waterfall'!BI6*Inputs!$B$16*Inputs!$B$13 -> 0
A7: Total MRR (sum) | B7: =SUM(B4:B6) -> 0 | C7: =SUM(C4:C6) -> 0 | D7: =SUM(D4:D6) -> 0 | E7: =SUM(E4:E6) -> 0 | F7: =SUM(F4:F6) -> 0 | G7: =SUM(G4:G6) -> 0 | H7: =SUM(H4:H6) -> 0 | I7: =SUM(I4:I6) -> 0 | ... BI7: =SUM(BI4:BI6) -> 0
A8: ARR check (×12) | B8: =B7*12 -> 0 | C8: =C7*12 -> 0 | D8: =D7*12 -> 0 | E8: =E7*12 -> 0 | F8: =F7*12 -> 0 | G8: =G7*12 -> 0 | H8: =H7*12 -> 0 | I8: =I7*12 -> 0 | ... BI8: =BI7*12 -> 0
A9: ARR-Waterfall Ending ARR | B9: ='ARR-Waterfall'!B12 -> 0 | C9: ='ARR-Waterfall'!C12 -> 0 | D9: ='ARR-Waterfall'!D12 -> 0 | E9: ='ARR-Waterfall'!E12 -> 0 | F9: ='ARR-Waterfall'!F12 -> 0 | G9: ='ARR-Waterfall'!G12 -> 0 | H9: ='ARR-Waterfall'!H12 -> 0 | I9: ='ARR-Waterfall'!I12 -> 0 | ... BI9: ='ARR-Waterfall'!BI12 -> 0
A10: Reconciliation Δ (should be ≈0) | B10: =B8-B9 -> 0 | C10: =C8-C9 -> 0 | D10: =D8-D9 -> 0 | E10: =E8-E9 -> 0 | F10: =F8-F9 -> 0 | G10: =G8-G9 -> 0 | H10: =H8-H9 -> 0 | I10: =I8-I9 -> 0 | ... BI10: =BI8-BI9 -> 0

Sheet Headcount
A1: Headcount Plan — Quarterly Y1..Y5
A3: Role | B3: Y1Q1 | C3: Y1Q2 | D3: Y1Q3 | E3: Y1Q4 | F3: Y2Q1 | G3: Y2Q2 | H3: Y2Q3 | I3: Y2Q4 | J3: Y3Q1 | K3: Y3Q2 | L3: Y3Q3 | M3: Y3Q4 | N3: Y4Q1 | O3: Y4Q2 | P3: Y4Q3 | Q3: Y4Q4 | R3: Y5Q1 | S3: Y5Q2 | T3: Y5Q3 | U3: Y5Q4
A4: Engineering Lead | B4: 1 | C4: 1 | D4: 1 | E4: 1 | F4: 2 | G4: 2 | H4: 2 | I4: 2 | J4: 3 | K4: 3 | L4: 3 | M4: 3 | N4: 4 | O4: 4 | P4: 4 | Q4: 4 | R4: 4 | S4: 4 | T4: 4 | U4: 4
A5: Software Engineer | B5: 2 | C5: 2 | D5: 2 | E5: 2 | F5: 4 | G5: 4 | H5: 4 | I5: 4 | J5: 7 | K5: 7 | L5: 7 | M5: 7 | N5: 10 | O5: 10 | P5: 10 | Q5: 10 | R5: 10 | S5: 10 | T5: 10 | U5: 10
A6: Product Manager | B6: 1 | C6: 1 | D6: 1 | E6: 1 | F6: 1 | G6: 1 | H6: 1 | I6: 1 | J6: 2 | K6: 2 | L6: 2 | M6: 2 | N6: 3 | O6: 3 | P6: 3 | Q6: 3 | R6: 3 | S6: 3 | T6: 3 | U6: 3
A7: Designer | B7: 1 | C7: 1 | D7: 1 | E7: 1 | F7: 1 | G7: 1 | H7: 1 | I7: 1 | J7: 2 | K7: 2 | L7: 2 | M7: 2 | N7: 2 | O7: 2 | P7: 2 | Q7: 2 | R7: 2 | S7: 2 | T7: 2 | U7: 2
A8: Account Executive | B8: 1 | C8: 1 | D8: 1 | E8: 1 | F8: 3 | G8: 3 | H8: 3 | I8: 3 | J8: 6 | K8: 6 | L8: 6 | M8: 6 | N8: 10 | O8: 10 | P8: 10 | Q8: 10 | R8: 10 | S8: 10 | T8: 10 | U8: 10
A9: SDR / BDR | B9: 1 | C9: 1 | D9: 1 | E9: 1 | F9: 2 | G9: 2 | H9: 2 | I9: 2 | J9: 5 | K9: 5 | L9: 5 | M9: 5 | N9: 8 | O9: 8 | P9: 8 | Q9: 8 | R9: 8 | S9: 8 | T9: 8 | U9: 8
A10: Marketing Manager | B10: 1 | C10: 1 | D10: 1 | E10: 1 | F10: 1 | G10: 1 | H10: 1 | I10: 1 | J10: 2 | K10: 2 | L10: 2 | M10: 2 | N10: 3 | O10: 3 | P10: 3 | Q10: 3 | R10: 3 | S10: 3 | T10: 3 | U10: 3
A11: Customer Success Mgr | B11: 1 | C11: 1 | D11: 1 | E11: 1 | F11: 2 | G11: 2 | H11: 2 | I11: 2 | J11: 4 | K11: 4 | L11: 4 | M11: 4 | N11: 6 | O11: 6 | P11: 6 | Q11: 6 | R11: 6 | S11: 6 | T11: 6 | U11: 6
A12: Finance / Ops | B12: 1 | C12: 1 | D12: 1 | E12: 1 | F12: 1 | G12: 1 | H12: 1 | I12: 1 | J12: 2 | K12: 2 | L12: 2 | M12: 2 | N12: 3 | O12: 3 | P12: 3 | Q12: 3 | R12: 3 | S12: 3 | T12: 3 | U12: 3
A13: CEO / Founder | B13: 1 | C13: 1 | D13: 1 | E13: 1 | F13: 1 | G13: 1 | H13: 1 | I13: 1 | J13: 1 | K13: 1 | L13: 1 | M13: 1 | N13: 1 | O13: 1 | P13: 1 | Q13: 1 | R13: 1 | S13: 1 | T13: 1 | U13: 1
A14: Total Headcount | B14: =SUM(B4:B13) -> 0 | C14: =SUM(C4:C13) -> 0 | D14: =SUM(D4:D13) -> 0 | E14: =SUM(E4:E13) -> 0 | F14: =SUM(F4:F13) -> 0 | G14: =SUM(G4:G13) -> 0 | H14: =SUM(H4:H13) -> 0 | I14: =SUM(I4:I13) -> 0 | ... U14: =SUM(U4:U13) -> 0
A15: Quarterly Loaded Cost $ | B15: =SUMPRODUCT(B4:B13,Inputs!$B$63:$B$72)/4 -> 0 | C15: =SUMPRODUCT(C4:C13,Inputs!$B$63:$B$72)/4 -> 0 | D15: =SUMPRODUCT(D4:D13,Inputs!$B$63:$B$72)/4 -> 0 | E15: =SUMPRODUCT(E4:E13,Inputs!$B$63:$B$72)/4 -> 0 | F15: =SUMPRODUCT(F4:F13,Inputs!$B$63:$B$72)/4 -> 0 | G15: =SUMPRODUCT(G4:G13,Inputs!$B$63:$B$72)/4 -> 0 | H15: =SUMPRODUCT(H4:H13,Inputs!$B$63:$B$72)/4 -> 0 | I15: =SUMPRODUCT(I4:I13,Inputs!$B$63:$B$72)/4 -> 0 | ... U15: =SUMPRODUCT(U4:U13,Inputs!$B$63:$B$72)/4 -> 0

Sheet PnL
A1: Multi-Step P&L (Mersch format) — Annual
A3: Line | B3: Year 1 | C3: Year 2 | D3: Year 3 | E3: Year 4 | F3: Year 5
A4: RECURRING SOFTWARE REVENUE | B4: =SUM('ARR-Waterfall'!B14:M14) -> 0 | C4: =SUM('ARR-Waterfall'!N14:Y14) -> 0 | D4: =SUM('ARR-Waterfall'!Z14:AK14) -> 0 | E4: =SUM('ARR-Waterfall'!AL14:AW14) -> 0 | F4: =SUM('ARR-Waterfall'!AX14:BI14) -> 0
A5: Non-recurring (services/setup) | B5: =B4*0.05*(1=1)+B4*0.03*(1=2) -> 0 | C5: =B4*0.05*(2=1)+B4*0.03*(2=2) -> 0 | D5: =B4*0.05*(3=1)+B4*0.03*(3=2) -> 0 | E5: =B4*0.05*(4=1)+B4*0.03*(4=2) -> 0 | F5: =B4*0.05*(5=1)+B4*0.03*(5=2) -> 0
A6: TOTAL REVENUE | B6: =B4+B5 -> 0 | C6: =C4+C5 -> 0 | D6: =D4+D5 -> 0 | E6: =E4+E5 -> 0 | F6: =F4+F5 -> 0
A7: COST OF REVENUE (COGS %) | B7: =B6*COGS_PCT -> 0 | C7: =C6*COGS_PCT -> 0 | D7: =D6*COGS_PCT -> 0 | E7: =E6*COGS_PCT -> 0 | F7: =F6*COGS_PCT -> 0
A8: GROSS PROFIT | B8: =B6-B7 -> 0 | C8: =C6-C7 -> 0 | D8: =D6-D7 -> 0 | E8: =E6-E7 -> 0 | F8: =F6-F7 -> 0
A9: Gross Margin % | B9: =B8/B6 -> 0 | C9: =C8/C6 -> 0 | D9: =D8/D6 -> 0 | E9: =E8/E6 -> 0 | F9: =F8/F6 -> 0
A10: Sales & Marketing | B10: =B6*IF(1=1,SM_Y1,IF(1=2,SM_Y2,SM_Y3p)) -> 0 | C10: =C6*IF(2=1,SM_Y1,IF(2=2,SM_Y2,SM_Y3p)) -> 0 | D10: =D6*IF(3=1,SM_Y1,IF(3=2,SM_Y2,SM_Y3p)) -> 0 | E10: =E6*IF(4=1,SM_Y1,IF(4=2,SM_Y2,SM_Y3p)) -> 0 | F10: =F6*IF(5=1,SM_Y1,IF(5=2,SM_Y2,SM_Y3p)) -> 0
A11: Research & Development | B11: =B6*IF(1=1,RD_Y1,IF(1=2,RD_Y2,RD_Y3p)) -> 0 | C11: =C6*IF(2=1,RD_Y1,IF(2=2,RD_Y2,RD_Y3p)) -> 0 | D11: =D6*IF(3=1,RD_Y1,IF(3=2,RD_Y2,RD_Y3p)) -> 0 | E11: =E6*IF(4=1,RD_Y1,IF(4=2,RD_Y2,RD_Y3p)) -> 0 | F11: =F6*IF(5=1,RD_Y1,IF(5=2,RD_Y2,RD_Y3p)) -> 0
A12: General & Administrative | B12: =IF(1=1,GA_Y1*12,IF(1=2,GA_Y2*12,GA_Y3p*12)) -> 0 | C12: =IF(2=1,GA_Y1*12,IF(2=2,GA_Y2*12,GA_Y3p*12)) -> 0 | D12: =IF(3=1,GA_Y1*12,IF(3=2,GA_Y2*12,GA_Y3p*12)) -> 0 | E12: =IF(4=1,GA_Y1*12,IF(4=2,GA_Y2*12,GA_Y3p*12)) -> 0 | F12: =IF(5=1,GA_Y1*12,IF(5=2,GA_Y2*12,GA_Y3p*12)) -> 0
A13: TOTAL OPERATING EXPENSE | B13: =B10+B11+B12 -> 0 | C13: =C10+C11+C12 -> 0 | D13: =D10+D11+D12 -> 0 | E13: =E10+E11+E12 -> 0 | F13: =F10+F11+F12 -> 0
A14: OPERATING INCOME (LOSS) | B14: =B8-B13 -> 0 | C14: =C8-C13 -> 0 | D14: =D8-D13 -> 0 | E14: =E8-E13 -> 0 | F14: =F8-F13 -> 0
A15: Operating Margin % | B15: =B14/B6 -> 0 | C15: =C14/C6 -> 0 | D15: =D14/D6 -> 0 | E15: =E14/E6 -> 0 | F15: =F14/F6 -> 0
A16: + D&A (capex/5) | B16: =IF(1=1,Capex_Y1,IF(1=2,Capex_Y2,IF(1=3,Capex_Y3,IF(1=4,Capex_Y4,Capex_Y5))))/5 -> 0 | C16: =IF(2=1,Capex_Y1,IF(2=2,Capex_Y2,IF(2=3,Capex_Y3,IF(2=4,Capex_Y4,Capex_Y5))))/5 -> 0 | D16: =IF(3=1,Capex_Y1,IF(3=2,Capex_Y2,IF(3=3,Capex_Y3,IF(3=4,Capex_Y4,Capex_Y5))))/5 -> 0 | E16: =IF(4=1,Capex_Y1,IF(4=2,Capex_Y2,IF(4=3,Capex_Y3,IF(4=4,Capex_Y4,Capex_Y5))))/5 -> 0 | F16: =IF(5=1,Capex_Y1,IF(5=2,Capex_Y2,IF(5=3,Capex_Y3,IF(5=4,Capex_Y4,Capex_Y5))))/5 -> 0
A17: + Stock-based comp (5% rev) | B17: =B6*0.05 -> 0 | C17: =C6*0.05 -> 0 | D17: =D6*0.05 -> 0 | E17: =E6*0.05 -> 0 | F17: =F6*0.05 -> 0
A18: ADJUSTED EBITDA | B18: =B14+B16+B17 -> 0 | C18: =C14+C16+C17 -> 0 | D18: =D14+D16+D17 -> 0 | E18: =E14+E16+E17 -> 0 | F18: =F14+F16+F17 -> 0
A19: EBITDA Margin % | B19: =B18/B6 -> 0 | C19: =C18/C6 -> 0 | D19: =D18/D6 -> 0 | E19: =E18/E6 -> 0 | F19: =F18/F6 -> 0
A20: Tax (on positive op income only) | B20: =MAX(0,B14)*Tax_Rate -> 0 | C20: =MAX(0,C14)*Tax_Rate -> 0 | D20: =MAX(0,D14)*Tax_Rate -> 0 | E20: =MAX(0,E14)*Tax_Rate -> 0 | F20: =MAX(0,F14)*Tax_Rate -> 0
A21: NET INCOME | B21: =B14-B20 -> 0 | C21: =C14-C20 -> 0 | D21: =D14-D20 -> 0 | E21: =E14-E20 -> 0 | F21: =F14-F20 -> 0

Sheet Cash
A1: Cash Flow — Monthly (60 months)
A3: Month | B3: M1 | C3: M2 | D3: M3 | E3: M4 | F3: M5 | G3: M6 | H3: M7 | I3: M8 | J3: M9 | K3: M10 | L3: M11 | M3: M12 | N3: M13 | O3: M14 | P3: M15 | Q3: M16 | R3: M17 | S3: M18 | T3: M19 | U3: M20 | V3: M21 | W3: M22 | X3: M23 | Y3: M24 | Z3: M25 | AA3: M26 | AB3: M27 | AC3: M28 | AD3: M29 | AE3: M30 | AF3: M31 | AG3: M32 | AH3: M33 | AI3: M34 | AJ3: M35 | AK3: M36 | AL3: M37 | AM3: M38 | AN3: M39 | AO3: M40 | AP3: M41 | AQ3: M42 | AR3: M43 | AS3: M44 | AT3: M45 | AU3: M46 | AV3: M47 | AW3: M48 | AX3: M49 | AY3: M50 | AZ3: M51 | BA3: M52 | BB3: M53 | BC3: M54 | BD3: M55 | BE3: M56 | BF3: M57 | BG3: M58 | BH3: M59 | BI3: M60
A4: Revenue (cash collected, monthly) | B4: ='ARR-Waterfall'!B14 -> 0 | C4: ='ARR-Waterfall'!C14 -> 0 | D4: ='ARR-Waterfall'!D14 -> 0 | E4: ='ARR-Waterfall'!E14 -> 0 | F4: ='ARR-Waterfall'!F14 -> 0 | G4: ='ARR-Waterfall'!G14 -> 0 | H4: ='ARR-Waterfall'!H14 -> 0 | I4: ='ARR-Waterfall'!I14 -> 0 | ... BI4: ='ARR-Waterfall'!BI14 -> 0
A5: COGS (monthly) | B5: =B4*COGS_PCT -> 0 | C5: =C4*COGS_PCT -> 0 | D5: =D4*COGS_PCT -> 0 | E5: =E4*COGS_PCT -> 0 | F5: =F4*COGS_PCT -> 0 | G5: =G4*COGS_PCT -> 0 | H5: =H4*COGS_PCT -> 0 | I5: =I4*COGS_PCT -> 0 | ... BI5: =BI4*COGS_PCT -> 0
A6: Gross Profit | B6: =B4-B5 -> 0 | C6: =C4-C5 -> 0 | D6: =D4-D5 -> 0 | E6: =E4-E5 -> 0 | F6: =F4-F5 -> 0 | G6: =G4-G5 -> 0 | H6: =H4-H5 -> 0 | I6: =I4-I5 -> 0 | ... BI6: =BI4-BI5 -> 0
A7: Total Opex (HC × time + S&M% + G&A) | B7: =B4*(IF(1=1,SM_Y1,IF(1=2,SM_Y2,SM_Y3p))+IF(1=1,RD_Y1,IF(1=2,RD_Y2,RD_Y3p)))+IF(1=1,GA_Y1,IF(1=2,GA_Y2,GA_Y3p)) -> 0 | C7: =C4*(IF(1=1,SM_Y1,IF(1=2,SM_Y2,SM_Y3p))+IF(1=1,RD_Y1,IF(1=2,RD_Y2,RD_Y3p)))+IF(1=1,GA_Y1,IF(1=2,GA_Y2,GA_Y3p)) -> 0 | D7: =D4*(IF(1=1,SM_Y1,IF(1=2,SM_Y2,SM_Y3p))+IF(1=1,RD_Y1,IF(1=2,RD_Y2,RD_Y3p)))+IF(1=1,GA_Y1,IF(1=2,GA_Y2,GA_Y3p)) -> 0 | E7: =E4*(IF(1=1,SM_Y1,IF(1=2,SM_Y2,SM_Y3p))+IF(1=1,RD_Y1,IF(1=2,RD_Y2,RD_Y3p)))+IF(1=1,GA_Y1,IF(1=2,GA_Y2,GA_Y3p)) -> 0 | F7: =F4*(IF(1=1,SM_Y1,IF(1=2,SM_Y2,SM_Y3p))+IF(1=1,RD_Y1,IF(1=2,RD_Y2,RD_Y3p)))+IF(1=1,GA_Y1,IF(1=2,GA_Y2,GA_Y3p)) -> 0 | G7: =G4*(IF(1=1,SM_Y1,IF(1=2,SM_Y2,SM_Y3p))+IF(1=1,RD_Y1,IF(1=2,RD_Y2,RD_Y3p)))+IF(1=1,GA_Y1,IF(1=2,GA_Y2,GA_Y3p)) -> 0 | H7: =H4*(IF(1=1,SM_Y1,IF(1=2,SM_Y2,SM_Y3p))+IF(1=1,RD_Y1,IF(1=2,RD_Y2,RD_Y3p)))+IF(1=1,GA_Y1,IF(1=2,GA_Y2,GA_Y3p)) -> 0 | I7: =I4*(IF(1=1,SM_Y1,IF(1=2,SM_Y2,SM_Y3p))+IF(1=1,RD_Y1,IF(1=2,RD_Y2,RD_Y3p)))+IF(1=1,GA_Y1,IF(1=2,GA_Y2,GA_Y3p)) -> 0 | ... M7: =M4*(IF(1=1,SM_Y1,IF(1=2,SM_Y2,SM_Y3p))+IF(1=1,RD_Y1,IF(1=2,RD_Y2,RD_Y3p)))+IF(1=1,GA_Y1,IF(1=2,GA_Y2,GA_Y3p)) -> 0 | N7: =N4*(IF(2=1,SM_Y1,IF(2=2,SM_Y2,SM_Y3p))+IF(2=1,RD_Y1,IF(2=2,RD_Y2,RD_Y3p)))+IF(2=1,GA_Y1,IF(2=2,GA_Y2,GA_Y3p)) -> 0 | O7: =O4*(IF(2=1,SM_Y1,IF(2=2,SM_Y2,SM_Y3p))+IF(2=1,RD_Y1,IF(2=2,RD_Y2,RD_Y3p)))+IF(2=1,GA_Y1,IF(2=2,GA_Y2,GA_Y3p)) -> 0 | P7: =P4*(IF(2=1,SM_Y1,IF(2=2,SM_Y2,SM_Y3p))+IF(2=1,RD_Y1,IF(2=2,RD_Y2,RD_Y3p)))+IF(2=1,GA_Y1,IF(2=2,GA_Y2,GA_Y3p)) -> 0 | Q7: =Q4*(IF(2=1,SM_Y1,IF(2=2,SM_Y2,SM_Y3p))+IF(2=1,RD_Y1,IF(2=2,RD_Y2,RD_Y3p)))+IF(2=1,GA_Y1,IF(2=2,GA_Y2,GA_Y3p)) -> 0 | R7: =R4*(IF(2=1,SM_Y1,IF(2=2,SM_Y2,SM_Y3p))+IF(2=1,RD_Y1,IF(2=2,RD_Y2,RD_Y3p)))+IF(2=1,GA_Y1,IF(2=2,GA_Y2,GA_Y3p)) -> 0 | S7: =S4*(IF(2=1,SM_Y1,IF(2=2,SM_Y2,SM_Y3p))+IF(2=1,RD_Y1,IF(2=2,RD_Y2,RD_Y3p)))+IF(2=1,GA_Y1,IF(2=2,GA_Y2,GA_Y3p)) -> 0 | T7: =T4*(IF(2=1,SM_Y1,IF(2=2,SM_Y2,SM_Y3p))+IF(2=1,RD_Y1,IF(2=2,RD_Y2,RD_Y3p)))+IF(2=1,GA_Y1,IF(2=2,GA_Y2,GA_Y3p)) -> 0 | U7: =U4*(IF(2=1,SM_Y1,IF(2=2,SM_Y2,SM_Y3p))+IF(2=1,RD_Y1,IF(2=2,RD_Y2,RD_Y3p)))+IF(2=1,GA_Y1,IF(2=2,GA_Y2,GA_Y3p)) -> 0 | ... Y7: =Y4*(IF(2=1,SM_Y1,IF(2=2,SM_Y2,SM_Y3p))+IF(2=1,RD_Y1,IF(2=2,RD_Y2,RD_Y3p)))+IF(2=1,GA_Y1,IF(2=2,GA_Y2,GA_Y3p)) -> 0 | Z7: =Z4*(IF(3=1,SM_Y1,IF(3=2,SM_Y2,SM_Y3p))+IF(3=1,RD_Y1,IF(3=2,RD_Y2,RD_Y3p)))+IF(3=1,GA_Y1,IF(3=2,GA_Y2,GA_Y3p)) -> 0 | AA7: =AA4*(IF(3=1,SM_Y1,IF(3=2,SM_Y2,SM_Y3p))+IF(3=1,RD_Y1,IF(3=2,RD_Y2,RD_Y3p)))+IF(3=1,GA_Y1,IF(3=2,GA_Y2,GA_Y3p)) -> 0 | AB7: =AB4*(IF(3=1,SM_Y1,IF(3=2,SM_Y2,SM_Y3p))+IF(3=1,RD_Y1,IF(3=2,RD_Y2,RD_Y3p)))+IF(3=1,GA_Y1,IF(3=2,GA_Y2,GA_Y3p)) -> 0 | AC7: =AC4*(IF(3=1,SM_Y1,IF(3=2,SM_Y2,SM_Y3p))+IF(3=1,RD_Y1,IF(3=2,RD_Y2,RD_Y3p)))+IF(3=1,GA_Y1,IF(3=2,GA_Y2,GA_Y3p)) -> 0 | AD7: =AD4*(IF(3=1,SM_Y1,IF(3=2,SM_Y2,SM_Y3p))+IF(3=1,RD_Y1,IF(3=2,RD_Y2,RD_Y3p)))+IF(3=1,GA_Y1,IF(3=2,GA_Y2,GA_Y3p)) -> 0 | AE7: =AE4*(IF(3=1,SM_Y1,IF(3=2,SM_Y2,SM_Y3p))+IF(3=1,RD_Y1,IF(3=2,RD_Y2,RD_Y3p)))+IF(3=1,GA_Y1,IF(3=2,GA_Y2,GA_Y3p)) -> 0 | AF7: =AF4*(IF(3=1,SM_Y1,IF(3=2,SM_Y2,SM_Y3p))+IF(3=1,RD_Y1,IF(3=2,RD_Y2,RD_Y3p)))+IF(3=1,GA_Y1,IF(3=2,GA_Y2,GA_Y3p)) -> 0 | AG7: =AG4*(IF(3=1,SM_Y1,IF(3=2,SM_Y2,SM_Y3p))+IF(3=1,RD_Y1,IF(3=2,RD_Y2,RD_Y3p)))+IF(3=1,GA_Y1,IF(3=2,GA_Y2,GA_Y3p)) -> 0 | ... AK7: =AK4*(IF(3=1,SM_Y1,IF(3=2,SM_Y2,SM_Y3p))+IF(3=1,RD_Y1,IF(3=2,RD_Y2,RD_Y3p)))+IF(3=1,GA_Y1,IF(3=2,GA_Y2,GA_Y3p)) -> 0 | AL7: =AL4*(IF(4=1,SM_Y1,IF(4=2,SM_Y2,SM_Y3p))+IF(4=1,RD_Y1,IF(4=2,RD_Y2,RD_Y3p)))+IF(4=1,GA_Y1,IF(4=2,GA_Y2,GA_Y3p)) -> 0 | AM7: =AM4*(IF(4=1,SM_Y1,IF(4=2,SM_Y2,SM_Y3p))+IF(4=1,RD_Y1,IF(4=2,RD_Y2,RD_Y3p)))+IF(4=1,GA_Y1,IF(4=2,GA_Y2,GA_Y3p)) -> 0 | AN7: =AN4*(IF(4=1,SM_Y1,IF(4=2,SM_Y2,SM_Y3p))+IF(4=1,RD_Y1,IF(4=2,RD_Y2,RD_Y3p)))+IF(4=1,GA_Y1,IF(4=2,GA_Y2,GA_Y3p)) -> 0 | AO7: =AO4*(IF(4=1,SM_Y1,IF(4=2,SM_Y2,SM_Y3p))+IF(4=1,RD_Y1,IF(4=2,RD_Y2,RD_Y3p)))+IF(4=1,GA_Y1,IF(4=2,GA_Y2,GA_Y3p)) -> 0 | AP7: =AP4*(IF(4=1,SM_Y1,IF(4=2,SM_Y2,SM_Y3p))+IF(4=1,RD_Y1,IF(4=2,RD_Y2,RD_Y3p)))+IF(4=1,GA_Y1,IF(4=2,GA_Y2,GA_Y3p)) -> 0 | AQ7: =AQ4*(IF(4=1,SM_Y1,IF(4=2,SM_Y2,SM_Y3p))+IF(4=1,RD_Y1,IF(4=2,RD_Y2,RD_Y3p)))+IF(4=1,GA_Y1,IF(4=2,GA_Y2,GA_Y3p)) -> 0 | AR7: =AR4*(IF(4=1,SM_Y1,IF(4=2,SM_Y2,SM_Y3p))+IF(4=1,RD_Y1,IF(4=2,RD_Y2,RD_Y3p)))+IF(4=1,GA_Y1,IF(4=2,GA_Y2,GA_Y3p)) -> 0 | AS7: =AS4*(IF(4=1,SM_Y1,IF(4=2,SM_Y2,SM_Y3p))+IF(4=1,RD_Y1,IF(4=2,RD_Y2,RD_Y3p)))+IF(4=1,GA_Y1,IF(4=2,GA_Y2,GA_Y3p)) -> 0 | ... AW7: =AW4*(IF(4=1,SM_Y1,IF(4=2,SM_Y2,SM_Y3p))+IF(4=1,RD_Y1,IF(4=2,RD_Y2,RD_Y3p)))+IF(4=1,GA_Y1,IF(4=2,GA_Y2,GA_Y3p)) -> 0 | AX7: =AX4*(IF(5=1,SM_Y1,IF(5=2,SM_Y2,SM_Y3p))+IF(5=1,RD_Y1,IF(5=2,RD_Y2,RD_Y3p)))+IF(5=1,GA_Y1,IF(5=2,GA_Y2,GA_Y3p)) -> 0 | AY7: =AY4*(IF(5=1,SM_Y1,IF(5=2,SM_Y2,SM_Y3p))+IF(5=1,RD_Y1,IF(5=2,RD_Y2,RD_Y3p)))+IF(5=1,GA_Y1,IF(5=2,GA_Y2,GA_Y3p)) -> 0 | AZ7: =AZ4*(IF(5=1,SM_Y1,IF(5=2,SM_Y2,SM_Y3p))+IF(5=1,RD_Y1,IF(5=2,RD_Y2,RD_Y3p)))+IF(5=1,GA_Y1,IF(5=2,GA_Y2,GA_Y3p)) -> 0 | BA7: =BA4*(IF(5=1,SM_Y1,IF(5=2,SM_Y2,SM_Y3p))+IF(5=1,RD_Y1,IF(5=2,RD_Y2,RD_Y3p)))+IF(5=1,GA_Y1,IF(5=2,GA_Y2,GA_Y3p)) -> 0 | BB7: =BB4*(IF(5=1,SM_Y1,IF(5=2,SM_Y2,SM_Y3p))+IF(5=1,RD_Y1,IF(5=2,RD_Y2,RD_Y3p)))+IF(5=1,GA_Y1,IF(5=2,GA_Y2,GA_Y3p)) -> 0 | BC7: =BC4*(IF(5=1,SM_Y1,IF(5=2,SM_Y2,SM_Y3p))+IF(5=1,RD_Y1,IF(5=2,RD_Y2,RD_Y3p)))+IF(5=1,GA_Y1,IF(5=2,GA_Y2,GA_Y3p)) -> 0 | BD7: =BD4*(IF(5=1,SM_Y1,IF(5=2,SM_Y2,SM_Y3p))+IF(5=1,RD_Y1,IF(5=2,RD_Y2,RD_Y3p)))+IF(5=1,GA_Y1,IF(5=2,GA_Y2,GA_Y3p)) -> 0 | BE7: =BE4*(IF(5=1,SM_Y1,IF(5=2,SM_Y2,SM_Y3p))+IF(5=1,RD_Y1,IF(5=2,RD_Y2,RD_Y3p)))+IF(5=1,GA_Y1,IF(5=2,GA_Y2,GA_Y3p)) -> 0 | ... BI7: =BI4*(IF(5=1,SM_Y1,IF(5=2,SM_Y2,SM_Y3p))+IF(5=1,RD_Y1,IF(5=2,RD_Y2,RD_Y3p)))+IF(5=1,GA_Y1,IF(5=2,GA_Y2,GA_Y3p)) -> 0
A8: Operating Cash Flow | B8: =B6-B7 -> 0 | C8: =C6-C7 -> 0 | D8: =D6-D7 -> 0 | E8: =E6-E7 -> 0 | F8: =F6-F7 -> 0 | G8: =G6-G7 -> 0 | H8: =H6-H7 -> 0 | I8: =I6-I7 -> 0 | ... BI8: =BI6-BI7 -> 0
A9: Capex (monthly) | B9: =-IF(1=1,Capex_Y1,IF(1=2,Capex_Y2,IF(1=3,Capex_Y3,IF(1=4,Capex_Y4,Capex_Y5))))/12 -> 0 | C9: =-IF(1=1,Capex_Y1,IF(1=2,Capex_Y2,IF(1=3,Capex_Y3,IF(1=4,Capex_Y4,Capex_Y5))))/12 -> 0 | D9: =-IF(1=1,Capex_Y1,IF(1=2,Capex_Y2,IF(1=3,Capex_Y3,IF(1=4,Capex_Y4,Capex_Y5))))/12 -> 0 | E9: =-IF(1=1,Capex_Y1,IF(1=2,Capex_Y2,IF(1=3,Capex_Y3,IF(1=4,Capex_Y4,Capex_Y5))))/12 -> 0 | F9: =-IF(1=1,Capex_Y1,IF(1=2,Capex_Y2,IF(1=3,Capex_Y3,IF(1=4,Capex_Y4,Capex_Y5))))/12 -> 0 | G9: =-IF(1=1,Capex_Y1,IF(1=2,Capex_Y2,IF(1=3,Capex_Y3,IF(1=4,Capex_Y4,Capex_Y5))))/12 -> 0 | H9: =-IF(1=1,Capex_Y1,IF(1=2,Capex_Y2,IF(1=3,Capex_Y3,IF(1=4,Capex_Y4,Capex_Y5))))/12 -> 0 | I9: =-IF(1=1,Capex_Y1,IF(1=2,Capex_Y2,IF(1=3,Capex_Y3,IF(1=4,Capex_Y4,Capex_Y5))))/12 -> 0 | ... M9: =-IF(1=1,Capex_Y1,IF(1=2,Capex_Y2,IF(1=3,Capex_Y3,IF(1=4,Capex_Y4,Capex_Y5))))/12 -> 0 | N9: =-IF(2=1,Capex_Y1,IF(2=2,Capex_Y2,IF(2=3,Capex_Y3,IF(2=4,Capex_Y4,Capex_Y5))))/12 -> 0 | O9: =-IF(2=1,Capex_Y1,IF(2=2,Capex_Y2,IF(2=3,Capex_Y3,IF(2=4,Capex_Y4,Capex_Y5))))/12 -> 0 | P9: =-IF(2=1,Capex_Y1,IF(2=2,Capex_Y2,IF(2=3,Capex_Y3,IF(2=4,Capex_Y4,Capex_Y5))))/12 -> 0 | Q9: =-IF(2=1,Capex_Y1,IF(2=2,Capex_Y2,IF(2=3,Capex_Y3,IF(2=4,Capex_Y4,Capex_Y5))))/12 -> 0 | R9: =-IF(2=1,Capex_Y1,IF(2=2,Capex_Y2,IF(2=3,Capex_Y3,IF(2=4,Capex_Y4,Capex_Y5))))/12 -> 0 | S9: =-IF(2=1,Capex_Y1,IF(2=2,Capex_Y2,IF(2=3,Capex_Y3,IF(2=4,Capex_Y4,Capex_Y5))))/12 -> 0 | T9: =-IF(2=1,Capex_Y1,IF(2=2,Capex_Y2,IF(2=3,Capex_Y3,IF(2=4,Capex_Y4,Capex_Y5))))/12 -> 0 | U9: =-IF(2=1,Capex_Y1,IF(2=2,Capex_Y2,IF(2=3,Capex_Y3,IF(2=4,Capex_Y4,Capex_Y5))))/12 -> 0 | ... Y9: =-IF(2=1,Capex_Y1,IF(2=2,Capex_Y2,IF(2=3,Capex_Y3,IF(2=4,Capex_Y4,Capex_Y5))))/12 -> 0 | Z9: =-IF(3=1,Capex_Y1,IF(3=2,Capex_Y2,IF(3=3,Capex_Y3,IF(3=4,Capex_Y4,Capex_Y5))))/12 -> 0 | AA9: =-IF(3=1,Capex_Y1,IF(3=2,Capex_Y2,IF(3=3,Capex_Y3,IF(3=4,Capex_Y4,Capex_Y5))))/12 -> 0 | AB9: =-IF(3=1,Capex_Y1,IF(3=2,Capex_Y2,IF(3=3,Capex_Y3,IF(3=4,Capex_Y4,Capex_Y5))))/12 -> 0 | AC9: =-IF(3=1,Capex_Y1,IF(3=2,Capex_Y2,IF(3=3,Capex_Y3,IF(3=4,Capex_Y4,Capex_Y5))))/12 -> 0 | AD9: =-IF(3=1,Capex_Y1,IF(3=2,Capex_Y2,IF(3=3,Capex_Y3,IF(3=4,Capex_Y4,Capex_Y5))))/12 -> 0 | AE9: =-IF(3=1,Capex_Y1,IF(3=2,Capex_Y2,IF(3=3,Capex_Y3,IF(3=4,Capex_Y4,Capex_Y5))))/12 -> 0 | AF9: =-IF(3=1,Capex_Y1,IF(3=2,Capex_Y2,IF(3=3,Capex_Y3,IF(3=4,Capex_Y4,Capex_Y5))))/12 -> 0 | AG9: =-IF(3=1,Capex_Y1,IF(3=2,Capex_Y2,IF(3=3,Capex_Y3,IF(3=4,Capex_Y4,Capex_Y5))))/12 -> 0 | ... AK9: =-IF(3=1,Capex_Y1,IF(3=2,Capex_Y2,IF(3=3,Capex_Y3,IF(3=4,Capex_Y4,Capex_Y5))))/12 -> 0 | AL9: =-IF(4=1,Capex_Y1,IF(4=2,Capex_Y2,IF(4=3,Capex_Y3,IF(4=4,Capex_Y4,Capex_Y5))))/12 -> 0 | AM9: =-IF(4=1,Capex_Y1,IF(4=2,Capex_Y2,IF(4=3,Capex_Y3,IF(4=4,Capex_Y4,Capex_Y5))))/12 -> 0 | AN9: =-IF(4=1,Capex_Y1,IF(4=2,Capex_Y2,IF(4=3,Capex_Y3,IF(4=4,Capex_Y4,Capex_Y5))))/12 -> 0 | AO9: =-IF(4=1,Capex_Y1,IF(4=2,Capex_Y2,IF(4=3,Capex_Y3,IF(4=4,Capex_Y4,Capex_Y5))))/12 -> 0 | AP9: =-IF(4=1,Capex_Y1,IF(4=2,Capex_Y2,IF(4=3,Capex_Y3,IF(4=4,Capex_Y4,Capex_Y5))))/12 -> 0 | AQ9: =-IF(4=1,Capex_Y1,IF(4=2,Capex_Y2,IF(4=3,Capex_Y3,IF(4=4,Capex_Y4,Capex_Y5))))/12 -> 0 | AR9: =-IF(4=1,Capex_Y1,IF(4=2,Capex_Y2,IF(4=3,Capex_Y3,IF(4=4,Capex_Y4,Capex_Y5))))/12 -> 0 | AS9: =-IF(4=1,Capex_Y1,IF(4=2,Capex_Y2,IF(4=3,Capex_Y3,IF(4=4,Capex_Y4,Capex_Y5))))/12 -> 0 | ... AW9: =-IF(4=1,Capex_Y1,IF(4=2,Capex_Y2,IF(4=3,Capex_Y3,IF(4=4,Capex_Y4,Capex_Y5))))/12 -> 0 | AX9: =-IF(5=1,Capex_Y1,IF(5=2,Capex_Y2,IF(5=3,Capex_Y3,IF(5=4,Capex_Y4,Capex_Y5))))/12 -> 0 | AY9: =-IF(5=1,Capex_Y1,IF(5=2,Capex_Y2,IF(5=3,Capex_Y3,IF(5=4,Capex_Y4,Capex_Y5))))/12 -> 0 | AZ9: =-IF(5=1,Capex_Y1,IF(5=2,Capex_Y2,IF(5=3,Capex_Y3,IF(5=4,Capex_Y4,Capex_Y5))))/12 -> 0 | BA9: =-IF(5=1,Capex_Y1,IF(5=2,Capex_Y2,IF(5=3,Capex_Y3,IF(5=4,Capex_Y4,Capex_Y5))))/12 -> 0 | BB9: =-IF(5=1,Capex_Y1,IF(5=2,Capex_Y2,IF(5=3,Capex_Y3,IF(5=4,Capex_Y4,Capex_Y5))))/12 -> 0 | BC9: =-IF(5=1,Capex_Y1,IF(5=2,Capex_Y2,IF(5=3,Capex_Y3,IF(5=4,Capex_Y4,Capex_Y5))))/12 -> 0 | BD9: =-IF(5=1,Capex_Y1,IF(5=2,Capex_Y2,IF(5=3,Capex_Y3,IF(5=4,Capex_Y4,Capex_Y5))))/12 -> 0 | BE9: =-IF(5=1,Capex_Y1,IF(5=2,Capex_Y2,IF(5=3,Capex_Y3,IF(5=4,Capex_Y4,Capex_Y5))))/12 -> 0 | ... BI9: =-IF(5=1,Capex_Y1,IF(5=2,Capex_Y2,IF(5=3,Capex_Y3,IF(5=4,Capex_Y4,Capex_Y5))))/12 -> 0
A10: Equity raised (in month) | B10: =IF(1=1,Eq_Y1,IF(1=2,Eq_Y2,IF(1=3,Eq_Y3,0))) -> 0 | C10: 0 | D10: 0 | E10: 0 | F10: 0 | G10: 0 | H10: 0 | I10: 0 | J10: 0 | K10: 0 | L10: 0 | M10: 0 | N10: =IF(2=1,Eq_Y1,IF(2=2,Eq_Y2,IF(2=3,Eq_Y3,0))) -> 0 | O10: 0 | P10: 0 | Q10: 0 | R10: 0 | S10: 0 | T10: 0 | U10: 0 | V10: 0 | W10: 0 | X10: 0 | Y10: 0 | Z10: =IF(3=1,Eq_Y1,IF(3=2,Eq_Y2,IF(3=3,Eq_Y3,0))) -> 0 | AA10: 0 | AB10: 0 | AC10: 0 | AD10: 0 | AE10: 0 | AF10: 0 | AG10: 0 | AH10: 0 | AI10: 0 | AJ10: 0 | AK10: 0 | AL10: =IF(4=1,Eq_Y1,IF(4=2,Eq_Y2,IF(4=3,Eq_Y3,0))) -> 0 | AM10: 0 | AN10: 0 | AO10: 0 | AP10: 0 | AQ10: 0 | AR10: 0 | AS10: 0 | AT10: 0 | AU10: 0 | AV10: 0 | AW10: 0 | AX10: =IF(5=1,Eq_Y1,IF(5=2,Eq_Y2,IF(5=3,Eq_Y3,0))) -> 0 | AY10: 0 | AZ10: 0 | BA10: 0 | BB10: 0 | BC10: 0 | BD10: 0 | BE10: 0 | BF10: 0 | BG10: 0 | BH10: 0 | BI10: 0
A11: Net cash change | B11: =B8+B9+B10 -> 0 | C11: =C8+C9+C10 -> 0 | D11: =D8+D9+D10 -> 0 | E11: =E8+E9+E10 -> 0 | F11: =F8+F9+F10 -> 0 | G11: =G8+G9+G10 -> 0 | H11: =H8+H9+H10 -> 0 | I11: =I8+I9+I10 -> 0 | ... BI11: =BI8+BI9+BI10 -> 0
A12: Beginning cash | B12: =Start_Cash -> 0 | C12: =B13 -> 0 | D12: =C13 -> 0 | E12: =D13 -> 0 | F12: =E13 -> 0 | G12: =F13 -> 0 | H12: =G13 -> 0 | I12: =H13 -> 0 | J12: =I13 -> 0 | ... BI12: =BH13 -> 0
A13: Ending cash | B13: =B12+B11 -> 0 | C13: =C12+C11 -> 0 | D13: =D12+D11 -> 0 | E13: =E12+E11 -> 0 | F13: =F12+F11 -> 0 | G13: =G12+G11 -> 0 | H13: =H12+H11 -> 0 | I13: =I12+I11 -> 0 | ... BI13: =BI12+BI11 -> 0
A14: Cumulative FCF (Op + Investing) | B14: =B8+B9 -> 0 | C14: =B14+C8+C9 -> 0 | D14: =C14+D8+D9 -> 0 | E14: =D14+E8+E9 -> 0 | F14: =E14+F8+F9 -> 0 | G14: =F14+G8+G9 -> 0 | H14: =G14+H8+H9 -> 0 | I14: =H14+I8+I9 -> 0 | J14: =I14+J8+J9 -> 0 | ... BI14: =BH14+BI8+BI9 -> 0
A16: Runway & Working-Capital Trough
A17: Min ending cash (60 mo) | B17: =MIN(B13:BI13) -> 0
A18: Month of trough | B18: =MATCH(MIN(B13:BI13),B13:BI13,0) -> 0
A19: Months of runway from M1 (negative ⇒ year exhausted) | B19: =IFERROR(MATCH(TRUE,INDEX(B13:BI13<=0,0),0)-1,"60+") -> 0
A20: End of period cash (Y5) | B20: =BI13 -> 0

Sheet Sensitivity
A1: Sensitivity — New-Logo Growth × Churn
A3: Reading: each cell = Year-3 Ending ARR ($) under hypothetical inputs (illustrative — assumes linear scaling).
A5: Churn Δ ↓ / Growth Δ → | B5: -0.3 | C5: -0.2 | D5: -0.1 | E5: 0 | F5: 0.1 | G5: 0.2 | H5: 0.3
A6: -0.3 | B6: ='ARR-Waterfall'!AK12*(1+-0.3)^12*(1--0.3)^12 -> 0 | C6: ='ARR-Waterfall'!AK12*(1+-0.2)^12*(1--0.3)^12 -> 0 | D6: ='ARR-Waterfall'!AK12*(1+-0.1)^12*(1--0.3)^12 -> 0 | E6: ='ARR-Waterfall'!AK12*(1+0)^12*(1--0.3)^12 -> 0 | F6: ='ARR-Waterfall'!AK12*(1+0.1)^12*(1--0.3)^12 -> 0 | G6: ='ARR-Waterfall'!AK12*(1+0.2)^12*(1--0.3)^12 -> 0 | H6: ='ARR-Waterfall'!AK12*(1+0.3)^12*(1--0.3)^12 -> 0
A7: -0.15 | B7: ='ARR-Waterfall'!AK12*(1+-0.3)^12*(1--0.15)^12 -> 0 | C7: ='ARR-Waterfall'!AK12*(1+-0.2)^12*(1--0.15)^12 -> 0 | D7: ='ARR-Waterfall'!AK12*(1+-0.1)^12*(1--0.15)^12 -> 0 | E7: ='ARR-Waterfall'!AK12*(1+0)^12*(1--0.15)^12 -> 0 | F7: ='ARR-Waterfall'!AK12*(1+0.1)^12*(1--0.15)^12 -> 0 | G7: ='ARR-Waterfall'!AK12*(1+0.2)^12*(1--0.15)^12 -> 0 | H7: ='ARR-Waterfall'!AK12*(1+0.3)^12*(1--0.15)^12 -> 0
A8: 0 | B8: ='ARR-Waterfall'!AK12*(1+-0.3)^12*(1-0)^12 -> 0 | C8: ='ARR-Waterfall'!AK12*(1+-0.2)^12*(1-0)^12 -> 0 | D8: ='ARR-Waterfall'!AK12*(1+-0.1)^12*(1-0)^12 -> 0 | E8: ='ARR-Waterfall'!AK12*(1+0)^12*(1-0)^12 -> 0 | F8: ='ARR-Waterfall'!AK12*(1+0.1)^12*(1-0)^12 -> 0 | G8: ='ARR-Waterfall'!AK12*(1+0.2)^12*(1-0)^12 -> 0 | H8: ='ARR-Waterfall'!AK12*(1+0.3)^12*(1-0)^12 -> 0
A9: 0.15 | B9: ='ARR-Waterfall'!AK12*(1+-0.3)^12*(1-0.15)^12 -> 0 | C9: ='ARR-Waterfall'!AK12*(1+-0.2)^12*(1-0.15)^12 -> 0 | D9: ='ARR-Waterfall'!AK12*(1+-0.1)^12*(1-0.15)^12 -> 0 | E9: ='ARR-Waterfall'!AK12*(1+0)^12*(1-0.15)^12 -> 0 | F9: ='ARR-Waterfall'!AK12*(1+0.1)^12*(1-0.15)^12 -> 0 | G9: ='ARR-Waterfall'!AK12*(1+0.2)^12*(1-0.15)^12 -> 0 | H9: ='ARR-Waterfall'!AK12*(1+0.3)^12*(1-0.15)^12 -> 0
A10: 0.3 | B10: ='ARR-Waterfall'!AK12*(1+-0.3)^12*(1-0.3)^12 -> 0 | C10: ='ARR-Waterfall'!AK12*(1+-0.2)^12*(1-0.3)^12 -> 0 | D10: ='ARR-Waterfall'!AK12*(1+-0.1)^12*(1-0.3)^12 -> 0 | E10: ='ARR-Waterfall'!AK12*(1+0)^12*(1-0.3)^12 -> 0 | F10: ='ARR-Waterfall'!AK12*(1+0.1)^12*(1-0.3)^12 -> 0 | G10: ='ARR-Waterfall'!AK12*(1+0.2)^12*(1-0.3)^12 -> 0 | H10: ='ARR-Waterfall'!AK12*(1+0.3)^12*(1-0.3)^12 -> 0
A11: 0.5 | B11: ='ARR-Waterfall'!AK12*(1+-0.3)^12*(1-0.5)^12 -> 0 | C11: ='ARR-Waterfall'!AK12*(1+-0.2)^12*(1-0.5)^12 -> 0 | D11: ='ARR-Waterfall'!AK12*(1+-0.1)^12*(1-0.5)^12 -> 0 | E11: ='ARR-Waterfall'!AK12*(1+0)^12*(1-0.5)^12 -> 0 | F11: ='ARR-Waterfall'!AK12*(1+0.1)^12*(1-0.5)^12 -> 0 | G11: ='ARR-Waterfall'!AK12*(1+0.2)^12*(1-0.5)^12 -> 0 | H11: ='ARR-Waterfall'!AK12*(1+0.3)^12*(1-0.5)^12 -> 0
A12: 1 | B12: ='ARR-Waterfall'!AK12*(1+-0.3)^12*(1-1.0)^12 -> 0 | C12: ='ARR-Waterfall'!AK12*(1+-0.2)^12*(1-1.0)^12 -> 0 | D12: ='ARR-Waterfall'!AK12*(1+-0.1)^12*(1-1.0)^12 -> 0 | E12: ='ARR-Waterfall'!AK12*(1+0)^12*(1-1.0)^12 -> 0 | F12: ='ARR-Waterfall'!AK12*(1+0.1)^12*(1-1.0)^12 -> 0 | G12: ='ARR-Waterfall'!AK12*(1+0.2)^12*(1-1.0)^12 -> 0 | H12: ='ARR-Waterfall'!AK12*(1+0.3)^12*(1-1.0)^12 -> 0

Sheet Scenarios
A1: Scenarios — Base / Bull / Bear / Stress
A2: Toggle the active scenario on Inputs cell B5. Multipliers apply to logos, churn, ARPA.
A4: Variable | B4: Base | C4: Bull | D4: Bear | E4: Stress
A5: Logo growth multiplier | B5: 1 | C5: 1.25 | D5: 0.75 | E5: 0.5
A6: Churn multiplier | B6: 1 | C6: 0.75 | D6: 1.5 | E6: 2
A7: ARPA multiplier | B7: 1 | C7: 1.2 | D7: 0.85 | E7: 0.7
A8: FX depreciation % | B8: 0.05 | C8: 0.03 | D8: 0.08 | E8: 0.15
A10: Y3 ending ARR (driven by Inputs!Scen_Active) | B10: ='ARR-Waterfall'!AK12 -> 0
A11: Y5 ending ARR | B11: ='ARR-Waterfall'!BI12 -> 0

Sheet Bankability-Dashboard
A1: Bankability Dashboard — SaaS KPIs
A4: Y1 Revenue | B4: =PnL!B6 -> 0
A5: Y3 Revenue | B5: =PnL!D6 -> 0
A6: Y5 Revenue | B6: =PnL!F6 -> 0
A7: Y3 EBITDA Margin | B7: =PnL!D19 -> 0
A8: Y3 Ending ARR | B8: ='ARR-Waterfall'!AK12 -> 0
A9: Y5 Ending ARR | B9: ='ARR-Waterfall'!BI12 -> 0
A10: Min cash (60mo) | B10: =Cash!B17 -> 0
A11: Trough month | B11: =Cash!B18 -> 0
A12: Gross Margin | B12: =GM_P -> 0
A13: NRR (annual) | B13: =1+(Expansion_P-Rev_Churn_P-Contraction_P)*12 -> 0
A14: GRR (annual) | B14: =MAX(0,1-Rev_Churn_P*12) -> 0
A15: LTV:CAC | B15: =(ARPA_P*GM_P/Logo_Churn_P)/CAC_P -> 0
A16: CAC Payback (months) | B16: =CAC_P/(ARPA_P*GM_P) -> 0
A17: Rule of 40 (Y3) | B17: =('ARR-Waterfall'!AK12/'ARR-Waterfall'!Y12-1)+PnL!D19 -> 0
A18: Magic Number (Y2) | B18: =(('ARR-Waterfall'!Y12-'ARR-Waterfall'!M12))/(PnL!B10) -> 0
A19: Burn Multiple (Y2) | B19: =IF(('ARR-Waterfall'!Y12-'ARR-Waterfall'!M12)>0,MAX(0,-PnL!C18)/('ARR-Waterfall'!Y12-'ARR-Waterfall'!M12),999) -> 0
A20: Quick Ratio (illustrative) | B20: =(Expansion_P+M1_Logos*ARPA_P/'ARR-Waterfall'!M12*12)/(Rev_Churn_P+Contraction_P) -> 0

Sheet Africa-Notes
A1: Africa-Specific Adjustments & Notes
A3: FX Pass-Through | B3: USD-denominated cloud (AWS/Azure/GCP), AI APIs, and SaaS tooling sit against UGX/KES/NGN/ZAR/EGP revenue. Adjust gross-margin benchmarks 5–10pp downward vs US comps. Hold an FX rate on Inputs and stress it ±15% in the sensitivity tab.
A4: M-Pesa Payment Rail (Kenya, Tanzania) | B4: Typical fee 1.0–1.5% per transaction. STK-Push timeout failures generate involuntary churn — model 3-retry dunning over 7 days; recovery typically 30–50%. Track separately from voluntary churn.
A5: MoMo (MTN / Airtel — Uganda, Ghana, Rwanda, Nigeria) | B5: Fee band 1.5–2.0% per transaction. PIN-failure and float-shortage produce 4–6% annual involuntary churn vs <1% US card rails. Best-practice: integrate two rails (MoMo + card) and route based on tier.
A6: Card Rails (Flutterwave / Paystack / Stripe) | B6: Card fees 2.9–3.8% + fixed. Card-decline rate 8–15% on first attempt for African issuing banks. Use Account-Updater services where available.
A7: USD-Enterprise Tier | B7: Charge Enterprise customers (>$1k MRR) in USD invoiced via local entity or offshore SPV to hedge FX. Carries through to the Multi-Step P&L as a separate revenue stream. Recommended for 30–60% of total ARR by Y3.
A8: Longer Collection Cycles | B8: Enterprise/public-sector DSO in Africa: 60–120 days (vs 30–45 US). Working-capital trough is deeper. Buffer trough at 9 months of opex vs the US 6-month standard.
A9: Annual Prepayment Uptake | B9: African SaaS: 20–40% of new contracts pay annually (vs 60–80% US enterprise). Discount typically 10–15%. Model deferred revenue accordingly — do not assume US prepayment economics.
A10: Sales-Cycle Length | B10: African mid-market sales cycle: 90–180 days. Enterprise: 6–18 months including procurement / public-sector RFP loops. CAC-payback benchmarks: relax US targets by 50–100%: <18 (SMB), <24 (Mid), <36 (Ent).
A11: AI Cost Hedging | B11: LLM APIs are USD-priced. Hedge via (a) USD-priced AI premium tier, (b) per-tenant usage caps, (c) open-source model fallback (Llama-class on Bedrock/Together). The AI-cost calculator workbook models all three.
A12: DFI / Local-Bank Reporting | B12: Banks (Stanbic, Equity, KCB, Centenary) and DFIs (FMO, Norfund, Proparco, IFC) require local-currency primary view + USD parallel view. Build the model in USD here; toggle the FX row on Inputs for local presentation.
A13: Rule-of-40 Calibration | B13: Adjust to target 30 for years 1–3 of African SaaS (vs US 40). Aim for 40 by Year 4 once vertical S&M is unlocked.
A14: DFI / Local Bank Format | B14: DFIs (FMO, Norfund, IFC, Proparco) + local banks (Stanbic, Equity, KCB, Centenary) expect local-currency primary view. Build the model in USD here; toggle the FX row on Inputs and produce a parallel local-currency view for submission.
A15: AI Cost Sensitivity Connection | B15: AI cost-per-tenant is FX-exposed (LLM APIs are USD-priced). The dedicated workbook `saas-ai-cost-of-tenant-calculator.xlsx` should feed the COGS % cell on Inputs Section 4. Refresh quarterly or when AI pricing changes.
